Workbook

Sheet Bid Tape
B2: As-of Date | C2: Pre-Approval Flag | D2: Loan ID | E2: Seller | F2: Borrowing Entity | G2: Mortgagor | H2: Origination Date | I2: Non-Cashflowing Flag | J2: Holdback Funded in Escrow | K2: Loan Type | L2: New Construction Flag | M2: Street | N2: City | O2: State | P2: Zip | Q2: Property Type | R2: Number of Properties | S2: Number of Units | T2: Day 1 Loan Amount | U2: Holdback Loan Amount | V2: Interest Reserve | W2: Total Loan Amount | X2: Disbursed Holdback Amount | Y2: Undisbursed Holdback Amount | Z2: Disbursed Interest Reserve | AA2: Undisbursed Interest Reserve | AB2: Total Loan Amount Disbursed | AC2: Interest Bearing Balance | AD2: UPB | AE2: Completion Percentage | AF2: Purchase Price | AG2: Purchase Date | AH2: Rehab Budget | AI2: Cost Incurred to Date | AJ2: Total Project Costs | AK2: AIV | AL2: ARV | AM2: Appraisal Date | AN2: LTAIV | AO2: LTC | AP2: LTARV | AQ2: Pre-Rehab Square Footage | AR2: Post-Rehab Square Footage | AS2: Term | AT2: First Payment Date | AU2: Original Maturity Date | AV2: Current Maturity Date | AW2: Next Due Date | AX2: Dutch Flag | AY2: Interest Days Method | AZ2: Interest Rate | BA2: Purchase Rate | BB2: Lender Retained Spread | BC2: Total Points | BD2: Borrower Liquidity | BE2: FICO | BF2: Foreign National Flag | BG2: Guarantor Track Record | BH2: Recourse | BI2: Pre-Sold Flag | BJ2: Exit Strategy | BK2: Cross Collateralization Flag | BL2: Mid Construction Flag | BM2: Property Conversion Flag | BN2: Extension Flag | BO2: Extension Fee $ | BP2: Extension Fee % | BQ2: Gurantor Name | BR2: Notes | BS2: Collateral Tracking #
B3: 46190 | D3: YSCAP258134727 | F3: TBD | G3: 123 LLC | H3: 46022 | I3: Y | J3: 0 | K3: Purchase | L3: N | M3: 123 Main St | N3: Midland | O3: TX | P3: 79701 | Q3: SFR | R3: 1 | S3: 1 | T3: 275000 | U3: 75000 | V3: 0 | W3: 350000 | X3: 0 | Y3: 75000 | Z3: 0 | AA3: 0 | AB3: 275000 | AC3: 275000 | AD3: 275000 | AE3: =IFERROR(X3/U3,"") -> 0 | AF3: 350000 | AG3: 46022 | AH3: 75000 | AI3: 0 | AJ3: =AF3+AH3 -> 425000 | AK3: 350000 | AL3: 500000 | AM3: 46006 | AN3: =T3/AK3 -> 0.78571429 | AO3: =W3/AJ3 -> 0.82352941 | AP3: =W3/AL3 -> 0.7 | AQ3: 2867 | AR3: 2867 | AS3: 6 | AT3: 46054 | AU3: 46388 | AV3: 46388 | AW3: 46054 | AX3: N | AY3: 30/360 | AZ3: 0.1029 | BC3: 0.025 | BD3: 200000 | BE3: 764 | BF3: N | BG3: 2 | BH3: Full | BI3: N | BJ3: Sell | BK3: N | BL3: N | BM3: N | BN3: N | BQ3: John Doe
B99: . | C99: . | D99: . | E99: . | F99: . | G99: . | H99: . | I99: . | J99: . | K99: . | L99: . | M99: . | N99: . | O99: . | P99: . | Q99: . | R99: . | S99: . | T99: . | U99: . | V99: . | W99: . | X99: . | Y99: . | Z99: . | AA99: . | AB99: . | AC99: . | AD99: . | AE99: . | AF99: . | AG99: . | AH99: . | AI99: . | AJ99: . | AK99: . | AL99: . | AM99: . | AN99: . | AO99: . | AP99: . | AQ99: . | AR99: . | AS99: . | AT99: . | AU99: . | AV99: . | AW99: . | AX99: . | AY99: . | AZ99: . | BA99: . | BB99: . | BC99: . | BD99: . | BE99: . | BF99: . | BG99: . | BH99: . | BI99: . | BJ99: . | BK99: . | BN99: . | BO99: . | BP99: . | BQ99: . | BR99: . | BS99: .

Sheet Settlement Statement
B2: Closing Date | C2: =_xlfn.CONCAT(TEXT(D20,"d"),IF(RIGHT(TEXT(D20,"dd"),1)="1","st",IF(RIGHT(TEXT(D20,"dd"),1)="2","nd",IF(RIGHT(TEXT(D20,"dd"),1)="3","rd","th")))," day of ",TEXT(D20,"mmmm"), ", ",TEXT(D20,"yyyy")) -> 17th day of October, 2025
B3: Cut-off Date | C3: =TEXT(C20,"mmmm dd, yyyy") -> June 17, 2026
B4: MLPA Date | C4: 45932
B6: Total UPB | C6: =SUM(F20:F53) -> #REF!
B7: Original Purchase Price % | C7: =SUMPRODUCT(J20:J53,F20:F53)/C6 -> #REF!
B8: Net Purchase Price | C8: =SUM(K20:K53) -> #REF!
B9: Accured Interest | C9: =SUM(O20:O53) -> #VALUE!
B10: Total Wire | C10: =SUM(P20:P53) -> #VALUE!
B12: Weighted Avg. Coupon | C12: =ROUND(SUMPRODUCT(G20:G53,F20:F53)/C6,6) -> #REF!
B13: Weighted Avg. Purchase Rate | C13: =ROUND(SUMPRODUCT(L20:L53,F20:F53)/C6,3) -> #REF!
B14: Weighted Avg. Lender Spread | C14: =SUMPRODUCT(M20:M53,F20:F53)/C6 -> #VALUE!
B15: Monthly Lender Spread ($) | C15: =(C14/12)*C8 -> #VALUE!
B17: =_xlfn.CONCAT("Blue Lake RTL",TEXT(D20," - mmddyyyy")) -> Blue Lake RTL - 10172025
B18: =IF(COUNTA(B20:B69)=COUNTA('Bid Tape'!D3:D49),"","Count Error") -> Count Error
B19: Originator Name | C19: Cut-Off Date | D19: Trade Date | E19: Seller Loan Number | F19: UPB ($) | G19: Note Rate | H19: Origination Date | I19: Next Due Date | J19: Purchase Price % | K19: Net Purchase Price | L19: Purchase Rate | M19: Lender Spread | N19: Accural Days | O19: Accured Interest | P19: Full Price
B20: ='Bid Tape'!E3 -> 0 | C20: ='Bid Tape'!B3 -> 46190 | D20: 45947 | E20: ='Bid Tape'!D3 -> YSCAP258134727 | F20: ='Bid Tape'!AD3 -> 275000 | G20: ='Bid Tape'!AZ3 -> 0.1029 | H20: ='Bid Tape'!H3 -> 46022 | I20: ='Bid Tape'!AW3 -> 46054 | J20: 1 | K20: =ROUND(J20*F20,2) -> 275000 | L20: =INDEX('Pricing Confirm'!$B$4:$B$50,MATCH('Settlement Statement'!E20,'Pricing Confirm'!$E$4:$E$50)) -> Not Qual | M20: =G20-L20 -> #VALUE! | N20: =DAYS360(EDATE(I20,-1),D20) -> -74 | O20: =ROUND(((L20/360)*K20)*N20,2) -> #VALUE! | P20: =O20+K20 -> #VALUE!
B21: ='Bid Tape'!#REF! -> #REF! | C21: ='Bid Tape'!#REF! -> #REF! | D21: =D20 -> 45947 | E21: ='Bid Tape'!#REF! -> #REF! | F21: ='Bid Tape'!#REF! -> #REF! | G21: ='Bid Tape'!#REF! -> #REF! | H21: ='Bid Tape'!#REF! -> #REF! | I21: ='Bid Tape'!#REF! -> #REF! | J21: 1 | K21: =ROUND(J21*F21,2) -> #REF! | L21: =INDEX('Pricing Confirm'!$B$4:$B$50,MATCH('Settlement Statement'!E21,'Pricing Confirm'!$E$4:$E$50)) -> #REF! | M21: =G21-L21 -> #REF! | N21: =DAYS360(EDATE(I21,-1),D21) -> #REF! | O21: =ROUND(((L21/360)*K21)*N21,2) -> #REF! | P21: =O21+K21 -> #REF!
B22: ='Bid Tape'!#REF! -> #REF! | C22: ='Bid Tape'!#REF! -> #REF! | D22: =D21 -> 45947 | E22: ='Bid Tape'!#REF! -> #REF! | F22: ='Bid Tape'!#REF! -> #REF! | G22: ='Bid Tape'!#REF! -> #REF! | H22: ='Bid Tape'!#REF! -> #REF! | I22: ='Bid Tape'!#REF! -> #REF! | J22: 1 | K22: =ROUND(J22*F22,2) -> #REF! | L22: =INDEX('Pricing Confirm'!$B$4:$B$50,MATCH('Settlement Statement'!E22,'Pricing Confirm'!$E$4:$E$50)) -> #REF! | M22: =G22-L22 -> #REF! | N22: =DAYS360(EDATE(I22,-1),D22) -> #REF! | O22: =ROUND(((L22/360)*K22)*N22,2) -> #REF! | P22: =O22+K22 -> #REF!
B23: ='Bid Tape'!#REF! -> #REF! | C23: ='Bid Tape'!#REF! -> #REF! | D23: =D22 -> 45947 | E23: ='Bid Tape'!#REF! -> #REF! | F23: ='Bid Tape'!#REF! -> #REF! | G23: ='Bid Tape'!#REF! -> #REF! | H23: ='Bid Tape'!#REF! -> #REF! | I23: ='Bid Tape'!#REF! -> #REF! | J23: 1 | K23: =ROUND(J23*F23,2) -> #REF! | L23: =INDEX('Pricing Confirm'!$B$4:$B$50,MATCH('Settlement Statement'!E23,'Pricing Confirm'!$E$4:$E$50)) -> #REF! | M23: =G23-L23 -> #REF! | N23: =DAYS360(EDATE(I23,-1),D23) -> #REF! | O23: =ROUND(((L23/360)*K23)*N23,2) -> #REF! | P23: =O23+K23 -> #REF!

Sheet Data Dictionary
A1: Field Name | B1: Description | C1: Required (Y/N) | D1: Format | E1: Example A | F1: Example B
A2: As-of Date | B2: Effective date of the information on the data tape. | C2: Yes | D2: Date | E2: 45702 | F2: 46150
A3: Pre-Approval Flag | B3: Flag identifying loans that fit escalation criteria or sit outside of current guidelines that required pre-approval. | C3: Only for loans with Pre-approval | D3: Y/N | E3: Y | F3: Y
A4: Loan ID | B4: Lender Loan Number/ID | C4: Yes | D4: Text | E4: 123456 | F4: ABC-1234
A5: Seller | B5: Lender Name as it appears on the MLPA | C5: Yes | D5: Text | E5: ACME Lending, LLC | F5: Lending Fund, INC
A6: Borrowing Entity | B6: Borrowing Entity as it appears on the loan documents | C6: Yes | D6: Text | E6: Fix and Flip, LLC | F6: Borrower INC
A7: Mortgagor | B7: Mortgagor name as it appears on the Mortgage | C7: Yes | D7: Text | E7: Fix and Flip, LLC | F7: Borrower INC
A8: Origination Date | B8: Note Date for subject loan | C8: Yes | D8: Date | E8: 45702 | F8: 46150
A9: Non-Cashflowing Flag | B9: Flag identifying if property is cashflowing (N for tenant occupied properties) | C9: Yes | D9: Y/N | E9: Y | F9: N
A10: Holdback Funded in Escrow | B10: Interest bearing (Dutch) holdback funds | C10: Yes | D10: Dollar Amount | E10: 125000 | F10: 0
A11: Loan Type | B11: Purchase -- Rate/Term -- Cashout | C11: Yes | D11: Text | E11: Purchase | F11: Rate/Term
A12: New Construction Flag | B12: Flag identifying if a loan is for a Ground up construction project (Y for GUC loans) | C12: Yes | D12: Y/N | E12: N | F12: Y
A13: Street | B13: Property Street Address | C13: Yes | D13: Text | E13: 123 Main St | F13: 456 City Ave
A14: City | B14: Property City | C14: Yes | D14: Text | E14: Austin | F14: Incline Village
A15: State | B15: Property State (Abbreviated) | C15: Yes | D15: Text | E15: TX | F15: CA
A16: Zip | B16: Property Zip Code | C16: Yes | D16: Number | E16: 78745 | F16: 98424
A17: Property Type | B17: Subject finished property type | C17: Yes | D17: Text | E17: SFR | F17: Triplex
A18: Number of Properties | B18: Number of properties collateralized with the subject loan | C18: Yes | D18: Number | E18: 1 | F18: 2
A19: Number of Units | B19: Number of dwelling units within the subject property once any renovation is completed | C19: Yes | D19: Number | E19: 1 | F19: 3
A20: Day 1 Loan Amount | B20: Loan amount disbursed to the borrower / on behalf of the borrower at closing | C20: Yes | D20: Dollar Amount | E20: 125000 | F20: 250000
A21: Holdback Loan Amount | B21: Loan amount held back for renovation | C21: Yes | D21: Dollar Amount | E21: 125000 | F21: 250000
A22: Interest Reserve | B22: Loan amount disbursed at closing held in escrow as an interest reserve | C22: Yes | D22: Dollar Amount | E22: 0 | F22: 50000
A23: Total Loan Amount | B23: Maximum total loan amount as stated on the Note | C23: Yes | D23: Dollar Amount | E23: 750000 | F23: 450000
A24: Disbursed Holdback Amount | B24: Renovation holdback that has been disbursed to the borrower | C24: Yes | D24: Dollar Amount | E24: 0 | F24: 50000
A25: Undisbursed Holdback Amount | B25: Renovation holdback that has not been disbursed to the borrower | C25: Yes | D25: Dollar Amount | E25: 125000 | F25: 250000
A26: Disbursed Interest Reserve | B26: Interest Reserve that has been disbursed to the borrower | C26: Yes | D26: Dollar Amount | E26: 0 | F26: 6000
A27: Undisbursed Interest Reserve | B27: Interest Reserve that has not been disbursed to the borrower | C27: Yes | D27: Dollar Amount | E27: 0 | F27: 50000
A28: Total Loan Amount Disbursed | B28: Total sum of all funds disbursed to the borrower as of the cut off date | C28: Yes | D28: Dollar Amount | E28: 125000 | F28: 250000
A29: Interest Bearing Balance | B29: Total interest bearing balance of the loan (Disbursed for non-Dutch // total loan amount for Dutch) | C29: Yes | D29: Dollar Amount | E29: 750000 | F29: 450000
... A49: Next Due Date | B49: Next payment due date for the loan as of the cut off date | C49: Yes | D49: Date | E49: 45702 | F49: 46150
A50: Dutch Flag | B50: Flag identifying if the loan is charging Dutch interest (interest on total loan amount vs only on drawn (ND)) | C50: Yes | D50: Y/N | E50: Y | F50: N
A51: Interest Days Method | B51: How interest is calculated on the loan based on the subject Note | C51: Yes | D51: Text | E51: 30/360 | F51: Actual/360
A52: Interest Rate | B52: Loan interest rate based on the subject Note | C52: Yes | D52: Percentage | E52: 0.0899 | F52: 0.1
A53: Purchase Rate | B53: Purchase rate of subject loan, to be completed by Blue Lake | C53: Yes | D53: Percentage | E53: 0.08 | F53: 0.0925
A54: Lender Retained Spread | B54: Interest spread payable to the Lender completed by Blue Lake | C54: Yes | D54: Percentage | E54: 0.0099 | F54: 0.0075
A55: Total Points | B55: Total origination points charged by the Lender to the borrower per the subject HUD | C55: Yes | D55: Percentage | E55: 0.01 | F55: 0.015
A56: Borrower Liquidity | B56: Borrowers pre-close liquidity based on their provided bank statements | C56: Yes | D56: Dollar Amount | E56: 75000 | F56: 45000
A57: FICO | B57: Primary Personal Guarantor FICO | C57: Yes | D57: Number | E57: 720 | F57: 700
A58: Foreign National Flag | B58: Flag idtifyinng if the borrower is a Foreign National | C58: Yes | D58: Y/N | E58: N | F58: Y
A59: Guarantor Track Record | B59: Number of verified exits borrower has in the past 36 months (measured from Note date) | C59: Yes | D59: Number | E59: 5 | F59: 10
...

Sheet Pricing Confirm
E1: =IF(COUNT(E4:E53)=COUNT('Bid Tape'!D3:D49),"","COUNT ERROR")
B3: Pricing | C3: Spread | E3: Loan Number | F3: Borrower FICO | G3: Borrower Experience | H3: Loan Purpose | I3: State | J3: New Construction (Y/N) | K3: Property Type | L3: Starting Sqft | M3: Ending Sqft | N3: Origination Date | O3: Property Purchase Date | P3: Purchase Price | Q3: Costs Spent | R3: As-Is Value | S3: Rehab Budget | T3: ARV | U3: Term (Mo) | V3: # of Prop | W3: Interest Rate | X3: Initial Loan Amount | Y3: Financed Rehab | Z3: Interest Reserve | AA3: Total Loan Amount | AC3: Borrower Tier | AD3: Rehab Type | AE3: Clac Program | AF3: Days Owned | AG3: Initial Cost Basis | AH3: Total Cost Basis | AI3: LTAIV | AJ3: LTC | AK3: LTARV | AL3: Max LTAIV | AM3: Max LTC | AN3: Max ARV | AO3: LTAIV Check | AP3: LTC Check | AQ3: ARV Check | AR3: TLA Check | AS3: 100% Reno Check | AT3: Profitability Check | AU3: State Check | AV3: Max/Min Loan Amnt | AW3: Portfolio Check | AX3: Test IR | AY3: GUC IR | AZ3: Base Purchase Rate | BA3: Term LLRA | BB3: FICO LLRA | BC3: TLA LLRA | BD3: Property LLRA | BE3: Purchase Rate | BF3: Final
B4: =BF4 -> Not Qual | C4: =IFERROR(W4-B4,"N/A") -> N/A | E4: ='Bid Tape'!D3 -> YSCAP258134727 | F4: ='Bid Tape'!BE3 -> 764 | G4: ='Bid Tape'!BG3 -> 2 | H4: ='Bid Tape'!K3 -> Purchase | I4: ='Bid Tape'!O3 -> TX | J4: ='Bid Tape'!L3 -> N | K4: ='Bid Tape'!Q3 -> SFR | L4: ='Bid Tape'!AQ3 -> 2867 | M4: ='Bid Tape'!AR3 -> 2867 | N4: ='Bid Tape'!H3 -> 46022 | O4: ='Bid Tape'!AG3 -> 46022 | P4: ='Bid Tape'!AF3 -> 350000 | Q4: ='Bid Tape'!AI3 -> 0 | R4: ='Bid Tape'!AK3 -> 350000 | S4: ='Bid Tape'!AH3 -> 75000 | T4: ='Bid Tape'!AL3 -> 500000 | U4: ='Bid Tape'!AS3 -> 6 | V4: ='Bid Tape'!R3 -> 1 | W4: ='Bid Tape'!AZ3 -> 0.1029 | X4: ='Bid Tape'!T3 -> 275000 | Y4: ='Bid Tape'!U3 -> 75000 | Z4: ='Bid Tape'!V3 -> 0 | AA4: ='Bid Tape'!W3 -> 350000 | AC4: =IFERROR(IF(ISBLANK(E4),"",IF(F4>=_xlfn.XLOOKUP(G4,'Rate Sheet'!$D$4:$D$6,'Rate Sheet'!$C$4:$C$6,,-1),_xlfn.XLOOKUP(G4,'Rate Sheet'!$D$4:$D$6,'Rate Sheet'!$B$4:$B$6,,-1),"Not Qual")),"Error") -> Tier 3 | AD4: =IFERROR(IF(ISBLANK(E4),"",IF(J4="Y",'Rate Sheet'!$G$42,IF(OR('Pricing Confirm'!S4>'Pricing Confirm'!R4*0.5,'Pricing Confirm'!M4-'Pricing Confirm'!L4>249),'Rate Sheet'!$G$45,IF('Pricing Confirm'!S4=0,'Rate Sheet'!$G$43,'Rate Sheet'!$G$44)))),"Error") -> Renovation | AE4: =IFERROR(IF(ISBLANK(E4),"",_xlfn.CONCAT(AC4," - ",AD4," - ",H4)),"Error") -> Tier 3 - Renovation - Purchase | AF4: =IFERROR(IF(ISBLANK(E4),"",IF(H4="Purchase","",_xlfn.DAYS(N4,O4))),"Error") | AG4: =IFERROR(IF(ISBLANK(E4),"",IF(OR(H4="Purchase",'Pricing Confirm'!AF4<365),MIN('Pricing Confirm'!R4,'Pricing Confirm'!P4+'Pricing Confirm'!Q4),'Pricing Confirm'!R4)),"Error") -> 350000 | AH4: =IFERROR(IF(ISBLANK(E4),"",IF(J4="Y",AG4+Z4+S4,AG4+S4)),"Error") -> 425000 | AI4: =IFERROR(IF(ISBLANK(E4),"",X4/AG4),"Error") -> 0.78571429 | AJ4: =IFERROR(IF(ISBLANK(E4),"",AA4/AH4),"Error") -> 0.82352941 | AK4: =IFERROR(IF(OR(ISBLANK(E4),T4<1,ISBLANK(T4)),"",AA4/T4),"Error") -> 0.7 | AL4: =IFERROR(IF(ISBLANK(E4),"",INDEX('Rate Sheet'!$I$4:$I$39,MATCH('Pricing Confirm'!AE4,'Rate Sheet'!$G$4:$G$39,0))),"Error") -> 0.85 | AM4: =IFERROR(IF(ISBLANK(E4),"",INDEX('Rate Sheet'!$H$4:$H$39,MATCH('Pricing Confirm'!AE4,'Rate Sheet'!$G$4:$G$39,0))),"Error") -> 0.85 | AN4: =IFERROR(IF(ISBLANK(E4),"",INDEX('Rate Sheet'!$J$4:$J$39,MATCH('Pricing Confirm'!AE4,'Rate Sheet'!$G$4:$G$39,0))),"Error") -> 0.7 | AO4: =IFERROR(IF(ISBLANK(E4),"",IF(AND(ISNUMBER(AI4+AL4),AI4>AL4),"FAIL","PASS")),"Error") -> PASS | AP4: =IFERROR(IF(ISBLANK(E4),"",IF(AND(ISNUMBER(AJ4+AM4),AJ4>AM4),"FAIL","PASS")),"Error") -> PASS | AQ4: =IFERROR(IF(ISBLANK(E4),"",IF(AND(ISNUMBER(AK4+AN4),AK4>AN4),"FAIL","PASS")),"Error") -> PASS | AR4: =IFERROR(IF(ISBLANK(E4),"",IF(SUM(X4:Y4)=AA4,"PASS","FAIL")),"Error") -> PASS | AS4: =IFERROR(IF(ISBLANK(E4),"",IF(Y4=S4,"PASS","FAIL")),"Error") -> PASS | AT4: =IFERROR(IF(ISBLANK(E4),"",IF(AND(NOT(S4=0),T4<AH4),"FAIL","PASS")),"Error") -> PASS | AU4: =IFERROR(IF(ISBLANK(E4),"",INDEX('Rate Sheet'!$N$4:$N$54,MATCH('Pricing Confirm'!I4,'Rate Sheet'!$M$4:$M$54,0))),"Error") -> Pass | AV4: =IFERROR(IF(ISBLANK(E4),"",IF(OR(AA4>'Rate Sheet'!$C$29,'Pricing Confirm'!AA4<'Rate Sheet'!$C$30),"FAIL","PASS")),"Error") -> PASS | AW4: =IFERROR(IF(ISBLANK(E4),"",IF(V4>1,"FAIL","PASS")),"Error") -> PASS | AX4: =IFERROR(IF(ISBLANK(E4),"",IF(J4="Y",ROUND(AA4*W4*(U4/12)*0.75,2),0)),"Error") -> 0 | AY4: =IFERROR(IF(ISBLANK(E4),"",IF(AND(J4="Y",AX4>Z4),"FAIL","PASS")),"Error") -> PASS | AZ4: =IFERROR(IF(ISBLANK(E4),"",INDEX('Rate Sheet'!$K$4:$K$39,MATCH('Pricing Confirm'!AE4,'Rate Sheet'!$G$4:$G$39,0))),"Error") -> 0.0925 | BA4: =IFERROR(IF(ISBLANK(E4),"",INDEX('Rate Sheet'!$C$9:$C$11,MATCH('Pricing Confirm'!U4,'Rate Sheet'!$B$9:$B$11,0))),"Error") -> Error | BB4: =IFERROR(IF(ISBLANK(E4),"",_xlfn.XLOOKUP(F4,'Rate Sheet'!$B$13:$B$15,'Rate Sheet'!$C$13:$C$15,,-1)),"Error") -> -0.0025 | BC4: =IFERROR(IF(ISBLANK(E4),"",_xlfn.XLOOKUP('Pricing Confirm'!AA4,'Rate Sheet'!$B$17:$B$18,'Rate Sheet'!$C$17:$C$18,,-1)),"Error") -> 0 | BD4: =IFERROR(IF(ISBLANK(E4),"",INDEX('Rate Sheet'!$C$20:$C$27,MATCH('Pricing Confirm'!K4,'Rate Sheet'!$B$20:$B$27,0))),"Error") -> 0 | BE4: =IFERROR(IF(ISBLANK(E4),"",AZ4+BA4+BB4+BC4+BD4),"Not Qual") -> Not Qual | BF4: =IFERROR(IF(ISBLANK(E4),"",IF(AND(AO4="PASS",AP4="PASS",AQ4="PASS",AR4="PASS",AS4="PASS",AT4="PASS",AU4="PASS",AV4="PASS",AY4="PASS",AW4="PASS"),BE4,"Not Qual")),"Error") -> Not Qual
B5: =BF5 -> Not Qual | C5: =IFERROR(W5-B5,"N/A") -> N/A | E5: ='Bid Tape'!#REF! -> #REF! | F5: ='Bid Tape'!#REF! -> #REF! | G5: ='Bid Tape'!#REF! -> #REF! | H5: ='Bid Tape'!#REF! -> #REF! | I5: ='Bid Tape'!#REF! -> #REF! | J5: ='Bid Tape'!#REF! -> #REF! | K5: ='Bid Tape'!#REF! -> #REF! | L5: ='Bid Tape'!#REF! -> #REF! | ... AA5: ='Bid Tape'!#REF! -> #REF! | AC5: =IFERROR(IF(ISBLANK(E5),"",IF(F5>=_xlfn.XLOOKUP(G5,'Rate Sheet'!$D$4:$D$6,'Rate Sheet'!$C$4:$C$6,,-1),_xlfn.XLOOKUP(G5,'Rate Sheet'!$D$4:$D$6,'Rate Sheet'!$B$4:$B$6,,-1),"Not Qual")),"Error") -> Error | AD5: =IFERROR(IF(ISBLANK(E5),"",IF(J5="Y",'Rate Sheet'!$G$42,IF(OR('Pricing Confirm'!S5>'Pricing Confirm'!R5*0.5,'Pricing Confirm'!M5-'Pricing Confirm'!L5>249),'Rate Sheet'!$G$45,IF('Pricing Confirm'!S5=0,'Rate Sheet'!$G$43,'Rate Sheet'!$G$44)))),"Error") -> Error | AE5: =IFERROR(IF(ISBLANK(E5),"",_xlfn.CONCAT(AC5," - ",AD5," - ",H5)),"Error") -> Error | AF5: =IFERROR(IF(ISBLANK(E5),"",IF(H5="Purchase","",_xlfn.DAYS(N5,O5))),"Error") -> Error | AG5: =IFERROR(IF(ISBLANK(E5),"",IF(OR(H5="Purchase",'Pricing Confirm'!AF5<365),MIN('Pricing Confirm'!R5,'Pricing Confirm'!P5+'Pricing Confirm'!Q5),'Pricing Confirm'!R5)),"Error") -> Error | AH5: =IFERROR(IF(ISBLANK(E5),"",IF(J5="Y",AG5+Z5+S5,AG5+S5)),"Error") -> Error | AI5: =IFERROR(IF(ISBLANK(E5),"",X5/AG5),"Error") -> Error | AJ5: =IFERROR(IF(ISBLANK(E5),"",AA5/AH5),"Error") -> Error | AK5: =IFERROR(IF(OR(ISBLANK(E5),T5<1,ISBLANK(T5)),"",AA5/T5),"Error") -> Error | AL5: =IFERROR(IF(ISBLANK(E5),"",INDEX('Rate Sheet'!$I$4:$I$39,MATCH('Pricing Confirm'!AE5,'Rate Sheet'!$G$4:$G$39,0))),"Error") -> Error | AM5: =IFERROR(IF(ISBLANK(E5),"",INDEX('Rate Sheet'!$H$4:$H$39,MATCH('Pricing Confirm'!AE5,'Rate Sheet'!$G$4:$G$39,0))),"Error") -> Error | AN5: =IFERROR(IF(ISBLANK(E5),"",INDEX('Rate Sheet'!$J$4:$J$39,MATCH('Pricing Confirm'!AE5,'Rate Sheet'!$G$4:$G$39,0))),"Error") -> Error | AO5: =IFERROR(IF(ISBLANK(E5),"",IF(AND(ISNUMBER(AI5+AL5),AI5>AL5),"FAIL","PASS")),"Error") -> PASS | AP5: =IFERROR(IF(ISBLANK(E5),"",IF(AND(ISNUMBER(AJ5+AM5),AJ5>AM5),"FAIL","PASS")),"Error") -> PASS | AQ5: =IFERROR(IF(ISBLANK(E5),"",IF(AND(ISNUMBER(AK5+AN5),AK5>AN5),"FAIL","PASS")),"Error") -> PASS | AR5: =IFERROR(IF(ISBLANK(E5),"",IF(SUM(X5:Y5)=AA5,"PASS","FAIL")),"Error") -> Error | AS5: =IFERROR(IF(ISBLANK(E5),"",IF(Y5=S5,"PASS","FAIL")),"Error") -> Error | AT5: =IFERROR(IF(ISBLANK(E5),"",IF(AND(NOT(S5=0),T5<AH5),"FAIL","PASS")),"Error") -> Error | AU5: =IFERROR(IF(ISBLANK(E5),"",INDEX('Rate Sheet'!$N$4:$N$54,MATCH('Pricing Confirm'!I5,'Rate Sheet'!$M$4:$M$54,0))),"Error") -> Error | AV5: =IFERROR(IF(ISBLANK(E5),"",IF(OR(AA5>'Rate Sheet'!$C$29,'Pricing Confirm'!AA5<'Rate Sheet'!$C$30),"FAIL","PASS")),"Error") -> Error | AW5: =IFERROR(IF(ISBLANK(E5),"",IF(V5>1,"FAIL","PASS")),"Error") -> Error | AX5: =IFERROR(IF(ISBLANK(E5),"",IF(J5="Y",ROUND(AA5*W5*(U5/12)*0.75,2),0)),"Error") -> Error | AY5: =IFERROR(IF(ISBLANK(E5),"",IF(AND(J5="Y",AX5>Z5),"FAIL","PASS")),"Error") -> Error | AZ5: =IFERROR(IF(ISBLANK(E5),"",INDEX('Rate Sheet'!$K$4:$K$39,MATCH('Pricing Confirm'!AE5,'Rate Sheet'!$G$4:$G$39,0))),"Error") -> Error | BA5: =IFERROR(IF(ISBLANK(E5),"",INDEX('Rate Sheet'!$C$9:$C$11,MATCH('Pricing Confirm'!U5,'Rate Sheet'!$B$9:$B$11,0))),"Error") -> Error | BB5: =IFERROR(IF(ISBLANK(E5),"",_xlfn.XLOOKUP(F5,'Rate Sheet'!$B$13:$B$15,'Rate Sheet'!$C$13:$C$15,,-1)),"Error") -> Error | BC5: =IFERROR(IF(ISBLANK(E5),"",_xlfn.XLOOKUP('Pricing Confirm'!AA5,'Rate Sheet'!$B$17:$B$18,'Rate Sheet'!$C$17:$C$18,,-1)),"Error") -> Error | BD5: =IFERROR(IF(ISBLANK(E5),"",INDEX('Rate Sheet'!$C$20:$C$27,MATCH('Pricing Confirm'!K5,'Rate Sheet'!$B$20:$B$27,0))),"Error") -> Error | BE5: =IFERROR(IF(ISBLANK(E5),"",SUM(AZ5:BD5)),"Error") -> 0 | BF5: =IFERROR(IF(ISBLANK(E5),"",IF(AND(AO5="PASS",AP5="PASS",AQ5="PASS",AR5="PASS",AS5="PASS",AT5="PASS",AU5="PASS",AV5="PASS",AY5="PASS",AW5="PASS"),BE5,"Not Qual")),"Error") -> Not Qual
B6: =BF6 -> Not Qual | C6: =IFERROR(W6-B6,"N/A") -> N/A | E6: ='Bid Tape'!#REF! -> #REF! | F6: ='Bid Tape'!#REF! -> #REF! | G6: ='Bid Tape'!#REF! -> #REF! | H6: ='Bid Tape'!#REF! -> #REF! | I6: ='Bid Tape'!#REF! -> #REF! | J6: ='Bid Tape'!#REF! -> #REF! | K6: ='Bid Tape'!#REF! -> #REF! | L6: ='Bid Tape'!#REF! -> #REF! | ... AA6: ='Bid Tape'!#REF! -> #REF! | AC6: =IFERROR(IF(ISBLANK(E6),"",IF(F6>=_xlfn.XLOOKUP(G6,'Rate Sheet'!$D$4:$D$6,'Rate Sheet'!$C$4:$C$6,,-1),_xlfn.XLOOKUP(G6,'Rate Sheet'!$D$4:$D$6,'Rate Sheet'!$B$4:$B$6,,-1),"Not Qual")),"Error") -> Error | AD6: =IFERROR(IF(ISBLANK(E6),"",IF(J6="Y",'Rate Sheet'!$G$42,IF(OR('Pricing Confirm'!S6>'Pricing Confirm'!R6*0.5,'Pricing Confirm'!M6-'Pricing Confirm'!L6>249),'Rate Sheet'!$G$45,IF('Pricing Confirm'!S6=0,'Rate Sheet'!$G$43,'Rate Sheet'!$G$44)))),"Error") -> Error | AE6: =IFERROR(IF(ISBLANK(E6),"",_xlfn.CONCAT(AC6," - ",AD6," - ",H6)),"Error") -> Error | AF6: =IFERROR(IF(ISBLANK(E6),"",IF(H6="Purchase","",_xlfn.DAYS(N6,O6))),"Error") -> Error | AG6: =IFERROR(IF(ISBLANK(E6),"",IF(OR(H6="Purchase",'Pricing Confirm'!AF6<365),MIN('Pricing Confirm'!R6,'Pricing Confirm'!P6+'Pricing Confirm'!Q6),'Pricing Confirm'!R6)),"Error") -> Error | AH6: =IFERROR(IF(ISBLANK(E6),"",IF(J6="Y",AG6+Z6+S6,AG6+S6)),"Error") -> Error | AI6: =IFERROR(IF(ISBLANK(E6),"",X6/AG6),"Error") -> Error | AJ6: =IFERROR(IF(ISBLANK(E6),"",AA6/AH6),"Error") -> Error | AK6: =IFERROR(IF(OR(ISBLANK(E6),T6<1,ISBLANK(T6)),"",AA6/T6),"Error") -> Error | AL6: =IFERROR(IF(ISBLANK(E6),"",INDEX('Rate Sheet'!$I$4:$I$39,MATCH('Pricing Confirm'!AE6,'Rate Sheet'!$G$4:$G$39,0))),"Error") -> Error | AM6: =IFERROR(IF(ISBLANK(E6),"",INDEX('Rate Sheet'!$H$4:$H$39,MATCH('Pricing Confirm'!AE6,'Rate Sheet'!$G$4:$G$39,0))),"Error") -> Error | AN6: =IFERROR(IF(ISBLANK(E6),"",INDEX('Rate Sheet'!$J$4:$J$39,MATCH('Pricing Confirm'!AE6,'Rate Sheet'!$G$4:$G$39,0))),"Error") -> Error | AO6: =IFERROR(IF(ISBLANK(E6),"",IF(AND(ISNUMBER(AI6+AL6),AI6>AL6),"FAIL","PASS")),"Error") -> PASS | AP6: =IFERROR(IF(ISBLANK(E6),"",IF(AND(ISNUMBER(AJ6+AM6),AJ6>AM6),"FAIL","PASS")),"Error") -> PASS | AQ6: =IFERROR(IF(ISBLANK(E6),"",IF(AND(ISNUMBER(AK6+AN6),AK6>AN6),"FAIL","PASS")),"Error") -> PASS | AR6: =IFERROR(IF(ISBLANK(E6),"",IF(SUM(X6:Y6)=AA6,"PASS","FAIL")),"Error") -> Error | AS6: =IFERROR(IF(ISBLANK(E6),"",IF(Y6=S6,"PASS","FAIL")),"Error") -> Error | AT6: =IFERROR(IF(ISBLANK(E6),"",IF(AND(NOT(S6=0),T6<AH6),"FAIL","PASS")),"Error") -> Error | AU6: =IFERROR(IF(ISBLANK(E6),"",INDEX('Rate Sheet'!$N$4:$N$54,MATCH('Pricing Confirm'!I6,'Rate Sheet'!$M$4:$M$54,0))),"Error") -> Error | AV6: =IFERROR(IF(ISBLANK(E6),"",IF(OR(AA6>'Rate Sheet'!$C$29,'Pricing Confirm'!AA6<'Rate Sheet'!$C$30),"FAIL","PASS")),"Error") -> Error | AW6: =IFERROR(IF(ISBLANK(E6),"",IF(V6>1,"FAIL","PASS")),"Error") -> Error | AX6: =IFERROR(IF(ISBLANK(E6),"",IF(J6="Y",ROUND(AA6*W6*(U6/12)*0.75,2),0)),"Error") -> Error | AY6: =IFERROR(IF(ISBLANK(E6),"",IF(AND(J6="Y",AX6>Z6),"FAIL","PASS")),"Error") -> Error | AZ6: =IFERROR(IF(ISBLANK(E6),"",INDEX('Rate Sheet'!$K$4:$K$39,MATCH('Pricing Confirm'!AE6,'Rate Sheet'!$G$4:$G$39,0))),"Error") -> Error | BA6: =IFERROR(IF(ISBLANK(E6),"",INDEX('Rate Sheet'!$C$9:$C$11,MATCH('Pricing Confirm'!U6,'Rate Sheet'!$B$9:$B$11,0))),"Error") -> Error | BB6: =IFERROR(IF(ISBLANK(E6),"",_xlfn.XLOOKUP(F6,'Rate Sheet'!$B$13:$B$15,'Rate Sheet'!$C$13:$C$15,,-1)),"Error") -> Error | BC6: =IFERROR(IF(ISBLANK(E6),"",_xlfn.XLOOKUP('Pricing Confirm'!AA6,'Rate Sheet'!$B$17:$B$18,'Rate Sheet'!$C$17:$C$18,,-1)),"Error") -> Error | BD6: =IFERROR(IF(ISBLANK(E6),"",INDEX('Rate Sheet'!$C$20:$C$27,MATCH('Pricing Confirm'!K6,'Rate Sheet'!$B$20:$B$27,0))),"Error") -> Error | BE6: =IFERROR(IF(ISBLANK(E6),"",SUM(AZ6:BD6)),"Error") -> 0 | BF6: =IFERROR(IF(ISBLANK(E6),"",IF(AND(AO6="PASS",AP6="PASS",AQ6="PASS",AR6="PASS",AS6="PASS",AT6="PASS",AU6="PASS",AV6="PASS",AY6="PASS",AW6="PASS"),BE6,"Not Qual")),"Error") -> Not Qual
B7: =BF7 -> Not Qual | C7: =IFERROR(W7-B7,"N/A") -> N/A | E7: ='Bid Tape'!#REF! -> #REF! | F7: ='Bid Tape'!#REF! -> #REF! | G7: ='Bid Tape'!#REF! -> #REF! | H7: ='Bid Tape'!#REF! -> #REF! | I7: ='Bid Tape'!#REF! -> #REF! | J7: ='Bid Tape'!#REF! -> #REF! | K7: ='Bid Tape'!#REF! -> #REF! | L7: ='Bid Tape'!#REF! -> #REF! | ... AA7: ='Bid Tape'!#REF! -> #REF! | AC7: =IFERROR(IF(ISBLANK(E7),"",IF(F7>=_xlfn.XLOOKUP(G7,'Rate Sheet'!$D$4:$D$6,'Rate Sheet'!$C$4:$C$6,,-1),_xlfn.XLOOKUP(G7,'Rate Sheet'!$D$4:$D$6,'Rate Sheet'!$B$4:$B$6,,-1),"Not Qual")),"Error") -> Error | AD7: =IFERROR(IF(ISBLANK(E7),"",IF(J7="Y",'Rate Sheet'!$G$42,IF(OR('Pricing Confirm'!S7>'Pricing Confirm'!R7*0.5,'Pricing Confirm'!M7-'Pricing Confirm'!L7>249),'Rate Sheet'!$G$45,IF('Pricing Confirm'!S7=0,'Rate Sheet'!$G$43,'Rate Sheet'!$G$44)))),"Error") -> Error | AE7: =IFERROR(IF(ISBLANK(E7),"",_xlfn.CONCAT(AC7," - ",AD7," - ",H7)),"Error") -> Error | AF7: =IFERROR(IF(ISBLANK(E7),"",IF(H7="Purchase","",_xlfn.DAYS(N7,O7))),"Error") -> Error | AG7: =IFERROR(IF(ISBLANK(E7),"",IF(OR(H7="Purchase",'Pricing Confirm'!AF7<365),MIN('Pricing Confirm'!R7,'Pricing Confirm'!P7+'Pricing Confirm'!Q7),'Pricing Confirm'!R7)),"Error") -> Error | AH7: =IFERROR(IF(ISBLANK(E7),"",IF(J7="Y",AG7+Z7+S7,AG7+S7)),"Error") -> Error | AI7: =IFERROR(IF(ISBLANK(E7),"",X7/AG7),"Error") -> Error | AJ7: =IFERROR(IF(ISBLANK(E7),"",AA7/AH7),"Error") -> Error | AK7: =IFERROR(IF(OR(ISBLANK(E7),T7<1,ISBLANK(T7)),"",AA7/T7),"Error") -> Error | AL7: =IFERROR(IF(ISBLANK(E7),"",INDEX('Rate Sheet'!$I$4:$I$39,MATCH('Pricing Confirm'!AE7,'Rate Sheet'!$G$4:$G$39,0))),"Error") -> Error | AM7: =IFERROR(IF(ISBLANK(E7),"",INDEX('Rate Sheet'!$H$4:$H$39,MATCH('Pricing Confirm'!AE7,'Rate Sheet'!$G$4:$G$39,0))),"Error") -> Error | AN7: =IFERROR(IF(ISBLANK(E7),"",INDEX('Rate Sheet'!$J$4:$J$39,MATCH('Pricing Confirm'!AE7,'Rate Sheet'!$G$4:$G$39,0))),"Error") -> Error | AO7: =IFERROR(IF(ISBLANK(E7),"",IF(AND(ISNUMBER(AI7+AL7),AI7>AL7),"FAIL","PASS")),"Error") -> PASS | AP7: =IFERROR(IF(ISBLANK(E7),"",IF(AND(ISNUMBER(AJ7+AM7),AJ7>AM7),"FAIL","PASS")),"Error") -> PASS | AQ7: =IFERROR(IF(ISBLANK(E7),"",IF(AND(ISNUMBER(AK7+AN7),AK7>AN7),"FAIL","PASS")),"Error") -> PASS | AR7: =IFERROR(IF(ISBLANK(E7),"",IF(SUM(X7:Y7)=AA7,"PASS","FAIL")),"Error") -> Error | AS7: =IFERROR(IF(ISBLANK(E7),"",IF(Y7=S7,"PASS","FAIL")),"Error") -> Error | AT7: =IFERROR(IF(ISBLANK(E7),"",IF(AND(NOT(S7=0),T7<AH7),"FAIL","PASS")),"Error") -> Error | AU7: =IFERROR(IF(ISBLANK(E7),"",INDEX('Rate Sheet'!$N$4:$N$54,MATCH('Pricing Confirm'!I7,'Rate Sheet'!$M$4:$M$54,0))),"Error") -> Error | AV7: =IFERROR(IF(ISBLANK(E7),"",IF(OR(AA7>'Rate Sheet'!$C$29,'Pricing Confirm'!AA7<'Rate Sheet'!$C$30),"FAIL","PASS")),"Error") -> Error | AW7: =IFERROR(IF(ISBLANK(E7),"",IF(V7>1,"FAIL","PASS")),"Error") -> Error | AX7: =IFERROR(IF(ISBLANK(E7),"",IF(J7="Y",ROUND(AA7*W7*(U7/12)*0.75,2),0)),"Error") -> Error | AY7: =IFERROR(IF(ISBLANK(E7),"",IF(AND(J7="Y",AX7>Z7),"FAIL","PASS")),"Error") -> Error | AZ7: =IFERROR(IF(ISBLANK(E7),"",INDEX('Rate Sheet'!$K$4:$K$39,MATCH('Pricing Confirm'!AE7,'Rate Sheet'!$G$4:$G$39,0))),"Error") -> Error | BA7: =IFERROR(IF(ISBLANK(E7),"",INDEX('Rate Sheet'!$C$9:$C$11,MATCH('Pricing Confirm'!U7,'Rate Sheet'!$B$9:$B$11,0))),"Error") -> Error | BB7: =IFERROR(IF(ISBLANK(E7),"",_xlfn.XLOOKUP(F7,'Rate Sheet'!$B$13:$B$15,'Rate Sheet'!$C$13:$C$15,,-1)),"Error") -> Error | BC7: =IFERROR(IF(ISBLANK(E7),"",_xlfn.XLOOKUP('Pricing Confirm'!AA7,'Rate Sheet'!$B$17:$B$18,'Rate Sheet'!$C$17:$C$18,,-1)),"Error") -> Error | BD7: =IFERROR(IF(ISBLANK(E7),"",INDEX('Rate Sheet'!$C$20:$C$27,MATCH('Pricing Confirm'!K7,'Rate Sheet'!$B$20:$B$27,0))),"Error") -> Error | BE7: =IFERROR(IF(ISBLANK(E7),"",SUM(AZ7:BD7)),"Error") -> 0 | BF7: =IFERROR(IF(ISBLANK(E7),"",IF(AND(AO7="PASS",AP7="PASS",AQ7="PASS",AR7="PASS",AS7="PASS",AT7="PASS",AU7="PASS",AV7="PASS",AY7="PASS",AW7="PASS"),BE7,"Not Qual")),"Error") -> Not Qual

Sheet Rate Sheet
B3: Borrower Tier | C3: Min FICO | D3: Min Exp | G3: Leverage Matrix | H3: LTC | I3: LTAIV | J3: ARV | K3: Price | M3: State | N3: (Pass/Fail)
B4: Tier 1 | C4: 680 | D4: 10 | G4: Tier 1 - Bridge - Purchase | H4: N/A | I4: 0.8 | J4: N/A | K4: 0.085 | M4: AK | N4: FAIL
B5: Tier 2 | C5: 680 | D5: 5 | G5: Tier 1 - Bridge - Rate/Term | H5: N/A | I5: 0.75 | J5: N/A | K5: 0.085 | M5: AL | N5: Pass
B6: Tier 3 | C6: 700 | D6: 2 | G6: Tier 1 - Bridge - Cashout | H6: N/A | I6: 0.7 | J6: N/A | K6: 0.085 | M6: AR | N6: FAIL
G7: Tier 1 - Renovation - Purchase | H7: 0.93 | I7: 0.9 | J7: 0.75 | K7: 0.0825 | M7: AZ | N7: FAIL
B8: Term | C8: Price Adj | G8: Tier 1 - Renovation - Rate/Term | H8: 0.93 | I8: 0.9 | J8: 0.75 | K8: 0.0825 | M8: CA | N8: FAIL
B9: 12 | C9: 0 | G9: Tier 1 - Renovation - Cashout | H9: N/A | I9: N/A | J9: N/A | K9: 0.0825 | M9: CO | N9: Pass
B10: 15 | C10: 0.0025 | G10: Tier 1 - Heavy Renovation - Purchase | H10: 0.9 | I10: 0.85 | J10: 0.75 | K10: 0.09 | M10: CT | N10: Pass
B11: 18 | C11: 0.005 | G11: Tier 1 - Heavy Renovation - Rate/Term | H11: 0.9 | I11: 0.85 | J11: 0.75 | K11: 0.09 | M11: DC | N11: Pass
B12: FICO | C12: Price Adj | G12: Tier 1 - Heavy Renovation - Cashout | H12: N/A | I12: N/A | J12: N/A | K12: 0.09 | M12: DE | N12: Pass
B13: 740 | C13: -0.0025 | G13: Tier 1 - Construction - Purchase | H13: 0.85 | I13: 0.75 | J13: 0.7 | K13: 0.0925 | M13: FL | N13: FAIL
B14: 700 | C14: 0 | G14: Tier 1 - Construction - Rate/Term | H14: 0.85 | I14: 0.75 | J14: 0.7 | K14: 0.0925 | M14: GA | N14: Pass
B15: 680 | C15: 0.0025 | G15: Tier 1 - Construction - Cashout | H15: N/A | I15: N/A | J15: N/A | K15: 0.0925 | M15: HI | N15: FAIL
B16: TLA | C16: Price Adj | G16: Tier 2 - Bridge - Purchase | H16: N/A | I16: 0.8 | J16: N/A | K16: 0.09 | M16: IA | N16: FAIL
B17: 1500000 | C17: 0.0025 | G17: Tier 2 - Bridge - Rate/Term | H17: N/A | I17: 0.75 | J17: N/A | K17: 0.09 | M17: ID | N17: FAIL
B18: 0 | C18: 0 | G18: Tier 2 - Bridge - Cashout | H18: N/A | I18: 0.7 | J18: N/A | K18: 0.09 | M18: IL | N18: Pass
B19: Property Type | C19: Price Adj | G19: Tier 2 - Renovation - Purchase | H19: 0.9 | I19: 0.875 | J19: 0.75 | K19: 0.0875 | M19: IN | N19: Pass
B20: SFR | C20: 0 | G20: Tier 2 - Renovation - Rate/Term | H20: 0.9 | I20: 0.875 | J20: 0.75 | K20: 0.0875 | M20: KS | N20: Pass
B21: Condo | C21: 0 | G21: Tier 2 - Renovation - Cashout | H21: N/A | I21: N/A | J21: N/A | K21: 0.0875 | M21: KY | N21: Pass
B22: Duplex | C22: 0.005 | G22: Tier 2 - Heavy Renovation - Purchase | H22: 0.85 | I22: 0.8 | J22: 0.7 | K22: 0.095 | M22: LA | N22: FAIL
B23: Triplex | C23: 0.005 | G23: Tier 2 - Heavy Renovation - Rate/Term | H23: 0.85 | I23: 0.8 | J23: 0.7 | K23: 0.095 | M23: MA | N23: Pass
B24: Fourplex | C24: 0.005 | G24: Tier 2 - Heavy Renovation - Cashout | H24: N/A | I24: N/A | J24: N/A | K24: N/A | M24: MD | N24: Pass
B25: Land - Unentitled | C25: 0 | G25: Tier 2 - Construction - Purchase | H25: 0.85 | I25: 0.75 | J25: 0.675 | K25: 0.0975 | M25: ME | N25: FAIL
B26: Land - Entitled | C26: 0 | G26: Tier 2 - Construction - Rate/Term | H26: 0.85 | I26: 0.75 | J26: 0.675 | K26: 0.0975 | M26: MI | N26: Pass
B27: PUD (Planned Urban Development) | C27: 0 | G27: Tier 2 - Construction - Cashout | H27: N/A | I27: N/A | J27: N/A | K27: 0.0975 | M27: MN | N27: FAIL
G28: Tier 3 - Bridge - Purchase | H28: N/A | I28: 0.75 | J28: N/A | K28: 0.095 | M28: MO | N28: FAIL
B29: Max Loan | C29: 3000000 | G29: Tier 3 - Bridge - Rate/Term | H29: N/A | I29: 0.7 | J29: N/A | K29: 0.095 | M29: MS | N29: FAIL
B30: Min Loan | C30: 100000 | G30: Tier 3 - Bridge - Cashout | H30: N/A | I30: 0.65 | J30: N/A | K30: 0.095 | M30: MT | N30: FAIL
G31: Tier 3 - Renovation - Purchase | H31: 0.85 | I31: 0.85 | J31: 0.7 | K31: 0.0925 | M31: NC | N31: Pass
G32: Tier 3 - Renovation - Rate/Term | H32: 0.85 | I32: 0.85 | J32: 0.7 | K32: 0.0925 | M32: ND | N32: FAIL
G33: Tier 3 - Renovation - Cashout | H33: N/A | I33: N/A | J33: N/A | K33: N/A | M33: NE | N33: FAIL
G34: Tier 3 - Heavy Renovation - Purchase | H34: N/A | I34: N/A | J34: N/A | K34: N/A | M34: NH | N34: FAIL
G35: Tier 3 - Heavy Renovation - Rate/Term | H35: N/A | I35: N/A | J35: N/A | K35: N/A | M35: NJ | N35: Pass
G36: Tier 3 - Heavy Renovation - Cashout | H36: N/A | I36: N/A | J36: N/A | K36: N/A | M36: NM | N36: FAIL
G37: Tier 3 - Construction - Purchase | H37: 0.8 | I37: 0.65 | J37: 0.65 | K37: 0.1025 | M37: NV | N37: FAIL
G38: Tier 3 - Construction - Rate/Term | H38: 0.8 | I38: 0.65 | J38: 0.65 | K38: 0.1025 | M38: NY | N38: FAIL
G39: Tier 3 - Construction - Cashout | H39: N/A | I39: N/A | J39: N/A | K39: N/A | M39: OH | N39: Pass
M40: OK | N40: Pass
G41: Loan Types | M41: OR | N41: Pass
G42: Construction | M42: PA | N42: Pass
...
