Workbook
Name ExitLabels: Engine!$R$2:$R$4
Name ExitTokens: Engine!$S$2:$S$4
Name MktLabels: Engine!$P$2:$P$3
Name MktTokens: Engine!$Q$2:$Q$3
Name ProdLabels: Engine!$L$2:$L$4
Name ProdTokens: Engine!$M$2:$M$4
Name PurpLabels: Engine!$N$2:$N$3
Name PurpTokens: Engine!$O$2:$O$3
Name RateKeys: Engine!$A$2:$A$1556
Name RateVals: Engine!$B$2:$B$1556
Name TermsList: Engine!$T$2:$T$4
Name TGKeys: Engine!$E$2:$E$19
Name TGmaxacq: Engine!$H$2:$H$19
Name TGmaxar: Engine!$I$2:$I$19
Name TGmaxloan: Engine!$F$2:$F$19
Name TGmaxltc: Engine!$J$2:$J$19
Name TGminfico: Engine!$G$2:$G$19
Name YesNoList: Engine!$U$2:$U$3

Sheet Pricing Tool
B2: EMCAP RTL — Seller Pricing & Eligibility Tool
B3: Enter the loan details in the yellow cells. Rate, eligibility and required-document flags update automatically. Yellow = input; everything else is locked.
B5: 1. LOAN INPUTS | J5: market token | K5: =INDEX(MktTokens,MATCH(C9,MktLabels,0)) -> STD
B6: Loan Product | C6: Ground-Up Construction (GUC) | J6: size token | K6: =IF(C17<=2500000,"S","L") -> S
B7: Loan Purpose | C7: Purchase | J7: product token | K7: =INDEX(ProdTokens,MATCH(C6,ProdLabels,0)) -> GUC
B8: Requested Term (months) | C8: 18 | J8: purpose token | K8: =INDEX(PurpTokens,MATCH(C7,PurpLabels,0)) -> P
B9: Property Market | C9: Standard (Non-NYC) | J9: term token | K9: =TEXT(C8,"0") -> 18
B10: Property ZIP code | C10: 19133 | J10: exit token | K10: =INDEX(ExitTokens,MATCH(C11,ExitLabels,0)) -> FLIP
B11: Exit Strategy | C11: Fix & Flip (sell) | J11: tier base | K11: =IF(K6="S",IF(C14>=3,1,IF(C14>=1,2,3)),IF(C14>=5,1,IF(C14>=2,2,3))) -> 1
J12: tier num | K12: =IF(C15="Yes",IF(K6="S",MAX(K11,2),3),K11) -> 1
B13: FICO Score | C13: 760 | J13: tier token | K13: ="T"&K12 -> T1
B14: # Comparable projects completed (last 3 yrs) | C14: 5 | J14: arltv ratio | K14: =IF(C20>0,C17/C20,"") -> 0.75
B15: GC-only experience? | C15: No | J15: ltc ratio | K15: =IF((C18+C19)>0,C17/(C18+C19),"") -> 0.92307692
J16: acq ltv ratio | K16: =IF(C18>0,(C17-C19)/C18,"") -> 0.8
B17: Total Loan Amount ($) | C17: 600000 | J17: arltv band | K17: =IF(K14="","",IF(K14<=0.6499,"<64.99%",IF(K14<=0.7,"65.00%-70.00%",IF(K14<=0.75,"70.01%-75.00%",">75%")))) -> 70.01%-75.00%
B18: Purchase / Acquisition Cost ($) | C18: 250000 | J18: fico band | K18: =IF(C13="","",IF(K12=3,IF(C13>=700,"FICO 700+",IF(C13>=680,"FICO 680-699",IF(C13>=640,"FICO 640-679","BELOW"))),IF(C13>=700,"FICO 700+",IF(C13>=660,"FICO 660-699",IF(C13>=640,"FICO 640-659","BELOW"))))) -> FICO 700+
B19: Rehab / Construction Budget ($) | C19: 400000 | J19: ltc band | K19: =IF(K15="","",IF(K15<=0.7499,"<74.99%",IF(K15<=0.8,"75.00%-80.00%",IF(K15<=0.85,"80.01%-85.00%",IF(K15<=0.875,"85.01%-87.50%",IF(K15<=0.8999,"87.51%-89.99%",IF(K15<=0.925,"90.00%-92.50%",">92.5%"))))))) -> 90.00%-92.50%
B20: After-Repair Value — ARV ($) | C20: 800000 | J20: rate key | K20: =_xlfn.TEXTJOIN("|",FALSE(),K5,K6,K7,K8,K9,K13,K17,K18,K19) -> STD|S|GUC|P|18|T1|70.01%-75.00%|FICO 700+|90.00%-92.50%
B21: Note Rate (%) | C21: 0.0925 | J21: rate | K21: =IFERROR(INDEX(RateVals,MATCH(K20,RateKeys,0)),"NO RATE") -> 0.095
J22: tg key | K22: =K7&"|"&K8&"|"&K13 -> GUC|P|T1
B23: Projected DSCR (if Fix & Hold / DSCR) | C23: 0 | J23: tg maxloan | K23: =IFERROR(INDEX(TGmaxloan,MATCH(K22,TGKeys,0)),0) -> 4500000
B24: Cash-Out Amount ($) (if Refinance) | C24: 0 | J24: tg minfico | K24: =IFERROR(INDEX(TGminfico,MATCH(K22,TGKeys,0)),"") -> 640
B25: Projected Project Profit ($) (if Refinance) | C25: 0 | J25: tg maxacq | K25: =IFERROR(INDEX(TGmaxacq,MATCH(K22,TGKeys,0)),"") -> 0.8
B26: 2. AUTO-CLASSIFICATION | J26: tg maxar | K26: =IFERROR(INDEX(TGmaxar,MATCH(K22,TGKeys,0)),"") -> 0.75
B27: Acq-LTV | C27: =IF(K16="","n/a",K16) -> 0.8 | J27: tg maxltc | K27: =IFERROR(INDEX(TGmaxltc,MATCH(K22,TGKeys,0)),"") -> 0.925
B28: LTC | C28: =IF(K15="","n/a",K15) -> 0.92307692 | J28: zip prefix | K28: =IF(C10="","",LEFT(TEXT(C10,"00000"),3)) -> 191
B29: AR-LTV | C29: =IF(K14="","n/a",K14) -> 0.75 | J29: geo fail | K29: =IF(OR(K28="191",K28="606",K28="607",K28="608"),1,0) -> 1
B30: Loan-size band | C30: =IF(K6="S","$100k – $2.5M","$2.5M – $4.5M") -> $100k – $2.5M | J30: loan fail | K30: =IF(AND(K23>0,C17>K23),1,0) -> 0
B31: Borrower Tier (derived) | C31: ="Tier "&K12&IF(C15="Yes"," (GC-capped)","") -> Tier 1 | J31: fico fail | K31: =IF(AND(ISNUMBER(K24),C13<K24),1,0) -> 0
B32: AR-LTV band | C32: =K17 -> 70.01%-75.00% | J32: acq fail | K32: =IF(AND(ISNUMBER(K25),K16<>"",K16>K25),1,0) -> 0
B33: FICO band | C33: =K18 -> FICO 700+ | J33: ar fail | K33: =IF(AND(ISNUMBER(K26),K14<>"",K14>K26),1,0) -> 0
B34: LTC band | C34: =K19 -> 90.00%-92.50% | J34: ltc fail | K34: =IF(AND(ISNUMBER(K27),K15<>"",K15>K27),1,0) -> 0
J35: term fail | K35: =IF(K9="12",0,IF(K9="18",IF(OR(K7<>"FF",C19>100000),0,1),IF(OR(K7<>"FF",C19>200000),0,1))) -> 0
B36: 3. PRICING RESULT | J36: combo fail | K36: =IF(K21="NO RATE",1,0) -> 0
B37: Indicative Buy Rate | C37: =IF(K39>0,"NA",IF(OR(C21="",C21=0),"",MAX(K21,C21-0.01))) -> NA | D37: =IF(OR(K39>0,C21="",C21=0),"",IF(K21<C21-0.01,"Grid "&TEXT(K21,"0.000%")&" lifted to Note Rate − 1.00 pt floor","At grid rate (Note − 1.00 pt floor not binding)")) | J37: dscr fail | K37: =IF(AND(K10="HOLD",C23>0,C23<1),1,0) -> 0
B38: Eligibility Decision | C38: =IF(K39=0,"ELIGIBLE","INELIGIBLE / REVIEW") -> INELIGIBLE / REVIEW | J38: cashout fail | K38: =IF(AND(K8="R",C24>0,C25>0,C24>0.5*C25),1,0) -> 0
B39: Flags / Reasons | C39: =_xlfn.TEXTJOIN(" • ",TRUE(),IF(K29=1,"Geography excluded → "&K42,""),IF(K30=1,"Loan $"&TEXT(C17,"#,##0")&" exceeds tier max ($"&TEXT(K23,"#,##0")&") → "&K43,""),IF(K31=1,"FICO "&C13&" below tier min → "&K44,""),IF(K32=1,"Acq-LTV exceeds max → "&K45,""),IF(K33=1,"AR-LTV exceeds max → "&K46,""),IF(K34=1,"LTC exceeds max → "&K47,""),IF(K40=1,"LTC not greater than AR-LTV → "&K48,""),IF(K35=1,"Term not eligible → "&K49,""),IF(K36=1,"No grid rate → "&K50,""),IF(K37=1,"DSCR below 1.00 → "&K51,""),IF(K38=1,"Cash-out exceeds 50% of profit → "&K52,"")) -> Geography excluded → Property must be outside excluded markets (not ZIP 191xx / 606–608xx) | J39: hardfails | K39: =SUM(K29:K38)+K40 -> 1
B40: Indicative only — subject to full underwriting, appraisal review, and the conditions below. | J40: ltc<=ar fail | K40: =IF(AND(K14<>"",K15<>"",K15<=K14),1,0) -> 0
B41: =IF(K39>0,"*All submissions resulting in In-Eligible decision can be submitted for individual review - please contact EMCAP Review Team","") -> *All submissions resulting in In-Eligible decision can be submitted for individual review - please contact EMCAP Review Team
B42: 4. ELIGIBILITY DETAIL (vs. Tier Grid) | J42: cure geo | K42: ="Property must be outside excluded markets (not ZIP 191xx / 606–608xx)" -> Property must be outside excluded markets (not ZIP 191xx / 606–608xx)
...

Sheet EMCAP_Pricing Matrix
B1: 12 MONTH TERM | V1: 18 MONTH TERM | AP1: 24 MONTH TERM
B2: Loan Sizes $100k-$2.5m | V2: Loan Sizes $100k-$2.5m | AP2: Loan Sizes $100k-$2.5m
B3: All loan products are eligible for 12 month terms | V3: GUC product -- F&F product w/ over $100k budget -- F&H product -- Bridge product eligible for 18 month terms (profitability calcs will be run at term) | AP3: GUC product -- F&F product w/ over $200k budget -- F&H product -- Bridge product eligible for 24 month terms (profitability calcs will be run at term)
B5: Pricing Matrix - Purchase Loans (F&F / F&H) | L5: Pricing Matrix - Refinance Loans (F&F / F&H) | V5: Pricing Matrix - Purchase Loans (F&F / F&H) | AF5: Pricing Matrix - Refinance Loans (F&F / F&H) | AP5: Pricing Matrix - Purchase Loans (F&F / F&H) | AZ5: Pricing Matrix - Refinance Loans (F&F / F&H)
B6: Tier 1 (3+ Proj. Comp. last 3 yrs) | L6: Tier 1 (3+ Proj. Comp. last 3 yrs) | V6: Tier 1 (3+ Proj. Comp. last 3 yrs) | AF6: Tier 1 (3+ Proj. Comp. last 3 yrs) | AP6: Tier 1 (3+ Proj. Comp. last 3 yrs) | AZ6: Tier 1 (3+ Proj. Comp. last 3 yrs)
C7: LTC | M7: LTC | W7: =C7 -> LTC | AG7: =W7 -> LTC | AQ7: =C7 -> LTC | BA7: =C7 -> LTC
B8: AR-LTV | C8: <74.99% | D8: 75.00%-80.00% | E8: 80.01%-85.00% | F8: 85.01%-87.50% | G8: 87.51%-89.99% | H8: 90.00%-92.50% | L8: AR-LTV | M8: <74.99% | N8: 75.00%-80.00% | O8: 80.01%-85.00% | P8: 85.01%-87.50% | Q8: 87.51%-89.99% | R8: 90.00%-92.50% | V8: =B8 -> AR-LTV | W8: =C8 -> <74.99% | X8: =D8 -> 75.00%-80.00% | Y8: =E8 -> 80.01%-85.00% | Z8: =F8 -> 85.01%-87.50% | AA8: =G8 -> 87.51%-89.99% | AB8: =H8 -> 90.00%-92.50% | AF8: =V8 -> AR-LTV | AG8: =W8 -> <74.99% | AH8: =X8 -> 75.00%-80.00% | AI8: =Y8 -> 80.01%-85.00% | AJ8: =Z8 -> 85.01%-87.50% | AK8: =AA8 -> 87.51%-89.99% | AL8: =AB8 -> 90.00%-92.50% | AP8: =B8 -> AR-LTV | AQ8: =C8 -> <74.99% | AR8: =D8 -> 75.00%-80.00% | AS8: =E8 -> 80.01%-85.00% | AT8: =F8 -> 85.01%-87.50% | AU8: =G8 -> 87.51%-89.99% | AV8: =H8 -> 90.00%-92.50% | AZ8: =B8 -> AR-LTV | BA8: =C8 -> <74.99% | BB8: =D8 -> 75.00%-80.00% | BC8: =E8 -> 80.01%-85.00% | BD8: =F8 -> 85.01%-87.50% | BE8: =G8 -> 87.51%-89.99% | BF8: =H8 -> 90.00%-92.50%
B9: 70.01%-75.00% | C9: =C17+0.25% -> 0.0825 | D9: =C9+0.125% -> 0.08375 | E9: =D9+0.125% -> 0.085 | F9: =E9+0.125% -> 0.08625 | G9: =F9+0.125% -> 0.0875 | H9: =G9 -> 0.0875 | L9: 70.01%-75.00% | M9: =M17+0.5% -> 0.11 | N9: =M9+0.25% -> 0.1125 | O9: =N9+0.25% -> 0.115 | P9: NA | Q9: NA | R9: NA | V9: =B9 -> 70.01%-75.00% | W9: =W17+0.25% -> 0.08375 | X9: =W9+0.125% -> 0.085 | Y9: =X9+0.125% -> 0.08625 | Z9: =Y9+0.125% -> 0.0875 | AA9: =Z9+0.125% -> 0.08875 | AB9: =AA9 -> 0.08875 | AF9: =V9 -> 70.01%-75.00% | AG9: =AG17+0.5% -> 0.11125 | AH9: =AG9+0.25% -> 0.11375 | AI9: =AH9+0.25% -> 0.11625 | AJ9: NA | AK9: NA | AL9: NA | AP9: =B9 -> 70.01%-75.00% | AQ9: =AQ17+0.25% -> 0.085 | AR9: =AQ9+0.125% -> 0.08625 | AS9: =AR9+0.125% -> 0.0875 | AT9: =AS9+0.125% -> 0.08875 | AU9: =AT9+0.125% -> 0.09 | AV9: =AU9 -> 0.09 | AZ9: =B9 -> 70.01%-75.00% | BA9: NA | BB9: NA | BC9: NA | BD9: NA | BE9: NA | BF9: NA
B10: FICO 700+ | C10: =C9+0 -> 0.0825 | D10: =D9+0 -> 0.08375 | E10: =E9+0 -> 0.085 | F10: =F9+0 -> 0.08625 | G10: =G9+0 -> 0.0875 | H10: =H9+0 -> 0.0875 | L10: FICO 700+ | M10: =M9+0 -> 0.11 | N10: =N9+0 -> 0.1125 | O10: =O9+0 -> 0.115 | P10: NA | Q10: NA | R10: NA | V10: =B10 -> FICO 700+ | W10: =W9+0 -> 0.08375 | X10: =X9+0 -> 0.085 | Y10: =Y9+0 -> 0.08625 | Z10: =Z9+0 -> 0.0875 | AA10: =AA9+0 -> 0.08875 | AB10: =AB9+0 -> 0.08875 | AF10: =V10 -> FICO 700+ | AG10: =AG9+0 -> 0.11125 | AH10: =AH9+0 -> 0.11375 | AI10: =AI9+0 -> 0.11625 | AJ10: NA | AK10: NA | AL10: NA | AP10: =B10 -> FICO 700+ | AQ10: =AQ9+0 -> 0.085 | AR10: =AR9+0 -> 0.08625 | AS10: =AS9+0 -> 0.0875 | AT10: =AT9+0 -> 0.08875 | AU10: =AU9+0 -> 0.09 | AV10: =AV9+0 -> 0.09 | AZ10: =B10 -> FICO 700+ | BA10: NA | BB10: NA | BC10: NA | BD10: NA | BE10: NA | BF10: NA
B11: FICO 660-699 | C11: =C9+0.5% -> 0.0875 | D11: =D9+0.5% -> 0.08875 | E11: =E9+0.5% -> 0.09 | F11: =F9+0.5% -> 0.09125 | G11: =G9+0.5% -> 0.0925 | H11: =H9+0.5% -> 0.0925 | L11: FICO 660-699 | M11: =M9+0.25% -> 0.1125 | N11: =N9+0.25% -> 0.115 | O11: =O9+0.25% -> 0.1175 | P11: NA | Q11: NA | R11: NA | V11: =B11 -> FICO 660-699 | W11: =W9+0.5% -> 0.08875 | X11: =X9+0.5% -> 0.09 | Y11: =Y9+0.5% -> 0.09125 | Z11: =Z9+0.5% -> 0.0925 | AA11: =AA9+0.5% -> 0.09375 | AB11: =AB9+0.5% -> 0.09375 | AF11: =V11 -> FICO 660-699 | AG11: =AG9+0.5% -> 0.11625 | AH11: =AH9+0.5% -> 0.11875 | AI11: =AI9+0.5% -> 0.12125 | AJ11: NA | AK11: NA | AL11: NA | AP11: =B11 -> FICO 660-699 | AQ11: =AQ9+0.5% -> 0.09 | AR11: =AR9+0.5% -> 0.09125 | AS11: =AS9+0.5% -> 0.0925 | AT11: =AT9+0.5% -> 0.09375 | AU11: =AU9+0.5% -> 0.095 | AV11: =AV9+0.5% -> 0.095 | AZ11: =B11 -> FICO 660-699 | BA11: NA | BB11: NA | BC11: NA | BD11: NA | BE11: NA | BF11: NA
B12: FICO 640-659 | C12: =C9+0.75% -> 0.09 | D12: =D9+0.75% -> 0.09125 | E12: =E9+0.75% -> 0.0925 | F12: =F9+0.75% -> 0.09375 | G12: =G9+0.75% -> 0.095 | H12: NA | L12: FICO 640-659 | M12: =M9+0.5% -> 0.115 | N12: =N9+0.5% -> 0.1175 | O12: =O9+0.5% -> 0.12 | P12: NA | Q12: NA | R12: NA | V12: =B12 -> FICO 640-659 | W12: =W9+0.75% -> 0.09125 | X12: =X9+0.75% -> 0.0925 | Y12: =Y9+0.75% -> 0.09375 | Z12: =Z9+0.75% -> 0.095 | AA12: =AA9+0.75% -> 0.09625 | AB12: =H12 -> NA | AF12: =V12 -> FICO 640-659 | AG12: =AG9+0.75% -> 0.11875 | AH12: =AH9+0.75% -> 0.12125 | AI12: =AI9+0.75% -> 0.12375 | AJ12: NA | AK12: NA | AL12: NA | AP12: =B12 -> FICO 640-659 | AQ12: =AQ9+0.75% -> 0.0925 | AR12: =AR9+0.75% -> 0.09375 | AS12: =AS9+0.75% -> 0.095 | AT12: =AT9+0.75% -> 0.09625 | AU12: =AU9+0.75% -> 0.0975 | AV12: =AV9+0.75% -> 0.0975 | AZ12: =B12 -> FICO 640-659 | BA12: NA | BB12: NA | BC12: NA | BD12: NA | BE12: NA | BF12: NA
B13: 65.00%-70.00% | C13: =C17+0.125% -> 0.08125 | D13: =C13+0.125% -> 0.0825 | E13: =D13+0.125% -> 0.08375 | F13: =E13+0.125% -> 0.085 | G13: =F13+0.125% -> 0.08625 | H13: =G13 -> 0.08625 | L13: 65.00%-70.00% | M13: =M17+0.25% -> 0.1075 | N13: =M13+0.25% -> 0.11 | O13: =N13+0.25% -> 0.1125 | P13: NA | Q13: NA | R13: NA | V13: =B13 -> 65.00%-70.00% | W13: =W17+0.125% -> 0.0825 | X13: =W13+0.125% -> 0.08375 | Y13: =X13+0.125% -> 0.085 | Z13: =Y13+0.125% -> 0.08625 | AA13: =Z13+0.125% -> 0.0875 | AB13: =AA13 -> 0.0875 | AF13: =V13 -> 65.00%-70.00% | AG13: =AG17+0.25% -> 0.10875 | AH13: =AG13+0.25% -> 0.11125 | AI13: =AH13+0.25% -> 0.11375 | AJ13: NA | AK13: NA | AL13: NA | AP13: =B13 -> 65.00%-70.00% | AQ13: =AQ17+0.125% -> 0.08375 | AR13: =AQ13+0.125% -> 0.085 | AS13: =AR13+0.125% -> 0.08625 | AT13: =AS13+0.125% -> 0.0875 | AU13: =AT13+0.125% -> 0.08875 | AV13: =AU13 -> 0.08875 | AZ13: =B13 -> 65.00%-70.00% | BA13: NA | BB13: NA | BC13: NA | BD13: NA | BE13: NA | BF13: NA
B14: FICO 700+ | C14: =C13+0 -> 0.08125 | D14: =D13+0 -> 0.0825 | E14: =E13+0 -> 0.08375 | F14: =F13+0 -> 0.085 | G14: =G13+0 -> 0.08625 | H14: =H13+0 -> 0.08625 | L14: FICO 700+ | M14: =M13+0 -> 0.1075 | N14: =N13+0 -> 0.11 | O14: =O13+0 -> 0.1125 | P14: NA | Q14: NA | R14: NA | V14: =B14 -> FICO 700+ | W14: =W13+0 -> 0.0825 | X14: =X13+0 -> 0.08375 | Y14: =Y13+0 -> 0.085 | Z14: =Z13+0 -> 0.08625 | AA14: =AA13+0 -> 0.0875 | AB14: =AB13+0 -> 0.0875 | AF14: =V14 -> FICO 700+ | AG14: =AG13+0 -> 0.10875 | AH14: =AH13+0 -> 0.11125 | AI14: =AI13+0 -> 0.11375 | AJ14: NA | AK14: NA | AL14: NA | AP14: =B14 -> FICO 700+ | AQ14: =AQ13+0 -> 0.08375 | AR14: =AR13+0 -> 0.085 | AS14: =AS13+0 -> 0.08625 | AT14: =AT13+0 -> 0.0875 | AU14: =AU13+0 -> 0.08875 | AV14: =AV13+0 -> 0.08875 | AZ14: =B14 -> FICO 700+ | BA14: NA | BB14: NA | BC14: NA | BD14: NA | BE14: NA | BF14: NA
B15: FICO 660-699 | C15: =C13+0.5% -> 0.08625 | D15: =D13+0.5% -> 0.0875 | E15: =E13+0.5% -> 0.08875 | F15: =F13+0.5% -> 0.09 | G15: =G13+0.5% -> 0.09125 | H15: =H13+0.5% -> 0.09125 | L15: FICO 660-699 | M15: =M13+0.25% -> 0.11 | N15: =N13+0.25% -> 0.1125 | O15: =O13+0.25% -> 0.115 | P15: NA | Q15: NA | R15: NA | V15: =B15 -> FICO 660-699 | W15: =W13+0.5% -> 0.0875 | X15: =X13+0.5% -> 0.08875 | Y15: =Y13+0.5% -> 0.09 | Z15: =Z13+0.5% -> 0.09125 | AA15: =AA13+0.5% -> 0.0925 | AB15: =AB13+0.5% -> 0.0925 | AF15: =V15 -> FICO 660-699 | AG15: =AG13+0.5% -> 0.11375 | AH15: =AH13+0.5% -> 0.11625 | AI15: =AI13+0.5% -> 0.11875 | AJ15: NA | AK15: NA | AL15: NA | AP15: =B15 -> FICO 660-699 | AQ15: =AQ13+0.5% -> 0.08875 | AR15: =AR13+0.5% -> 0.09 | AS15: =AS13+0.5% -> 0.09125 | AT15: =AT13+0.5% -> 0.0925 | AU15: =AU13+0.5% -> 0.09375 | AV15: =AV13+0.5% -> 0.09375 | AZ15: =B15 -> FICO 660-699 | BA15: NA | BB15: NA | BC15: NA | BD15: NA | BE15: NA | BF15: NA
B16: FICO 640-659 | C16: =C13+0.75% -> 0.08875 | D16: =D13+0.75% -> 0.09 | E16: =E13+0.75% -> 0.09125 | F16: =F13+0.75% -> 0.0925 | G16: =G13+0.75% -> 0.09375 | H16: NA | L16: FICO 640-659 | M16: =M13+0.5% -> 0.1125 | N16: =N13+0.5% -> 0.115 | O16: =O13+0.5% -> 0.1175 | P16: NA | Q16: NA | R16: NA | V16: =B16 -> FICO 640-659 | W16: =W13+0.75% -> 0.09 | X16: =X13+0.75% -> 0.09125 | Y16: =Y13+0.75% -> 0.0925 | Z16: =Z13+0.75% -> 0.09375 | AA16: =AA13+0.75% -> 0.095 | AB16: =H16 -> NA | AF16: =V16 -> FICO 640-659 | AG16: =AG13+0.75% -> 0.11625 | AH16: =AH13+0.75% -> 0.11875 | AI16: =AI13+0.75% -> 0.12125 | AJ16: NA | AK16: NA | AL16: NA | AP16: =B16 -> FICO 640-659 | AQ16: =AQ13+0.75% -> 0.09125 | AR16: =AR13+0.75% -> 0.0925 | AS16: =AS13+0.75% -> 0.09375 | AT16: =AT13+0.75% -> 0.095 | AU16: =AU13+0.75% -> 0.09625 | AV16: =AV13+0.75% -> 0.09625 | AZ16: =B16 -> FICO 640-659 | BA16: NA | BB16: NA | BC16: NA | BD16: NA | BE16: NA | BF16: NA
B17: <64.99% | C17: 0.08 | D17: =C17+0.125% -> 0.08125 | E17: =D17+0.125% -> 0.0825 | F17: =E17+0.125% -> 0.08375 | G17: =F17+0.125% -> 0.085 | H17: =G17 -> 0.085 | L17: <64.99% | M17: 0.105 | N17: =M17+0.25% -> 0.1075 | O17: =N17+0.25% -> 0.11 | P17: NA | Q17: NA | R17: NA | V17: =B17 -> <64.99% | W17: =C17+0.125% -> 0.08125 | X17: =W17+0.125% -> 0.0825 | Y17: =X17+0.125% -> 0.08375 | Z17: =Y17+0.125% -> 0.085 | AA17: =Z17+0.125% -> 0.08625 | AB17: =AA17 -> 0.08625 | AF17: =V17 -> <64.99% | AG17: =M17+0.125% -> 0.10625 | AH17: =AG17+0.25% -> 0.10875 | AI17: =AH17+0.25% -> 0.11125 | AJ17: NA | AK17: NA | AL17: NA | AP17: =B17 -> <64.99% | AQ17: =W17+0.125% -> 0.0825 | AR17: =AQ17+0.125% -> 0.08375 | AS17: =AR17+0.125% -> 0.085 | AT17: =AS17+0.125% -> 0.08625 | AU17: =AT17+0.125% -> 0.0875 | AV17: =AU17 -> 0.0875 | AZ17: =B17 -> <64.99% | BA17: NA | BB17: NA | BC17: NA | BD17: NA | BE17: NA | BF17: NA
B18: FICO 700+ | C18: =C17+0 -> 0.08 | D18: =D17+0 -> 0.08125 | E18: =E17+0 -> 0.0825 | F18: =F17+0 -> 0.08375 | G18: =G17+0 -> 0.085 | H18: =H17+0 -> 0.085 | L18: FICO 700+ | M18: =M17+0 -> 0.105 | N18: =N17+0 -> 0.1075 | O18: =O17+0 -> 0.11 | P18: NA | Q18: NA | R18: NA | V18: =B18 -> FICO 700+ | W18: =W17+0 -> 0.08125 | X18: =X17+0 -> 0.0825 | Y18: =Y17+0 -> 0.08375 | Z18: =Z17+0 -> 0.085 | AA18: =AA17+0 -> 0.08625 | AB18: =AB17+0 -> 0.08625 | AF18: =V18 -> FICO 700+ | AG18: =AG17+0 -> 0.10625 | AH18: =AH17+0 -> 0.10875 | AI18: =AI17+0 -> 0.11125 | AJ18: NA | AK18: NA | AL18: NA | AP18: =B18 -> FICO 700+ | AQ18: =AQ17+0 -> 0.0825 | AR18: =AR17+0 -> 0.08375 | AS18: =AS17+0 -> 0.085 | AT18: =AT17+0 -> 0.08625 | AU18: =AU17+0 -> 0.0875 | AV18: =AV17+0 -> 0.0875 | AZ18: =B18 -> FICO 700+ | BA18: NA | BB18: NA | BC18: NA | BD18: NA | BE18: NA | BF18: NA
B19: FICO 660-699 | C19: =C17+0.5% -> 0.085 | D19: =D17+0.5% -> 0.08625 | E19: =E17+0.5% -> 0.0875 | F19: =F17+0.5% -> 0.08875 | G19: =G17+0.5% -> 0.09 | H19: =H17+0.5% -> 0.09 | L19: FICO 660-699 | M19: =M17+0.25% -> 0.1075 | N19: =N17+0.25% -> 0.11 | O19: =O17+0.25% -> 0.1125 | P19: NA | Q19: NA | R19: NA | V19: =B19 -> FICO 660-699 | W19: =W17+0.5% -> 0.08625 | X19: =X17+0.5% -> 0.0875 | Y19: =Y17+0.5% -> 0.08875 | Z19: =Z17+0.5% -> 0.09 | AA19: =AA17+0.5% -> 0.09125 | AB19: =AB17+0.5% -> 0.09125 | AF19: =V19 -> FICO 660-699 | AG19: =AG17+0.5% -> 0.11125 | AH19: =AH17+0.5% -> 0.11375 | AI19: =AI17+0.5% -> 0.11625 | AJ19: NA | AK19: NA | AL19: NA | AP19: =B19 -> FICO 660-699 | AQ19: =AQ17+0.5% -> 0.0875 | AR19: =AR17+0.5% -> 0.08875 | AS19: =AS17+0.5% -> 0.09 | AT19: =AT17+0.5% -> 0.09125 | AU19: =AU17+0.5% -> 0.0925 | AV19: =AV17+0.5% -> 0.0925 | AZ19: =B19 -> FICO 660-699 | BA19: NA | BB19: NA | BC19: NA | BD19: NA | BE19: NA | BF19: NA
B20: FICO 640-659 | C20: =C17+0.75% -> 0.0875 | D20: =D17+0.75% -> 0.08875 | E20: =E17+0.75% -> 0.09 | F20: =F17+0.75% -> 0.09125 | G20: =G17+0.75% -> 0.0925 | H20: =H17+0.75% -> 0.0925 | L20: FICO 640-659 | M20: =M17+0.5% -> 0.11 | N20: =N17+0.5% -> 0.1125 | O20: =O17+0.5% -> 0.115 | P20: NA | Q20: NA | R20: NA | V20: =B20 -> FICO 640-659 | W20: =W17+0.75% -> 0.08875 | X20: =X17+0.75% -> 0.09 | Y20: =Y17+0.75% -> 0.09125 | Z20: =Z17+0.75% -> 0.0925 | AA20: =AA17+0.75% -> 0.09375 | AB20: =AB17+0.75% -> 0.09375 | AF20: =V20 -> FICO 640-659 | AG20: =AG17+0.75% -> 0.11375 | AH20: =AH17+0.75% -> 0.11625 | AI20: =AI17+0.75% -> 0.11875 | AJ20: NA | AK20: NA | AL20: NA | AP20: =B20 -> FICO 640-659 | AQ20: =AQ17+0.75% -> 0.09 | AR20: =AR17+0.75% -> 0.09125 | AS20: =AS17+0.75% -> 0.0925 | AT20: =AT17+0.75% -> 0.09375 | AU20: =AU17+0.75% -> 0.095 | AV20: =AV17+0.75% -> 0.095 | AZ20: =B20 -> FICO 640-659 | BA20: NA | BB20: NA | BC20: NA | BD20: NA | BE20: NA | BF20: NA
B22: Tier 2 (1-2 Proj. Comp. last 3 yrs) | L22: Tier 2 (1-2 Proj. Comp. last 3 yrs) | V22: Tier 2 (1-2 Proj. Comp. last 3 yrs) | AF22: Tier 2 (1-2 Proj. Comp. last 3 yrs) | AP22: Tier 2 (1-2 Proj. Comp. last 3 yrs) | AZ22: Tier 2 (1-2 Proj. Comp. last 3 yrs)
C23: LTC | M23: LTC | W23: =C23 -> LTC | AG23: =W23 -> LTC | AQ23: =C23 -> LTC | BA23: =C23 -> LTC
B24: AR-LTV | C24: <74.99% | D24: 75.00%-80.00% | E24: 80.01%-85.00% | F24: 85.01%-87.50% | G24: 87.51%-89.99% | H24: 90.00%-92.50% | L24: AR-LTV | M24: <74.99% | N24: 75.00%-80.00% | O24: 80.01%-85.00% | P24: 85.01%-87.50% | Q24: 87.51%-89.99% | R24: 90.00%-92.50% | V24: =B24 -> AR-LTV | W24: =C24 -> <74.99% | X24: =D24 -> 75.00%-80.00% | Y24: =E24 -> 80.01%-85.00% | Z24: =F24 -> 85.01%-87.50% | AA24: =G24 -> 87.51%-89.99% | AB24: =H24 -> 90.00%-92.50% | AF24: =V24 -> AR-LTV | AG24: =W24 -> <74.99% | AH24: =X24 -> 75.00%-80.00% | AI24: =Y24 -> 80.01%-85.00% | AJ24: =Z24 -> 85.01%-87.50% | AK24: =AA24 -> 87.51%-89.99% | AL24: =AB24 -> 90.00%-92.50% | AP24: =B24 -> AR-LTV | AQ24: =C24 -> <74.99% | AR24: =D24 -> 75.00%-80.00% | AS24: =E24 -> 80.01%-85.00% | AT24: =F24 -> 85.01%-87.50% | AU24: =G24 -> 87.51%-89.99% | AV24: =H24 -> 90.00%-92.50% | AZ24: =B24 -> AR-LTV | BA24: =C24 -> <74.99% | BB24: =D24 -> 75.00%-80.00% | BC24: =E24 -> 80.01%-85.00% | BD24: =F24 -> 85.01%-87.50% | BE24: =G24 -> 87.51%-89.99% | BF24: =H24 -> 90.00%-92.50%
B25: 70.01%-75.00% | C25: =C29+0.25% -> 0.0875 | D25: =D29+0.25% -> 0.08875 | E25: =E29+0.25% -> 0.09 | F25: =F29+0.25% -> 0.09125 | G25: =G29+0.25% -> 0.0925 | H25: NA | L25: 70.01%-75.00% | M25: NA | N25: NA | O25: NA | P25: NA | Q25: NA | R25: NA | V25: =B25 -> 70.01%-75.00% | W25: =W29+0.25% -> 0.08875 | X25: =W25+0.125% -> 0.09 | Y25: =X25+0.125% -> 0.09125 | Z25: =Y25+0.125% -> 0.0925 | AA25: =Z25+0.125% -> 0.09375 | AB25: NA | AF25: =V25 -> 70.01%-75.00% | AG25: NA | AH25: NA | AI25: NA | AJ25: NA | AK25: NA | AL25: NA | AP25: =B25 -> 70.01%-75.00% | AQ25: =AQ29+0.25% -> 0.09 | AR25: =AQ25+0.125% -> 0.09125 | AS25: =AR25+0.125% -> 0.0925 | AT25: =AS25+0.125% -> 0.09375 | AU25: =AT25+0.125% -> 0.095 | AV25: NA | AZ25: =B25 -> 70.01%-75.00% | BA25: NA | BB25: NA | BC25: NA | BD25: NA | BE25: NA | BF25: NA
B26: FICO 700+ | C26: =C25+0 -> 0.0875 | D26: =D25+0 -> 0.08875 | E26: =E25+0 -> 0.09 | F26: =F25+0 -> 0.09125 | G26: =G25+0 -> 0.0925 | H26: NA | L26: FICO 700+ | M26: NA | N26: NA | O26: NA | P26: NA | Q26: NA | R26: NA | V26: =B26 -> FICO 700+ | W26: =W25+0 -> 0.08875 | X26: =X25+0 -> 0.09 | Y26: =Y25+0 -> 0.09125 | Z26: =Z25+0 -> 0.0925 | AA26: =AA25+0 -> 0.09375 | AB26: NA | AF26: =V26 -> FICO 700+ | AG26: NA | AH26: NA | AI26: NA | AJ26: NA | AK26: NA | AL26: NA | AP26: =B26 -> FICO 700+ | AQ26: =AQ25+0 -> 0.09 | AR26: =AR25+0 -> 0.09125 | AS26: =AS25+0 -> 0.0925 | AT26: =AT25+0 -> 0.09375 | AU26: =AU25+0 -> 0.095 | AV26: NA | AZ26: =B26 -> FICO 700+ | BA26: NA | BB26: NA | BC26: NA | BD26: NA | BE26: NA | BF26: NA
B27: FICO 660-699 | C27: NA | D27: NA | E27: NA | F27: NA | G27: NA | H27: NA | L27: FICO 660-699 | M27: NA | N27: NA | O27: NA | P27: NA | Q27: NA | R27: NA | V27: =B27 -> FICO 660-699 | W27: NA | X27: NA | Y27: NA | Z27: NA | AA27: NA | AB27: NA | AF27: =V27 -> FICO 660-699 | AG27: NA | AH27: NA | AI27: NA | AJ27: NA | AK27: NA | AL27: NA | AP27: =B27 -> FICO 660-699 | AQ27: NA | AR27: NA | AS27: NA | AT27: NA | AU27: NA | AV27: NA | AZ27: =B27 -> FICO 660-699 | BA27: NA | BB27: NA | BC27: NA | BD27: NA | BE27: NA | BF27: NA
B28: FICO 640-659 | C28: NA | D28: NA | E28: NA | F28: NA | G28: NA | H28: NA | L28: FICO 640-659 | M28: NA | N28: NA | O28: NA | P28: NA | Q28: NA | R28: NA | V28: =B28 -> FICO 640-659 | W28: NA | X28: NA | Y28: NA | Z28: NA | AA28: NA | AB28: NA | AF28: =V28 -> FICO 640-659 | AG28: NA | AH28: NA | AI28: NA | AJ28: NA | AK28: NA | AL28: NA | AP28: =B28 -> FICO 640-659 | AQ28: NA | AR28: NA | AS28: NA | AT28: NA | AU28: NA | AV28: NA | AZ28: =B28 -> FICO 640-659 | BA28: NA | BB28: NA | BC28: NA | BD28: NA | BE28: NA | BF28: NA
B29: 65.00%-70.00% | C29: =C33+0.25% -> 0.085 | D29: =C29+0.125% -> 0.08625 | E29: =D29+0.125% -> 0.0875 | F29: =E29+0.125% -> 0.08875 | G29: =F29+0.125% -> 0.09 | H29: =G29 -> 0.09 | L29: 65.00%-70.00% | M29: =M33+0.25% -> 0.1075 | N29: =M29+0.25% -> 0.11 | O29: NA | P29: NA | Q29: NA | R29: NA | V29: =B29 -> 65.00%-70.00% | W29: =W33+0.25% -> 0.08625 | X29: =W29+0.125% -> 0.0875 | Y29: =X29+0.125% -> 0.08875 | Z29: =Y29+0.125% -> 0.09 | AA29: =Z29+0.125% -> 0.09125 | AB29: =AA29 -> 0.09125 | AF29: =V29 -> 65.00%-70.00% | AG29: NA | AH29: NA | AI29: NA | AJ29: NA | AK29: NA | AL29: NA | AP29: =B29 -> 65.00%-70.00% | AQ29: =AQ33+0.25% -> 0.0875 | AR29: =AQ29+0.125% -> 0.08875 | AS29: =AR29+0.125% -> 0.09 | AT29: =AS29+0.125% -> 0.09125 | AU29: =AT29+0.125% -> 0.0925 | AV29: =AU29 -> 0.0925 | AZ29: =B29 -> 65.00%-70.00% | BA29: NA | BB29: NA | BC29: NA | BD29: NA | BE29: NA | BF29: NA
B30: FICO 700+ | C30: =C29+0 -> 0.085 | D30: =D29+0 -> 0.08625 | E30: =E29+0 -> 0.0875 | F30: =F29+0 -> 0.08875 | G30: =G29+0 -> 0.09 | H30: =H29+0 -> 0.09 | L30: FICO 700+ | M30: =M29+0 -> 0.1075 | N30: =N29+0 -> 0.11 | O30: NA | P30: NA | Q30: NA | R30: NA | V30: =B30 -> FICO 700+ | W30: =W29+0 -> 0.08625 | X30: =X29+0 -> 0.0875 | Y30: =Y29+0 -> 0.08875 | Z30: =Z29+0 -> 0.09 | AA30: =AA29+0 -> 0.09125 | AB30: =AB29+0 -> 0.09125 | AF30: =V30 -> FICO 700+ | AG30: NA | AH30: NA | AI30: NA | AJ30: NA | AK30: NA | AL30: NA | AP30: =B30 -> FICO 700+ | AQ30: =AQ29+0 -> 0.0875 | AR30: =AR29+0 -> 0.08875 | AS30: =AS29+0 -> 0.09 | AT30: =AT29+0 -> 0.09125 | AU30: =AU29+0 -> 0.0925 | AV30: =AV29+0 -> 0.0925 | AZ30: =B30 -> FICO 700+ | BA30: NA | BB30: NA | BC30: NA | BD30: NA | BE30: NA | BF30: NA
B31: FICO 660-699 | C31: =C29+0.5% -> 0.09 | D31: =D29+0.5% -> 0.09125 | E31: =E29+0.5% -> 0.0925 | F31: =F29+0.5% -> 0.09375 | G31: =G29+0.5% -> 0.095 | H31: =H29+0.5% -> 0.095 | L31: FICO 660-699 | M31: =M29+0.25% -> 0.11 | N31: =N29+0.25% -> 0.1125 | O31: NA | P31: NA | Q31: NA | R31: NA | V31: =B31 -> FICO 660-699 | W31: =W29+0.5% -> 0.09125 | X31: =X29+0.5% -> 0.0925 | Y31: =Y29+0.5% -> 0.09375 | Z31: =Z29+0.5% -> 0.095 | AA31: =AA29+0.5% -> 0.09625 | AB31: =AB29+0.5% -> 0.09625 | AF31: =V31 -> FICO 660-699 | AG31: NA | AH31: NA | AI31: NA | AJ31: NA | AK31: NA | AL31: NA | AP31: =B31 -> FICO 660-699 | AQ31: =AQ29+0.5% -> 0.0925 | AR31: =AR29+0.5% -> 0.09375 | AS31: =AS29+0.5% -> 0.095 | AT31: =AT29+0.5% -> 0.09625 | AU31: =AU29+0.5% -> 0.0975 | AV31: =AV29+0.5% -> 0.0975 | AZ31: =B31 -> FICO 660-699 | BA31: NA | BB31: NA | BC31: NA | BD31: NA | BE31: NA | BF31: NA
B32: FICO 640-659 | C32: NA | D32: NA | E32: NA | F32: NA | G32: NA | H32: NA | L32: FICO 640-659 | M32: NA | N32: NA | O32: NA | P32: NA | Q32: NA | R32: NA | V32: =B32 -> FICO 640-659 | W32: NA | X32: NA | Y32: NA | Z32: NA | AA32: NA | AB32: NA | AF32: =V32 -> FICO 640-659 | AG32: NA | AH32: NA | AI32: NA | AJ32: NA | AK32: NA | AL32: NA | AP32: =B32 -> FICO 640-659 | AQ32: NA | AR32: NA | AS32: NA | AT32: NA | AU32: NA | AV32: NA | AZ32: =B32 -> FICO 640-659 | BA32: NA | BB32: NA | BC32: NA | BD32: NA | BE32: NA | BF32: NA
B33: <64.99% | C33: 0.0825 | D33: =C33+0.125% -> 0.08375 | E33: =D33+0.125% -> 0.085 | F33: =E33+0.125% -> 0.08625 | G33: =F33+0.125% -> 0.0875 | H33: =G33 -> 0.0875 | L33: <64.99% | M33: 0.105 | N33: =M33+0.25% -> 0.1075 | O33: NA | P33: NA | Q33: NA | R33: NA | V33: =B33 -> <64.99% | W33: =C33+0.125% -> 0.08375 | X33: =W33+0.125% -> 0.085 | Y33: =X33+0.125% -> 0.08625 | Z33: =Y33+0.125% -> 0.0875 | AA33: =Z33+0.125% -> 0.08875 | AB33: =AA33 -> 0.08875 | AF33: =V33 -> <64.99% | AG33: NA | AH33: NA | AI33: NA | AJ33: NA | AK33: NA | AL33: NA | AP33: =B33 -> <64.99% | AQ33: =W33+0.125% -> 0.085 | AR33: =AQ33+0.125% -> 0.08625 | AS33: =AR33+0.125% -> 0.0875 | AT33: =AS33+0.125% -> 0.08875 | AU33: =AT33+0.125% -> 0.09 | AV33: =AU33 -> 0.09 | AZ33: =B33 -> <64.99% | BA33: NA | BB33: NA | BC33: NA | BD33: NA | BE33: NA | BF33: NA
B34: FICO 700+ | C34: =C33+0 -> 0.0825 | D34: =D33+0 -> 0.08375 | E34: =E33+0 -> 0.085 | F34: =F33+0 -> 0.08625 | G34: =G33+0 -> 0.0875 | H34: =H33+0 -> 0.0875 | L34: FICO 700+ | M34: =M33+0 -> 0.105 | N34: =N33+0 -> 0.1075 | O34: NA | P34: NA | Q34: NA | R34: NA | V34: =B34 -> FICO 700+ | W34: =W33+0 -> 0.08375 | X34: =X33+0 -> 0.085 | Y34: =Y33+0 -> 0.08625 | Z34: =Z33+0 -> 0.0875 | AA34: =AA33+0 -> 0.08875 | AB34: =AB33+0 -> 0.08875 | AF34: =V34 -> FICO 700+ | AG34: NA | AH34: NA | AI34: NA | AJ34: NA | AK34: NA | AL34: NA | AP34: =B34 -> FICO 700+ | AQ34: =AQ33+0 -> 0.085 | AR34: =AR33+0 -> 0.08625 | AS34: =AS33+0 -> 0.0875 | AT34: =AT33+0 -> 0.08875 | AU34: =AU33+0 -> 0.09 | AV34: =AV33+0 -> 0.09 | AZ34: =B34 -> FICO 700+ | BA34: NA | BB34: NA | BC34: NA | BD34: NA | BE34: NA | BF34: NA
B35: FICO 660-699 | C35: =C33+0.5% -> 0.0875 | D35: =D33+0.5% -> 0.08875 | E35: =E33+0.5% -> 0.09 | F35: =F33+0.5% -> 0.09125 | G35: =G33+0.5% -> 0.0925 | H35: =H33+0.5% -> 0.0925 | L35: FICO 660-699 | M35: =M33+0.25% -> 0.1075 | N35: =N33+0.25% -> 0.11 | O35: NA | P35: NA | Q35: NA | R35: NA | V35: =B35 -> FICO 660-699 | W35: =W33+0.5% -> 0.08875 | X35: =X33+0.5% -> 0.09 | Y35: =Y33+0.5% -> 0.09125 | Z35: =Z33+0.5% -> 0.0925 | AA35: =AA33+0.5% -> 0.09375 | AB35: =AB33+0.5% -> 0.09375 | AF35: =V35 -> FICO 660-699 | AG35: NA | AH35: NA | AI35: NA | AJ35: NA | AK35: NA | AL35: NA | AP35: =B35 -> FICO 660-699 | AQ35: =AQ33+0.5% -> 0.09 | AR35: =AR33+0.5% -> 0.09125 | AS35: =AS33+0.5% -> 0.0925 | AT35: =AT33+0.5% -> 0.09375 | AU35: =AU33+0.5% -> 0.095 | AV35: =AV33+0.5% -> 0.095 | AZ35: =B35 -> FICO 660-699 | BA35: NA | BB35: NA | BC35: NA | BD35: NA | BE35: NA | BF35: NA
B36: FICO 640-659 | C36: NA | D36: NA | E36: NA | F36: NA | G36: NA | H36: NA | L36: FICO 640-659 | M36: NA | N36: NA | O36: NA | P36: NA | Q36: NA | R36: NA | V36: =B36 -> FICO 640-659 | W36: NA | X36: NA | Y36: NA | Z36: NA | AA36: NA | AB36: NA | AF36: =V36 -> FICO 640-659 | AG36: NA | AH36: NA | AI36: NA | AJ36: NA | AK36: NA | AL36: NA | AP36: =B36 -> FICO 640-659 | AQ36: NA | AR36: NA | AS36: NA | AT36: NA | AU36: NA | AV36: NA | AZ36: =B36 -> FICO 640-659 | BA36: NA | BB36: NA | BC36: NA | BD36: NA | BE36: NA | BF36: NA
B38: Tier 3 (0 Proj. Comp. last 3 yrs) | L38: Tier 3 (0 Proj. Comp. last 3 yrs) | V38: Tier 3 (0 Proj. Comp. last 3 yrs) | AF38: Tier 3 (0 Proj. Comp. last 3 yrs) | AP38: Tier 3 (0 Proj. Comp. last 3 yrs) | AZ38: Tier 3 (0 Proj. Comp. last 3 yrs)
C39: LTC | M39: LTC | W39: =C39 -> LTC | AG39: =W39 -> LTC | AQ39: =C39 -> LTC | BA39: =C39 -> LTC
B40: AR-LTV | C40: <74.99% | D40: 75.00%-80.00% | E40: 80.01%-85.00% | F40: 85.01%-87.50% | G40: 87.51%-89.99% | H40: 90.00%-92.50% | L40: AR-LTV | M40: <74.99% | N40: 75.00%-80.00% | O40: 80.01%-85.00% | P40: 85.01%-87.50% | Q40: 87.51%-89.99% | R40: 90.00%-92.50% | V40: =B40 -> AR-LTV | W40: =C40 -> <74.99% | X40: =D40 -> 75.00%-80.00% | Y40: =E40 -> 80.01%-85.00% | Z40: =F40 -> 85.01%-87.50% | AA40: =G40 -> 87.51%-89.99% | AB40: =H40 -> 90.00%-92.50% | AF40: =V40 -> AR-LTV | AG40: =W40 -> <74.99% | AH40: =X40 -> 75.00%-80.00% | AI40: =Y40 -> 80.01%-85.00% | AJ40: =Z40 -> 85.01%-87.50% | AK40: =AA40 -> 87.51%-89.99% | AL40: =AB40 -> 90.00%-92.50% | AP40: =B40 -> AR-LTV | AQ40: =C40 -> <74.99% | AR40: =D40 -> 75.00%-80.00% | AS40: =E40 -> 80.01%-85.00% | AT40: =F40 -> 85.01%-87.50% | AU40: =G40 -> 87.51%-89.99% | AV40: =H40 -> 90.00%-92.50% | AZ40: =B40 -> AR-LTV | BA40: =C40 -> <74.99% | BB40: =D40 -> 75.00%-80.00% | BC40: =E40 -> 80.01%-85.00% | BD40: =F40 -> 85.01%-87.50% | BE40: =G40 -> 87.51%-89.99% | BF40: =H40 -> 90.00%-92.50%
B41: 70.01%-75.00% | C41: NA | D41: NA | E41: NA | F41: NA | G41: NA | H41: NA | L41: 70.01%-75.00% | M41: NA | N41: NA | O41: NA | P41: NA | Q41: NA | R41: NA | V41: =B41 -> 70.01%-75.00% | W41: NA | X41: NA | Y41: NA | Z41: NA | AA41: NA | AB41: NA | AF41: =V41 -> 70.01%-75.00% | AG41: NA | AH41: NA | AI41: NA | AJ41: NA | AK41: NA | AL41: NA | AP41: =B41 -> 70.01%-75.00% | AQ41: NA | AR41: NA | AS41: NA | AT41: NA | AU41: NA | AV41: NA | AZ41: =B41 -> 70.01%-75.00% | BA41: NA | BB41: NA | BC41: NA | BD41: NA | BE41: NA | BF41: NA
B42: FICO 700+ | C42: NA | D42: NA | E42: NA | F42: NA | G42: NA | H42: NA | L42: FICO 700+ | M42: NA | N42: NA | O42: NA | P42: NA | Q42: NA | R42: NA | V42: =B42 -> FICO 700+ | W42: NA | X42: NA | Y42: NA | Z42: NA | AA42: NA | AB42: NA | AF42: =V42 -> FICO 700+ | AG42: NA | AH42: NA | AI42: NA | AJ42: NA | AK42: NA | AL42: NA | AP42: =B42 -> FICO 700+ | AQ42: NA | AR42: NA | AS42: NA | AT42: NA | AU42: NA | AV42: NA | AZ42: =B42 -> FICO 700+ | BA42: NA | BB42: NA | BC42: NA | BD42: NA | BE42: NA | BF42: NA
B43: FICO 680-699 | C43: NA | D43: NA | E43: NA | F43: NA | G43: NA | H43: NA | L43: FICO 680-699 | M43: NA | N43: NA | O43: NA | P43: NA | Q43: NA | R43: NA | V43: =B43 -> FICO 680-699 | W43: NA | X43: NA | Y43: NA | Z43: NA | AA43: NA | AB43: NA | AF43: =V43 -> FICO 680-699 | AG43: NA | AH43: NA | AI43: NA | AJ43: NA | AK43: NA | AL43: NA | AP43: =B43 -> FICO 680-699 | AQ43: NA | AR43: NA | AS43: NA | AT43: NA | AU43: NA | AV43: NA | AZ43: =B43 -> FICO 680-699 | BA43: NA | BB43: NA | BC43: NA | BD43: NA | BE43: NA | BF43: NA
...

Sheet Tier Grid
A1: June 2026 Guideline Version Grid
A3: Purchase Loans (F&F / F&H) | I3: Refinance Loans (F&F / F&H)
A4: Borrower Experience Tier | B4: Max Total Loan Amount | C4: Min FICO | D4: Max Acq-LTV | E4: Max AR-LTV | F4: Max LTC | G4: Eligible Strategy | I4: Borrower Experience Tier | J4: Max Total Loan Amount | K4: Min FICO | L4: Max Acq-LTV | M4: Max AR-LTV | N4: Max LTC | O4: Eligible Strategy
A5: Tier 1 | B5: $4.5M | C5: 640 | D5: 0.9 | E5: 0.75 | F5: 0.925 | G5: F&F / F&H | I5: Tier 1 | J5: $2.5M | K5: 700 | L5: 0.75 | M5: 0.7 | N5: 0.85 | O5: F&F / F&H
A6: Tier 2 | B6: $2.5M | C6: 660 | D6: 0.9 | E6: 0.75 | F6: 0.925 | G6: F&F / F&H | I6: Tier 2 | J6: $2.5M | K6: 700 | L6: 0.65 | M6: 0.7 | N6: 0.75 | O6: F&F / F&H
A7: Tier 3 | B7: $950K | C7: 680 | D7: 0.75 | E7: 0.65 | F7: 0.85 | G7: F&F / F&H | I7: Tier 3 | J7: NA | K7: NA | L7: NA | M7: NA | N7: NA | O7: F&F / F&H
A9: Purchase Loans (GUC) | I9: Refinance Loans (GUC)
A10: Borrower Experience Tier | B10: Max Total Loan Amount | C10: Min FICO | D10: Max Acq-LTV | E10: Max AR-LTV | F10: Max LTC | G10: Eligible Strategy | I10: Borrower Experience Tier | J10: Max Total Loan Amount | K10: Min FICO | L10: Max Acq-LTV | M10: Max AR-LTV | N10: Max LTC | O10: Eligible Strategy
A11: Tier 1 | B11: $4.5M | C11: 640 | D11: 0.8 | E11: 0.75 | F11: 0.925 | G11: GUC | I11: Tier 1 | J11: $4.5M | K11: 640 | L11: 0.8 | M11: 0.75 | N11: 0.925 | O11: GUC
A12: Tier 2 | B12: $2.5M | C12: 660 | D12: 0.7 | E12: 0.75 | F12: 0.925 | G12: GUC | I12: Tier 2 | J12: $2.5M | K12: 660 | L12: 0.7 | M12: 0.75 | N12: 0.925 | O12: GUC
A13: Tier 3 | B13: $950K | C13: 680 | D13: 0.65 | E13: 0.65 | F13: 0.8 | G13: GUC | I13: Tier 3 | J13: $950K | K13: 680 | L13: 0.65 | M13: 0.65 | N13: 0.8 | O13: GUC
A15: Purchase Loans (BRIDGE) | I15: Refinance Loans (BRIDGE)
A16: Borrower Experience Tier | B16: Max Total Loan Amount | C16: Min FICO | D16: Max Acq-LTV | E16: Max AR-LTV | F16: Max LTC | G16: Eligible Strategy | I16: Borrower Experience Tier | J16: Max Total Loan Amount | K16: Min FICO | L16: Max Acq-LTV | M16: Max AR-LTV | N16: Max LTC | O16: Eligible Strategy
A17: Tier 1 | B17: $4.5M | C17: 670 | D17: 0.75 | E17: 0.75 | F17: 0.75 | G17: BRIDGE | I17: Tier 1 | J17: $2.5M | K17: 700 | L17: 0.75 | M17: 0.75 | N17: 0.75 | O17: BRIDGE
A18: Tier 2 | B18: $2.5M | C18: 670 | D18: 0.75 | E18: 0.75 | F18: 0.75 | G18: BRIDGE | I18: Tier 2 | J18: $2.5M | K18: 700 | L18: 0.7 | M18: 0.7 | N18: 0.7 | O18: BRIDGE
A19: Tier 3 | B19: $950K | C19: 680 | D19: 0.7 | E19: 0.7 | F19: 0.7 | G19: BRIDGE | I19: Tier 3 | J19: $950K | K19: 700 | L19: 0.65 | M19: 0.65 | N19: 0.65 | O19: BRIDGE

Sheet Underwriting Commentary
A1: Valuations - Additional Appraisal Review Items
A2: - As Is Comparables - at least one As Is comp shown on a 1004 appraisal must show the characteristics below:
B3: - Sale / Close date within 12 months of subject loan submission date
B4: - 1 As Is comparable used must show less than 15% net adjustments to value
B5: - Comp used must be in the same zip code as subject property
A6: - ARV Comparables - at least one ARV comp shown on a 1004 appraisal must show the characteristics below:
B7: - Sale / Close date within 12 months of subject loan submission date
B8: - 1 ARV comparable used must show less than 15% net adjustments to value
B9: - Comp used must be in the same zip code as subject property
A10: - Fix & Hold / DSCR / Rental exit strategy - rental analysis must be included on appraisal
B11: - Projected DSCR of subj. property must meet min 1.0 DSCR
B12: - Projected DSCR loan must be over 100% of current loan amount
A13: - All appraisals must include interior pictures
A14: - All appraisals must exhibit the lender's name who is submitting the loan for funding
A16: Refinances - Additional Refinance Review Items
A17: - All refinance submissions should include clarification on current financing / background as well as exit strategy (if unclear)
A18: - Purchase Price will be used as As Is Value on subject properties where no value add work has been completed since acquisition
B19: - As Is values on appraisals can be used if properties were acquired over 18 months prior to submission
A20: - New Construction Refinances
B21: - Submissions within 18 months of acquisition can utilize Purchase Price + value add work completed to date
B22: - Value add work must be documented through invoices - all cost spent will be treated 1/1 with value add
A23: - Bridge Refinances (Stabilized property refinances) must exhibit all characteristics below to be eligible for financing
B24: - Borrowers must be Current on all payments with lender - Evidence through VOM / payoff from servicer must be provided
B25: - Borrowers have no missed payments to date (evidenced through VOM)
B26: - Borrowers are current on all taxes owed
B27: - Project must be profitable with the inclusion of new loan fees & carry (fees & carry for prior loan will be included in calc)
B28: - Interest Reserves for the term of the loan will always be net from cash out proceeds
B29: - Approved LTC / AR-LTV will be inclusive of IR funding
A30: - Mid-Way completed construction projects are not eligible for funding
A31: - Cash Out proceeds from refinances can not exceed 50% of total projected profitability for a project
A33: Borrower Experience - Additional Review Items
A34: - Borrowers must provide entity ownership verification & property acquisition verification for all prior projects completed that can not be verified through 3rd party resources
B35: - Borrowers must own 25% or more of an entity to be eligible (evidenced through Operating Agreements or entity documentation)
A36: - Borrower Experience / Loan Sizes over $1m / New Construction projects w/ over $500k budgets
B37: - Experience qualification for submissions that fit the categories above must exhibit the below characteristics to qualify:
C38: - New Construction projects w/ over $500k budgets
D39: - Only other new construction projects will qualify
D40: - Projects must show budgets within 80% of total budget of current submission
D41: - Projects must show re-sale values within 80% of projected re-sale value of current submission
C42: - Loan Sizes over $1m
...

Sheet Engine
A1: key | B1: rate | C1: source_cell | E1: tgkey | F1: maxloan | G1: minfico | H1: maxacq | I1: maxar | J1: maxltc | L1: prod_label | M1: prod_token | N1: purp_label | O1: purp_token | P1: mkt_label | Q1: mkt_token | R1: exit_label | S1: exit_token | T1: terms | U1: yesno
A2: STD|S|FF|P|12|T1|70.01%-75.00%|FICO 700+|<74.99% | B2: ='EMCAP_Pricing Matrix'!C10 -> 0.0825 | C2: C10 | E2: FF|P|T1 | F2: 4500000 | G2: 640 | H2: 0.9 | I2: 0.75 | J2: 0.925 | L2: Fix & Flip / Fix & Hold (F&F / F&H) | M2: FF | N2: Purchase | O2: P | P2: Standard (Non-NYC) | Q2: STD | R2: Fix & Flip (sell) | S2: FLIP | T2: 12 | U2: Yes
A3: STD|S|FF|P|12|T1|70.01%-75.00%|FICO 700+|75.00%-80.00% | B3: ='EMCAP_Pricing Matrix'!D10 -> 0.08375 | C3: D10 | E3: FF|R|T1 | F3: 2500000 | G3: 700 | H3: 0.75 | I3: 0.7 | J3: 0.85 | L3: Ground-Up Construction (GUC) | M3: GUC | N3: Refinance | O3: R | P3: NYC Five-Borough | Q3: NYC | R3: Fix & Hold / DSCR (rent) | S3: HOLD | T3: 18 | U3: No
A4: STD|S|FF|P|12|T1|70.01%-75.00%|FICO 700+|80.01%-85.00% | B4: ='EMCAP_Pricing Matrix'!E10 -> 0.085 | C4: E10 | E4: FF|P|T2 | F4: 2500000 | G4: 660 | H4: 0.9 | I4: 0.75 | J4: 0.925 | L4: Bridge | M4: BR | R4: Bridge / Stabilized | S4: BRIDGE | T4: 24
A5: STD|S|FF|P|12|T1|70.01%-75.00%|FICO 700+|85.01%-87.50% | B5: ='EMCAP_Pricing Matrix'!F10 -> 0.08625 | C5: F10 | E5: FF|R|T2 | F5: 2500000 | G5: 700 | H5: 0.65 | I5: 0.7 | J5: 0.75
A6: STD|S|FF|P|12|T1|70.01%-75.00%|FICO 700+|87.51%-89.99% | B6: ='EMCAP_Pricing Matrix'!G10 -> 0.0875 | C6: G10 | E6: FF|P|T3 | F6: 950000 | G6: 680 | H6: 0.75 | I6: 0.65 | J6: 0.85
A7: STD|S|FF|P|12|T1|70.01%-75.00%|FICO 700+|90.00%-92.50% | B7: ='EMCAP_Pricing Matrix'!H10 -> 0.0875 | C7: H10 | E7: FF|R|T3 | F7: 0
A8: STD|S|FF|R|12|T1|70.01%-75.00%|FICO 700+|<74.99% | B8: ='EMCAP_Pricing Matrix'!M10 -> 0.11 | C8: M10 | E8: GUC|P|T1 | F8: 4500000 | G8: 640 | H8: 0.8 | I8: 0.75 | J8: 0.925
A9: STD|S|FF|R|12|T1|70.01%-75.00%|FICO 700+|75.00%-80.00% | B9: ='EMCAP_Pricing Matrix'!N10 -> 0.1125 | C9: N10 | E9: GUC|R|T1 | F9: 4500000 | G9: 640 | H9: 0.8 | I9: 0.75 | J9: 0.925
A10: STD|S|FF|R|12|T1|70.01%-75.00%|FICO 700+|80.01%-85.00% | B10: ='EMCAP_Pricing Matrix'!O10 -> 0.115 | C10: O10 | E10: GUC|P|T2 | F10: 2500000 | G10: 660 | H10: 0.7 | I10: 0.75 | J10: 0.925
A11: STD|S|FF|P|18|T1|70.01%-75.00%|FICO 700+|<74.99% | B11: ='EMCAP_Pricing Matrix'!W10 -> 0.08375 | C11: W10 | E11: GUC|R|T2 | F11: 2500000 | G11: 660 | H11: 0.7 | I11: 0.75 | J11: 0.925
A12: STD|S|FF|P|18|T1|70.01%-75.00%|FICO 700+|75.00%-80.00% | B12: ='EMCAP_Pricing Matrix'!X10 -> 0.085 | C12: X10 | E12: GUC|P|T3 | F12: 950000 | G12: 680 | H12: 0.65 | I12: 0.65 | J12: 0.8
A13: STD|S|FF|P|18|T1|70.01%-75.00%|FICO 700+|80.01%-85.00% | B13: ='EMCAP_Pricing Matrix'!Y10 -> 0.08625 | C13: Y10 | E13: GUC|R|T3 | F13: 950000 | G13: 680 | H13: 0.65 | I13: 0.65 | J13: 0.8
A14: STD|S|FF|P|18|T1|70.01%-75.00%|FICO 700+|85.01%-87.50% | B14: ='EMCAP_Pricing Matrix'!Z10 -> 0.0875 | C14: Z10 | E14: BR|P|T1 | F14: 4500000 | G14: 670 | H14: 0.75 | I14: 0.75 | J14: 0.75
A15: STD|S|FF|P|18|T1|70.01%-75.00%|FICO 700+|87.51%-89.99% | B15: ='EMCAP_Pricing Matrix'!AA10 -> 0.08875 | C15: AA10 | E15: BR|R|T1 | F15: 2500000 | G15: 700 | H15: 0.75 | I15: 0.75 | J15: 0.75
A16: STD|S|FF|P|18|T1|70.01%-75.00%|FICO 700+|90.00%-92.50% | B16: ='EMCAP_Pricing Matrix'!AB10 -> 0.08875 | C16: AB10 | E16: BR|P|T2 | F16: 2500000 | G16: 670 | H16: 0.75 | I16: 0.75 | J16: 0.75
A17: STD|S|FF|R|18|T1|70.01%-75.00%|FICO 700+|<74.99% | B17: ='EMCAP_Pricing Matrix'!AG10 -> 0.11125 | C17: AG10 | E17: BR|R|T2 | F17: 2500000 | G17: 700 | H17: 0.7 | I17: 0.7 | J17: 0.7
A18: STD|S|FF|R|18|T1|70.01%-75.00%|FICO 700+|75.00%-80.00% | B18: ='EMCAP_Pricing Matrix'!AH10 -> 0.11375 | C18: AH10 | E18: BR|P|T3 | F18: 950000 | G18: 680 | H18: 0.7 | I18: 0.7 | J18: 0.7
A19: STD|S|FF|R|18|T1|70.01%-75.00%|FICO 700+|80.01%-85.00% | B19: ='EMCAP_Pricing Matrix'!AI10 -> 0.11625 | C19: AI10 | E19: BR|R|T3 | F19: 950000 | G19: 700 | H19: 0.65 | I19: 0.65 | J19: 0.65
A20: STD|S|FF|P|24|T1|70.01%-75.00%|FICO 700+|<74.99% | B20: ='EMCAP_Pricing Matrix'!AQ10 -> 0.085 | C20: AQ10
A21: STD|S|FF|P|24|T1|70.01%-75.00%|FICO 700+|75.00%-80.00% | B21: ='EMCAP_Pricing Matrix'!AR10 -> 0.08625 | C21: AR10
A22: STD|S|FF|P|24|T1|70.01%-75.00%|FICO 700+|80.01%-85.00% | B22: ='EMCAP_Pricing Matrix'!AS10 -> 0.0875 | C22: AS10
A23: STD|S|FF|P|24|T1|70.01%-75.00%|FICO 700+|85.01%-87.50% | B23: ='EMCAP_Pricing Matrix'!AT10 -> 0.08875 | C23: AT10
A24: STD|S|FF|P|24|T1|70.01%-75.00%|FICO 700+|87.51%-89.99% | B24: ='EMCAP_Pricing Matrix'!AU10 -> 0.09 | C24: AU10
A25: STD|S|FF|P|24|T1|70.01%-75.00%|FICO 700+|90.00%-92.50% | B25: ='EMCAP_Pricing Matrix'!AV10 -> 0.09 | C25: AV10
A26: STD|S|FF|P|12|T1|70.01%-75.00%|FICO 660-699|<74.99% | B26: ='EMCAP_Pricing Matrix'!C11 -> 0.0875 | C26: C11
A27: STD|S|FF|P|12|T1|70.01%-75.00%|FICO 660-699|75.00%-80.00% | B27: ='EMCAP_Pricing Matrix'!D11 -> 0.08875 | C27: D11
A28: STD|S|FF|P|12|T1|70.01%-75.00%|FICO 660-699|80.01%-85.00% | B28: ='EMCAP_Pricing Matrix'!E11 -> 0.09 | C28: E11
A29: STD|S|FF|P|12|T1|70.01%-75.00%|FICO 660-699|85.01%-87.50% | B29: ='EMCAP_Pricing Matrix'!F11 -> 0.09125 | C29: F11
A30: STD|S|FF|P|12|T1|70.01%-75.00%|FICO 660-699|87.51%-89.99% | B30: ='EMCAP_Pricing Matrix'!G11 -> 0.0925 | C30: G11
A31: STD|S|FF|P|12|T1|70.01%-75.00%|FICO 660-699|90.00%-92.50% | B31: ='EMCAP_Pricing Matrix'!H11 -> 0.0925 | C31: H11
A32: STD|S|FF|R|12|T1|70.01%-75.00%|FICO 660-699|<74.99% | B32: ='EMCAP_Pricing Matrix'!M11 -> 0.1125 | C32: M11
A33: STD|S|FF|R|12|T1|70.01%-75.00%|FICO 660-699|75.00%-80.00% | B33: ='EMCAP_Pricing Matrix'!N11 -> 0.115 | C33: N11
A34: STD|S|FF|R|12|T1|70.01%-75.00%|FICO 660-699|80.01%-85.00% | B34: ='EMCAP_Pricing Matrix'!O11 -> 0.1175 | C34: O11
A35: STD|S|FF|P|18|T1|70.01%-75.00%|FICO 660-699|<74.99% | B35: ='EMCAP_Pricing Matrix'!W11 -> 0.08875 | C35: W11
A36: STD|S|FF|P|18|T1|70.01%-75.00%|FICO 660-699|75.00%-80.00% | B36: ='EMCAP_Pricing Matrix'!X11 -> 0.09 | C36: X11
A37: STD|S|FF|P|18|T1|70.01%-75.00%|FICO 660-699|80.01%-85.00% | B37: ='EMCAP_Pricing Matrix'!Y11 -> 0.09125 | C37: Y11
A38: STD|S|FF|P|18|T1|70.01%-75.00%|FICO 660-699|85.01%-87.50% | B38: ='EMCAP_Pricing Matrix'!Z11 -> 0.0925 | C38: Z11
A39: STD|S|FF|P|18|T1|70.01%-75.00%|FICO 660-699|87.51%-89.99% | B39: ='EMCAP_Pricing Matrix'!AA11 -> 0.09375 | C39: AA11
A40: STD|S|FF|P|18|T1|70.01%-75.00%|FICO 660-699|90.00%-92.50% | B40: ='EMCAP_Pricing Matrix'!AB11 -> 0.09375 | C40: AB11
...
