Workbook

Sheet Pricing Matrix
A1: Fidelis Investors Pricing Matrix - Layered Guideline Version
A2: Rates are shown only where the guideline LTC bucket is eligible; Acq LTV and ARLTV caps must also be met
A4: Loan Type | B4: Strategy | C4: Tier | D4: Max Loan Amt | E4: Min FICO | F4: Max Acq LTV | G4: Max ARLTV | H4: Max LTC | I4: Notes | J4: 0.65 | K4: 0.7 | L4: 0.75 | M4: 0.8 | N4: 0.85 | O4: 0.9 | P4: 0.925
A5: Purchase | B5: Fix & Flip / Fix & Hold | C5: Tier 1 | D5: 3000000 | E5: 600 | F5: 0.9 | G5: 0.75 | H5: 0.925 | I5: Projects with sq. ft additions capped at 87.5% LTC | J5: =IF(J$4<=$H5,MAX('Rate Assumptions'!$B$5,MIN('Rate Assumptions'!$B$6,IF($B5="Bridge",'Rate Assumptions'!$B$11,IF($B5="New Construction",'Rate Assumptions'!$B$10,'Rate Assumptions'!$B$9))+IF($C5="Tier 1",'Rate Assumptions'!$B$12,IF($C5="Tier 2",'Rate Assumptions'!$B$13,'Rate Assumptions'!$B$14))+'Rate Assumptions'!$B$26)),"N/A") -> 0.0925 | K5: =IF(K$4<=$H5,MAX('Rate Assumptions'!$B$5,MIN('Rate Assumptions'!$B$6,IF($B5="Bridge",'Rate Assumptions'!$B$11,IF($B5="New Construction",'Rate Assumptions'!$B$10,'Rate Assumptions'!$B$9))+IF($C5="Tier 1",'Rate Assumptions'!$B$12,IF($C5="Tier 2",'Rate Assumptions'!$B$13,'Rate Assumptions'!$B$14))+'Rate Assumptions'!$B$27)),"N/A") -> 0.093 | L5: =IF(L$4<=$H5,MAX('Rate Assumptions'!$B$5,MIN('Rate Assumptions'!$B$6,IF($B5="Bridge",'Rate Assumptions'!$B$11,IF($B5="New Construction",'Rate Assumptions'!$B$10,'Rate Assumptions'!$B$9))+IF($C5="Tier 1",'Rate Assumptions'!$B$12,IF($C5="Tier 2",'Rate Assumptions'!$B$13,'Rate Assumptions'!$B$14))+'Rate Assumptions'!$B$28)),"N/A") -> 0.094 | M5: =IF(M$4<=$H5,MAX('Rate Assumptions'!$B$5,MIN('Rate Assumptions'!$B$6,IF($B5="Bridge",'Rate Assumptions'!$B$11,IF($B5="New Construction",'Rate Assumptions'!$B$10,'Rate Assumptions'!$B$9))+IF($C5="Tier 1",'Rate Assumptions'!$B$12,IF($C5="Tier 2",'Rate Assumptions'!$B$13,'Rate Assumptions'!$B$14))+'Rate Assumptions'!$B$29)),"N/A") -> 0.095 | N5: =IF(N$4<=$H5,MAX('Rate Assumptions'!$B$5,MIN('Rate Assumptions'!$B$6,IF($B5="Bridge",'Rate Assumptions'!$B$11,IF($B5="New Construction",'Rate Assumptions'!$B$10,'Rate Assumptions'!$B$9))+IF($C5="Tier 1",'Rate Assumptions'!$B$12,IF($C5="Tier 2",'Rate Assumptions'!$B$13,'Rate Assumptions'!$B$14))+'Rate Assumptions'!$B$30)),"N/A") -> 0.096 | O5: =IF(O$4<=$H5,MAX('Rate Assumptions'!$B$5,MIN('Rate Assumptions'!$B$6,IF($B5="Bridge",'Rate Assumptions'!$B$11,IF($B5="New Construction",'Rate Assumptions'!$B$10,'Rate Assumptions'!$B$9))+IF($C5="Tier 1",'Rate Assumptions'!$B$12,IF($C5="Tier 2",'Rate Assumptions'!$B$13,'Rate Assumptions'!$B$14))+'Rate Assumptions'!$B$31)),"N/A") -> 0.097 | P5: =IF(P$4<=$H5,MAX('Rate Assumptions'!$B$5,MIN('Rate Assumptions'!$B$6,IF($B5="Bridge",'Rate Assumptions'!$B$11,IF($B5="New Construction",'Rate Assumptions'!$B$10,'Rate Assumptions'!$B$9))+IF($C5="Tier 1",'Rate Assumptions'!$B$12,IF($C5="Tier 2",'Rate Assumptions'!$B$13,'Rate Assumptions'!$B$14))+'Rate Assumptions'!$B$32)),"N/A") -> 0.098
A6: Purchase | B6: Fix & Flip / Fix & Hold | C6: Tier 2 | D6: 2500000 | E6: 660 | F6: 0.9 | G6: 0.7 | H6: 0.925 | I6: Projects with sq. ft additions capped at 87.5% LTC | J6: =IF(J$4<=$H6,MAX('Rate Assumptions'!$B$5,MIN('Rate Assumptions'!$B$6,IF($B6="Bridge",'Rate Assumptions'!$B$11,IF($B6="New Construction",'Rate Assumptions'!$B$10,'Rate Assumptions'!$B$9))+IF($C6="Tier 1",'Rate Assumptions'!$B$12,IF($C6="Tier 2",'Rate Assumptions'!$B$13,'Rate Assumptions'!$B$14))+'Rate Assumptions'!$B$26)),"N/A") -> 0.093 | K6: =IF(K$4<=$H6,MAX('Rate Assumptions'!$B$5,MIN('Rate Assumptions'!$B$6,IF($B6="Bridge",'Rate Assumptions'!$B$11,IF($B6="New Construction",'Rate Assumptions'!$B$10,'Rate Assumptions'!$B$9))+IF($C6="Tier 1",'Rate Assumptions'!$B$12,IF($C6="Tier 2",'Rate Assumptions'!$B$13,'Rate Assumptions'!$B$14))+'Rate Assumptions'!$B$27)),"N/A") -> 0.094 | L6: =IF(L$4<=$H6,MAX('Rate Assumptions'!$B$5,MIN('Rate Assumptions'!$B$6,IF($B6="Bridge",'Rate Assumptions'!$B$11,IF($B6="New Construction",'Rate Assumptions'!$B$10,'Rate Assumptions'!$B$9))+IF($C6="Tier 1",'Rate Assumptions'!$B$12,IF($C6="Tier 2",'Rate Assumptions'!$B$13,'Rate Assumptions'!$B$14))+'Rate Assumptions'!$B$28)),"N/A") -> 0.095 | M6: =IF(M$4<=$H6,MAX('Rate Assumptions'!$B$5,MIN('Rate Assumptions'!$B$6,IF($B6="Bridge",'Rate Assumptions'!$B$11,IF($B6="New Construction",'Rate Assumptions'!$B$10,'Rate Assumptions'!$B$9))+IF($C6="Tier 1",'Rate Assumptions'!$B$12,IF($C6="Tier 2",'Rate Assumptions'!$B$13,'Rate Assumptions'!$B$14))+'Rate Assumptions'!$B$29)),"N/A") -> 0.096 | N6: =IF(N$4<=$H6,MAX('Rate Assumptions'!$B$5,MIN('Rate Assumptions'!$B$6,IF($B6="Bridge",'Rate Assumptions'!$B$11,IF($B6="New Construction",'Rate Assumptions'!$B$10,'Rate Assumptions'!$B$9))+IF($C6="Tier 1",'Rate Assumptions'!$B$12,IF($C6="Tier 2",'Rate Assumptions'!$B$13,'Rate Assumptions'!$B$14))+'Rate Assumptions'!$B$30)),"N/A") -> 0.097 | O6: =IF(O$4<=$H6,MAX('Rate Assumptions'!$B$5,MIN('Rate Assumptions'!$B$6,IF($B6="Bridge",'Rate Assumptions'!$B$11,IF($B6="New Construction",'Rate Assumptions'!$B$10,'Rate Assumptions'!$B$9))+IF($C6="Tier 1",'Rate Assumptions'!$B$12,IF($C6="Tier 2",'Rate Assumptions'!$B$13,'Rate Assumptions'!$B$14))+'Rate Assumptions'!$B$31)),"N/A") -> 0.098 | P6: =IF(P$4<=$H6,MAX('Rate Assumptions'!$B$5,MIN('Rate Assumptions'!$B$6,IF($B6="Bridge",'Rate Assumptions'!$B$11,IF($B6="New Construction",'Rate Assumptions'!$B$10,'Rate Assumptions'!$B$9))+IF($C6="Tier 1",'Rate Assumptions'!$B$12,IF($C6="Tier 2",'Rate Assumptions'!$B$13,'Rate Assumptions'!$B$14))+'Rate Assumptions'!$B$32)),"N/A") -> 0.099
A7: Purchase | B7: Fix & Flip / Fix & Hold | C7: Tier 3 | D7: 950000 | E7: 680 | F7: 0.8 | G7: 0.65 | H7: 0.85 | J7: =IF(J$4<=$H7,MAX('Rate Assumptions'!$B$5,MIN('Rate Assumptions'!$B$6,IF($B7="Bridge",'Rate Assumptions'!$B$11,IF($B7="New Construction",'Rate Assumptions'!$B$10,'Rate Assumptions'!$B$9))+IF($C7="Tier 1",'Rate Assumptions'!$B$12,IF($C7="Tier 2",'Rate Assumptions'!$B$13,'Rate Assumptions'!$B$14))+'Rate Assumptions'!$B$26)),"N/A") -> 0.095 | K7: =IF(K$4<=$H7,MAX('Rate Assumptions'!$B$5,MIN('Rate Assumptions'!$B$6,IF($B7="Bridge",'Rate Assumptions'!$B$11,IF($B7="New Construction",'Rate Assumptions'!$B$10,'Rate Assumptions'!$B$9))+IF($C7="Tier 1",'Rate Assumptions'!$B$12,IF($C7="Tier 2",'Rate Assumptions'!$B$13,'Rate Assumptions'!$B$14))+'Rate Assumptions'!$B$27)),"N/A") -> 0.096 | L7: =IF(L$4<=$H7,MAX('Rate Assumptions'!$B$5,MIN('Rate Assumptions'!$B$6,IF($B7="Bridge",'Rate Assumptions'!$B$11,IF($B7="New Construction",'Rate Assumptions'!$B$10,'Rate Assumptions'!$B$9))+IF($C7="Tier 1",'Rate Assumptions'!$B$12,IF($C7="Tier 2",'Rate Assumptions'!$B$13,'Rate Assumptions'!$B$14))+'Rate Assumptions'!$B$28)),"N/A") -> 0.097 | M7: =IF(M$4<=$H7,MAX('Rate Assumptions'!$B$5,MIN('Rate Assumptions'!$B$6,IF($B7="Bridge",'Rate Assumptions'!$B$11,IF($B7="New Construction",'Rate Assumptions'!$B$10,'Rate Assumptions'!$B$9))+IF($C7="Tier 1",'Rate Assumptions'!$B$12,IF($C7="Tier 2",'Rate Assumptions'!$B$13,'Rate Assumptions'!$B$14))+'Rate Assumptions'!$B$29)),"N/A") -> 0.098 | N7: =IF(N$4<=$H7,MAX('Rate Assumptions'!$B$5,MIN('Rate Assumptions'!$B$6,IF($B7="Bridge",'Rate Assumptions'!$B$11,IF($B7="New Construction",'Rate Assumptions'!$B$10,'Rate Assumptions'!$B$9))+IF($C7="Tier 1",'Rate Assumptions'!$B$12,IF($C7="Tier 2",'Rate Assumptions'!$B$13,'Rate Assumptions'!$B$14))+'Rate Assumptions'!$B$30)),"N/A") -> 0.099 | O7: =IF(O$4<=$H7,MAX('Rate Assumptions'!$B$5,MIN('Rate Assumptions'!$B$6,IF($B7="Bridge",'Rate Assumptions'!$B$11,IF($B7="New Construction",'Rate Assumptions'!$B$10,'Rate Assumptions'!$B$9))+IF($C7="Tier 1",'Rate Assumptions'!$B$12,IF($C7="Tier 2",'Rate Assumptions'!$B$13,'Rate Assumptions'!$B$14))+'Rate Assumptions'!$B$31)),"N/A") -> N/A | P7: =IF(P$4<=$H7,MAX('Rate Assumptions'!$B$5,MIN('Rate Assumptions'!$B$6,IF($B7="Bridge",'Rate Assumptions'!$B$11,IF($B7="New Construction",'Rate Assumptions'!$B$10,'Rate Assumptions'!$B$9))+IF($C7="Tier 1",'Rate Assumptions'!$B$12,IF($C7="Tier 2",'Rate Assumptions'!$B$13,'Rate Assumptions'!$B$14))+'Rate Assumptions'!$B$32)),"N/A") -> N/A
A8: Purchase | B8: New Construction | C8: Tier 1 | D8: 2500000 | E8: 680 | F8: 0.7 | G8: 0.7 | H8: 0.85 | I8: Max Acq. LTV subject to soft costs included in construction budget | J8: =IF(J$4<=$H8,MAX('Rate Assumptions'!$B$5,MIN('Rate Assumptions'!$B$6,IF($B8="Bridge",'Rate Assumptions'!$B$11,IF($B8="New Construction",'Rate Assumptions'!$B$10,'Rate Assumptions'!$B$9))+IF($C8="Tier 1",'Rate Assumptions'!$B$12,IF($C8="Tier 2",'Rate Assumptions'!$B$13,'Rate Assumptions'!$B$14))+'Rate Assumptions'!$B$26)),"N/A") -> 0.0945 | K8: =IF(K$4<=$H8,MAX('Rate Assumptions'!$B$5,MIN('Rate Assumptions'!$B$6,IF($B8="Bridge",'Rate Assumptions'!$B$11,IF($B8="New Construction",'Rate Assumptions'!$B$10,'Rate Assumptions'!$B$9))+IF($C8="Tier 1",'Rate Assumptions'!$B$12,IF($C8="Tier 2",'Rate Assumptions'!$B$13,'Rate Assumptions'!$B$14))+'Rate Assumptions'!$B$27)),"N/A") -> 0.0955 | L8: =IF(L$4<=$H8,MAX('Rate Assumptions'!$B$5,MIN('Rate Assumptions'!$B$6,IF($B8="Bridge",'Rate Assumptions'!$B$11,IF($B8="New Construction",'Rate Assumptions'!$B$10,'Rate Assumptions'!$B$9))+IF($C8="Tier 1",'Rate Assumptions'!$B$12,IF($C8="Tier 2",'Rate Assumptions'!$B$13,'Rate Assumptions'!$B$14))+'Rate Assumptions'!$B$28)),"N/A") -> 0.0965 | M8: =IF(M$4<=$H8,MAX('Rate Assumptions'!$B$5,MIN('Rate Assumptions'!$B$6,IF($B8="Bridge",'Rate Assumptions'!$B$11,IF($B8="New Construction",'Rate Assumptions'!$B$10,'Rate Assumptions'!$B$9))+IF($C8="Tier 1",'Rate Assumptions'!$B$12,IF($C8="Tier 2",'Rate Assumptions'!$B$13,'Rate Assumptions'!$B$14))+'Rate Assumptions'!$B$29)),"N/A") -> 0.0975 | N8: =IF(N$4<=$H8,MAX('Rate Assumptions'!$B$5,MIN('Rate Assumptions'!$B$6,IF($B8="Bridge",'Rate Assumptions'!$B$11,IF($B8="New Construction",'Rate Assumptions'!$B$10,'Rate Assumptions'!$B$9))+IF($C8="Tier 1",'Rate Assumptions'!$B$12,IF($C8="Tier 2",'Rate Assumptions'!$B$13,'Rate Assumptions'!$B$14))+'Rate Assumptions'!$B$30)),"N/A") -> 0.0985 | O8: =IF(O$4<=$H8,MAX('Rate Assumptions'!$B$5,MIN('Rate Assumptions'!$B$6,IF($B8="Bridge",'Rate Assumptions'!$B$11,IF($B8="New Construction",'Rate Assumptions'!$B$10,'Rate Assumptions'!$B$9))+IF($C8="Tier 1",'Rate Assumptions'!$B$12,IF($C8="Tier 2",'Rate Assumptions'!$B$13,'Rate Assumptions'!$B$14))+'Rate Assumptions'!$B$31)),"N/A") -> N/A | P8: =IF(P$4<=$H8,MAX('Rate Assumptions'!$B$5,MIN('Rate Assumptions'!$B$6,IF($B8="Bridge",'Rate Assumptions'!$B$11,IF($B8="New Construction",'Rate Assumptions'!$B$10,'Rate Assumptions'!$B$9))+IF($C8="Tier 1",'Rate Assumptions'!$B$12,IF($C8="Tier 2",'Rate Assumptions'!$B$13,'Rate Assumptions'!$B$14))+'Rate Assumptions'!$B$32)),"N/A") -> N/A
A9: Purchase | B9: New Construction | C9: Tier 2 | D9: 2500000 | E9: 700 | F9: 0.7 | G9: 0.65 | H9: 0.85 | I9: Max Acq. LTV subject to soft costs included in construction budget | J9: =IF(J$4<=$H9,MAX('Rate Assumptions'!$B$5,MIN('Rate Assumptions'!$B$6,IF($B9="Bridge",'Rate Assumptions'!$B$11,IF($B9="New Construction",'Rate Assumptions'!$B$10,'Rate Assumptions'!$B$9))+IF($C9="Tier 1",'Rate Assumptions'!$B$12,IF($C9="Tier 2",'Rate Assumptions'!$B$13,'Rate Assumptions'!$B$14))+'Rate Assumptions'!$B$26)),"N/A") -> 0.0955 | K9: =IF(K$4<=$H9,MAX('Rate Assumptions'!$B$5,MIN('Rate Assumptions'!$B$6,IF($B9="Bridge",'Rate Assumptions'!$B$11,IF($B9="New Construction",'Rate Assumptions'!$B$10,'Rate Assumptions'!$B$9))+IF($C9="Tier 1",'Rate Assumptions'!$B$12,IF($C9="Tier 2",'Rate Assumptions'!$B$13,'Rate Assumptions'!$B$14))+'Rate Assumptions'!$B$27)),"N/A") -> 0.0965 | L9: =IF(L$4<=$H9,MAX('Rate Assumptions'!$B$5,MIN('Rate Assumptions'!$B$6,IF($B9="Bridge",'Rate Assumptions'!$B$11,IF($B9="New Construction",'Rate Assumptions'!$B$10,'Rate Assumptions'!$B$9))+IF($C9="Tier 1",'Rate Assumptions'!$B$12,IF($C9="Tier 2",'Rate Assumptions'!$B$13,'Rate Assumptions'!$B$14))+'Rate Assumptions'!$B$28)),"N/A") -> 0.0975 | M9: =IF(M$4<=$H9,MAX('Rate Assumptions'!$B$5,MIN('Rate Assumptions'!$B$6,IF($B9="Bridge",'Rate Assumptions'!$B$11,IF($B9="New Construction",'Rate Assumptions'!$B$10,'Rate Assumptions'!$B$9))+IF($C9="Tier 1",'Rate Assumptions'!$B$12,IF($C9="Tier 2",'Rate Assumptions'!$B$13,'Rate Assumptions'!$B$14))+'Rate Assumptions'!$B$29)),"N/A") -> 0.0985 | N9: =IF(N$4<=$H9,MAX('Rate Assumptions'!$B$5,MIN('Rate Assumptions'!$B$6,IF($B9="Bridge",'Rate Assumptions'!$B$11,IF($B9="New Construction",'Rate Assumptions'!$B$10,'Rate Assumptions'!$B$9))+IF($C9="Tier 1",'Rate Assumptions'!$B$12,IF($C9="Tier 2",'Rate Assumptions'!$B$13,'Rate Assumptions'!$B$14))+'Rate Assumptions'!$B$30)),"N/A") -> 0.0995 | O9: =IF(O$4<=$H9,MAX('Rate Assumptions'!$B$5,MIN('Rate Assumptions'!$B$6,IF($B9="Bridge",'Rate Assumptions'!$B$11,IF($B9="New Construction",'Rate Assumptions'!$B$10,'Rate Assumptions'!$B$9))+IF($C9="Tier 1",'Rate Assumptions'!$B$12,IF($C9="Tier 2",'Rate Assumptions'!$B$13,'Rate Assumptions'!$B$14))+'Rate Assumptions'!$B$31)),"N/A") -> N/A | P9: =IF(P$4<=$H9,MAX('Rate Assumptions'!$B$5,MIN('Rate Assumptions'!$B$6,IF($B9="Bridge",'Rate Assumptions'!$B$11,IF($B9="New Construction",'Rate Assumptions'!$B$10,'Rate Assumptions'!$B$9))+IF($C9="Tier 1",'Rate Assumptions'!$B$12,IF($C9="Tier 2",'Rate Assumptions'!$B$13,'Rate Assumptions'!$B$14))+'Rate Assumptions'!$B$32)),"N/A") -> N/A
A10: Purchase | B10: New Construction | C10: Tier 3 | D10: 950000 | E10: 740 | F10: 0.6 | G10: 0.6 | H10: 0.8 | I10: Max Acq. LTV subject to soft costs included in construction budget | J10: =IF(J$4<=$H10,MAX('Rate Assumptions'!$B$5,MIN('Rate Assumptions'!$B$6,IF($B10="Bridge",'Rate Assumptions'!$B$11,IF($B10="New Construction",'Rate Assumptions'!$B$10,'Rate Assumptions'!$B$9))+IF($C10="Tier 1",'Rate Assumptions'!$B$12,IF($C10="Tier 2",'Rate Assumptions'!$B$13,'Rate Assumptions'!$B$14))+'Rate Assumptions'!$B$26)),"N/A") -> 0.0975 | K10: =IF(K$4<=$H10,MAX('Rate Assumptions'!$B$5,MIN('Rate Assumptions'!$B$6,IF($B10="Bridge",'Rate Assumptions'!$B$11,IF($B10="New Construction",'Rate Assumptions'!$B$10,'Rate Assumptions'!$B$9))+IF($C10="Tier 1",'Rate Assumptions'!$B$12,IF($C10="Tier 2",'Rate Assumptions'!$B$13,'Rate Assumptions'!$B$14))+'Rate Assumptions'!$B$27)),"N/A") -> 0.0985 | L10: =IF(L$4<=$H10,MAX('Rate Assumptions'!$B$5,MIN('Rate Assumptions'!$B$6,IF($B10="Bridge",'Rate Assumptions'!$B$11,IF($B10="New Construction",'Rate Assumptions'!$B$10,'Rate Assumptions'!$B$9))+IF($C10="Tier 1",'Rate Assumptions'!$B$12,IF($C10="Tier 2",'Rate Assumptions'!$B$13,'Rate Assumptions'!$B$14))+'Rate Assumptions'!$B$28)),"N/A") -> 0.0995 | M10: =IF(M$4<=$H10,MAX('Rate Assumptions'!$B$5,MIN('Rate Assumptions'!$B$6,IF($B10="Bridge",'Rate Assumptions'!$B$11,IF($B10="New Construction",'Rate Assumptions'!$B$10,'Rate Assumptions'!$B$9))+IF($C10="Tier 1",'Rate Assumptions'!$B$12,IF($C10="Tier 2",'Rate Assumptions'!$B$13,'Rate Assumptions'!$B$14))+'Rate Assumptions'!$B$29)),"N/A") -> 0.1005 | N10: =IF(N$4<=$H10,MAX('Rate Assumptions'!$B$5,MIN('Rate Assumptions'!$B$6,IF($B10="Bridge",'Rate Assumptions'!$B$11,IF($B10="New Construction",'Rate Assumptions'!$B$10,'Rate Assumptions'!$B$9))+IF($C10="Tier 1",'Rate Assumptions'!$B$12,IF($C10="Tier 2",'Rate Assumptions'!$B$13,'Rate Assumptions'!$B$14))+'Rate Assumptions'!$B$30)),"N/A") -> N/A | O10: =IF(O$4<=$H10,MAX('Rate Assumptions'!$B$5,MIN('Rate Assumptions'!$B$6,IF($B10="Bridge",'Rate Assumptions'!$B$11,IF($B10="New Construction",'Rate Assumptions'!$B$10,'Rate Assumptions'!$B$9))+IF($C10="Tier 1",'Rate Assumptions'!$B$12,IF($C10="Tier 2",'Rate Assumptions'!$B$13,'Rate Assumptions'!$B$14))+'Rate Assumptions'!$B$31)),"N/A") -> N/A | P10: =IF(P$4<=$H10,MAX('Rate Assumptions'!$B$5,MIN('Rate Assumptions'!$B$6,IF($B10="Bridge",'Rate Assumptions'!$B$11,IF($B10="New Construction",'Rate Assumptions'!$B$10,'Rate Assumptions'!$B$9))+IF($C10="Tier 1",'Rate Assumptions'!$B$12,IF($C10="Tier 2",'Rate Assumptions'!$B$13,'Rate Assumptions'!$B$14))+'Rate Assumptions'!$B$32)),"N/A") -> N/A
A11: Purchase | B11: Bridge | C11: Tier 1 | D11: 2500000 | E11: 600 | F11: 0.75 | G11: 0.75 | H11: 0.75 | J11: =IF(J$4<=$H11,MAX('Rate Assumptions'!$B$5,MIN('Rate Assumptions'!$B$6,IF($B11="Bridge",'Rate Assumptions'!$B$11,IF($B11="New Construction",'Rate Assumptions'!$B$10,'Rate Assumptions'!$B$9))+IF($C11="Tier 1",'Rate Assumptions'!$B$12,IF($C11="Tier 2",'Rate Assumptions'!$B$13,'Rate Assumptions'!$B$14))+'Rate Assumptions'!$B$26)),"N/A") -> 0.0925 | K11: =IF(K$4<=$H11,MAX('Rate Assumptions'!$B$5,MIN('Rate Assumptions'!$B$6,IF($B11="Bridge",'Rate Assumptions'!$B$11,IF($B11="New Construction",'Rate Assumptions'!$B$10,'Rate Assumptions'!$B$9))+IF($C11="Tier 1",'Rate Assumptions'!$B$12,IF($C11="Tier 2",'Rate Assumptions'!$B$13,'Rate Assumptions'!$B$14))+'Rate Assumptions'!$B$27)),"N/A") -> 0.093 | L11: =IF(L$4<=$H11,MAX('Rate Assumptions'!$B$5,MIN('Rate Assumptions'!$B$6,IF($B11="Bridge",'Rate Assumptions'!$B$11,IF($B11="New Construction",'Rate Assumptions'!$B$10,'Rate Assumptions'!$B$9))+IF($C11="Tier 1",'Rate Assumptions'!$B$12,IF($C11="Tier 2",'Rate Assumptions'!$B$13,'Rate Assumptions'!$B$14))+'Rate Assumptions'!$B$28)),"N/A") -> 0.094 | M11: =IF(M$4<=$H11,MAX('Rate Assumptions'!$B$5,MIN('Rate Assumptions'!$B$6,IF($B11="Bridge",'Rate Assumptions'!$B$11,IF($B11="New Construction",'Rate Assumptions'!$B$10,'Rate Assumptions'!$B$9))+IF($C11="Tier 1",'Rate Assumptions'!$B$12,IF($C11="Tier 2",'Rate Assumptions'!$B$13,'Rate Assumptions'!$B$14))+'Rate Assumptions'!$B$29)),"N/A") -> N/A | N11: =IF(N$4<=$H11,MAX('Rate Assumptions'!$B$5,MIN('Rate Assumptions'!$B$6,IF($B11="Bridge",'Rate Assumptions'!$B$11,IF($B11="New Construction",'Rate Assumptions'!$B$10,'Rate Assumptions'!$B$9))+IF($C11="Tier 1",'Rate Assumptions'!$B$12,IF($C11="Tier 2",'Rate Assumptions'!$B$13,'Rate Assumptions'!$B$14))+'Rate Assumptions'!$B$30)),"N/A") -> N/A | O11: =IF(O$4<=$H11,MAX('Rate Assumptions'!$B$5,MIN('Rate Assumptions'!$B$6,IF($B11="Bridge",'Rate Assumptions'!$B$11,IF($B11="New Construction",'Rate Assumptions'!$B$10,'Rate Assumptions'!$B$9))+IF($C11="Tier 1",'Rate Assumptions'!$B$12,IF($C11="Tier 2",'Rate Assumptions'!$B$13,'Rate Assumptions'!$B$14))+'Rate Assumptions'!$B$31)),"N/A") -> N/A | P11: =IF(P$4<=$H11,MAX('Rate Assumptions'!$B$5,MIN('Rate Assumptions'!$B$6,IF($B11="Bridge",'Rate Assumptions'!$B$11,IF($B11="New Construction",'Rate Assumptions'!$B$10,'Rate Assumptions'!$B$9))+IF($C11="Tier 1",'Rate Assumptions'!$B$12,IF($C11="Tier 2",'Rate Assumptions'!$B$13,'Rate Assumptions'!$B$14))+'Rate Assumptions'!$B$32)),"N/A") -> N/A
A12: Purchase | B12: Bridge | C12: Tier 2 | D12: 2500000 | E12: 660 | F12: 0.7 | G12: 0.7 | H12: 0.7 | J12: =IF(J$4<=$H12,MAX('Rate Assumptions'!$B$5,MIN('Rate Assumptions'!$B$6,IF($B12="Bridge",'Rate Assumptions'!$B$11,IF($B12="New Construction",'Rate Assumptions'!$B$10,'Rate Assumptions'!$B$9))+IF($C12="Tier 1",'Rate Assumptions'!$B$12,IF($C12="Tier 2",'Rate Assumptions'!$B$13,'Rate Assumptions'!$B$14))+'Rate Assumptions'!$B$26)),"N/A") -> 0.093 | K12: =IF(K$4<=$H12,MAX('Rate Assumptions'!$B$5,MIN('Rate Assumptions'!$B$6,IF($B12="Bridge",'Rate Assumptions'!$B$11,IF($B12="New Construction",'Rate Assumptions'!$B$10,'Rate Assumptions'!$B$9))+IF($C12="Tier 1",'Rate Assumptions'!$B$12,IF($C12="Tier 2",'Rate Assumptions'!$B$13,'Rate Assumptions'!$B$14))+'Rate Assumptions'!$B$27)),"N/A") -> 0.094 | L12: =IF(L$4<=$H12,MAX('Rate Assumptions'!$B$5,MIN('Rate Assumptions'!$B$6,IF($B12="Bridge",'Rate Assumptions'!$B$11,IF($B12="New Construction",'Rate Assumptions'!$B$10,'Rate Assumptions'!$B$9))+IF($C12="Tier 1",'Rate Assumptions'!$B$12,IF($C12="Tier 2",'Rate Assumptions'!$B$13,'Rate Assumptions'!$B$14))+'Rate Assumptions'!$B$28)),"N/A") -> N/A | M12: =IF(M$4<=$H12,MAX('Rate Assumptions'!$B$5,MIN('Rate Assumptions'!$B$6,IF($B12="Bridge",'Rate Assumptions'!$B$11,IF($B12="New Construction",'Rate Assumptions'!$B$10,'Rate Assumptions'!$B$9))+IF($C12="Tier 1",'Rate Assumptions'!$B$12,IF($C12="Tier 2",'Rate Assumptions'!$B$13,'Rate Assumptions'!$B$14))+'Rate Assumptions'!$B$29)),"N/A") -> N/A | N12: =IF(N$4<=$H12,MAX('Rate Assumptions'!$B$5,MIN('Rate Assumptions'!$B$6,IF($B12="Bridge",'Rate Assumptions'!$B$11,IF($B12="New Construction",'Rate Assumptions'!$B$10,'Rate Assumptions'!$B$9))+IF($C12="Tier 1",'Rate Assumptions'!$B$12,IF($C12="Tier 2",'Rate Assumptions'!$B$13,'Rate Assumptions'!$B$14))+'Rate Assumptions'!$B$30)),"N/A") -> N/A | O12: =IF(O$4<=$H12,MAX('Rate Assumptions'!$B$5,MIN('Rate Assumptions'!$B$6,IF($B12="Bridge",'Rate Assumptions'!$B$11,IF($B12="New Construction",'Rate Assumptions'!$B$10,'Rate Assumptions'!$B$9))+IF($C12="Tier 1",'Rate Assumptions'!$B$12,IF($C12="Tier 2",'Rate Assumptions'!$B$13,'Rate Assumptions'!$B$14))+'Rate Assumptions'!$B$31)),"N/A") -> N/A | P12: =IF(P$4<=$H12,MAX('Rate Assumptions'!$B$5,MIN('Rate Assumptions'!$B$6,IF($B12="Bridge",'Rate Assumptions'!$B$11,IF($B12="New Construction",'Rate Assumptions'!$B$10,'Rate Assumptions'!$B$9))+IF($C12="Tier 1",'Rate Assumptions'!$B$12,IF($C12="Tier 2",'Rate Assumptions'!$B$13,'Rate Assumptions'!$B$14))+'Rate Assumptions'!$B$32)),"N/A") -> N/A
A13: Purchase | B13: Bridge | C13: Tier 3 | D13: 950000 | E13: 680 | F13: 0.7 | G13: 0.7 | H13: 0.7 | J13: =IF(J$4<=$H13,MAX('Rate Assumptions'!$B$5,MIN('Rate Assumptions'!$B$6,IF($B13="Bridge",'Rate Assumptions'!$B$11,IF($B13="New Construction",'Rate Assumptions'!$B$10,'Rate Assumptions'!$B$9))+IF($C13="Tier 1",'Rate Assumptions'!$B$12,IF($C13="Tier 2",'Rate Assumptions'!$B$13,'Rate Assumptions'!$B$14))+'Rate Assumptions'!$B$26)),"N/A") -> 0.095 | K13: =IF(K$4<=$H13,MAX('Rate Assumptions'!$B$5,MIN('Rate Assumptions'!$B$6,IF($B13="Bridge",'Rate Assumptions'!$B$11,IF($B13="New Construction",'Rate Assumptions'!$B$10,'Rate Assumptions'!$B$9))+IF($C13="Tier 1",'Rate Assumptions'!$B$12,IF($C13="Tier 2",'Rate Assumptions'!$B$13,'Rate Assumptions'!$B$14))+'Rate Assumptions'!$B$27)),"N/A") -> 0.096 | L13: =IF(L$4<=$H13,MAX('Rate Assumptions'!$B$5,MIN('Rate Assumptions'!$B$6,IF($B13="Bridge",'Rate Assumptions'!$B$11,IF($B13="New Construction",'Rate Assumptions'!$B$10,'Rate Assumptions'!$B$9))+IF($C13="Tier 1",'Rate Assumptions'!$B$12,IF($C13="Tier 2",'Rate Assumptions'!$B$13,'Rate Assumptions'!$B$14))+'Rate Assumptions'!$B$28)),"N/A") -> N/A | M13: =IF(M$4<=$H13,MAX('Rate Assumptions'!$B$5,MIN('Rate Assumptions'!$B$6,IF($B13="Bridge",'Rate Assumptions'!$B$11,IF($B13="New Construction",'Rate Assumptions'!$B$10,'Rate Assumptions'!$B$9))+IF($C13="Tier 1",'Rate Assumptions'!$B$12,IF($C13="Tier 2",'Rate Assumptions'!$B$13,'Rate Assumptions'!$B$14))+'Rate Assumptions'!$B$29)),"N/A") -> N/A | N13: =IF(N$4<=$H13,MAX('Rate Assumptions'!$B$5,MIN('Rate Assumptions'!$B$6,IF($B13="Bridge",'Rate Assumptions'!$B$11,IF($B13="New Construction",'Rate Assumptions'!$B$10,'Rate Assumptions'!$B$9))+IF($C13="Tier 1",'Rate Assumptions'!$B$12,IF($C13="Tier 2",'Rate Assumptions'!$B$13,'Rate Assumptions'!$B$14))+'Rate Assumptions'!$B$30)),"N/A") -> N/A | O13: =IF(O$4<=$H13,MAX('Rate Assumptions'!$B$5,MIN('Rate Assumptions'!$B$6,IF($B13="Bridge",'Rate Assumptions'!$B$11,IF($B13="New Construction",'Rate Assumptions'!$B$10,'Rate Assumptions'!$B$9))+IF($C13="Tier 1",'Rate Assumptions'!$B$12,IF($C13="Tier 2",'Rate Assumptions'!$B$13,'Rate Assumptions'!$B$14))+'Rate Assumptions'!$B$31)),"N/A") -> N/A | P13: =IF(P$4<=$H13,MAX('Rate Assumptions'!$B$5,MIN('Rate Assumptions'!$B$6,IF($B13="Bridge",'Rate Assumptions'!$B$11,IF($B13="New Construction",'Rate Assumptions'!$B$10,'Rate Assumptions'!$B$9))+IF($C13="Tier 1",'Rate Assumptions'!$B$12,IF($C13="Tier 2",'Rate Assumptions'!$B$13,'Rate Assumptions'!$B$14))+'Rate Assumptions'!$B$32)),"N/A") -> N/A
A14: Refinance | B14: Fix & Flip / Fix & Hold | C14: Tier 1 | D14: 2500000 | E14: 640 | F14: 0.8 | G14: 0.7 | H14: 0.85 | I14: Mid-construction refinances ineligible | J14: =IF(J$4<=$H14,MAX('Rate Assumptions'!$B$5,MIN('Rate Assumptions'!$B$6,IF($B14="Bridge",'Rate Assumptions'!$B$11,IF($B14="New Construction",'Rate Assumptions'!$B$10,'Rate Assumptions'!$B$9))+IF($C14="Tier 1",'Rate Assumptions'!$B$12,IF($C14="Tier 2",'Rate Assumptions'!$B$13,'Rate Assumptions'!$B$14))+'Rate Assumptions'!$B$26)),"N/A") -> 0.0925 | K14: =IF(K$4<=$H14,MAX('Rate Assumptions'!$B$5,MIN('Rate Assumptions'!$B$6,IF($B14="Bridge",'Rate Assumptions'!$B$11,IF($B14="New Construction",'Rate Assumptions'!$B$10,'Rate Assumptions'!$B$9))+IF($C14="Tier 1",'Rate Assumptions'!$B$12,IF($C14="Tier 2",'Rate Assumptions'!$B$13,'Rate Assumptions'!$B$14))+'Rate Assumptions'!$B$27)),"N/A") -> 0.093 | L14: =IF(L$4<=$H14,MAX('Rate Assumptions'!$B$5,MIN('Rate Assumptions'!$B$6,IF($B14="Bridge",'Rate Assumptions'!$B$11,IF($B14="New Construction",'Rate Assumptions'!$B$10,'Rate Assumptions'!$B$9))+IF($C14="Tier 1",'Rate Assumptions'!$B$12,IF($C14="Tier 2",'Rate Assumptions'!$B$13,'Rate Assumptions'!$B$14))+'Rate Assumptions'!$B$28)),"N/A") -> 0.094 | M14: =IF(M$4<=$H14,MAX('Rate Assumptions'!$B$5,MIN('Rate Assumptions'!$B$6,IF($B14="Bridge",'Rate Assumptions'!$B$11,IF($B14="New Construction",'Rate Assumptions'!$B$10,'Rate Assumptions'!$B$9))+IF($C14="Tier 1",'Rate Assumptions'!$B$12,IF($C14="Tier 2",'Rate Assumptions'!$B$13,'Rate Assumptions'!$B$14))+'Rate Assumptions'!$B$29)),"N/A") -> 0.095 | N14: =IF(N$4<=$H14,MAX('Rate Assumptions'!$B$5,MIN('Rate Assumptions'!$B$6,IF($B14="Bridge",'Rate Assumptions'!$B$11,IF($B14="New Construction",'Rate Assumptions'!$B$10,'Rate Assumptions'!$B$9))+IF($C14="Tier 1",'Rate Assumptions'!$B$12,IF($C14="Tier 2",'Rate Assumptions'!$B$13,'Rate Assumptions'!$B$14))+'Rate Assumptions'!$B$30)),"N/A") -> 0.096 | O14: =IF(O$4<=$H14,MAX('Rate Assumptions'!$B$5,MIN('Rate Assumptions'!$B$6,IF($B14="Bridge",'Rate Assumptions'!$B$11,IF($B14="New Construction",'Rate Assumptions'!$B$10,'Rate Assumptions'!$B$9))+IF($C14="Tier 1",'Rate Assumptions'!$B$12,IF($C14="Tier 2",'Rate Assumptions'!$B$13,'Rate Assumptions'!$B$14))+'Rate Assumptions'!$B$31)),"N/A") -> N/A | P14: =IF(P$4<=$H14,MAX('Rate Assumptions'!$B$5,MIN('Rate Assumptions'!$B$6,IF($B14="Bridge",'Rate Assumptions'!$B$11,IF($B14="New Construction",'Rate Assumptions'!$B$10,'Rate Assumptions'!$B$9))+IF($C14="Tier 1",'Rate Assumptions'!$B$12,IF($C14="Tier 2",'Rate Assumptions'!$B$13,'Rate Assumptions'!$B$14))+'Rate Assumptions'!$B$32)),"N/A") -> N/A
A15: Refinance | B15: Fix & Flip / Fix & Hold | C15: Tier 2 | D15: 2500000 | E15: 660 | F15: 0.75 | G15: 0.65 | H15: 0.8 | I15: Mid-construction refinances ineligible | J15: =IF(J$4<=$H15,MAX('Rate Assumptions'!$B$5,MIN('Rate Assumptions'!$B$6,IF($B15="Bridge",'Rate Assumptions'!$B$11,IF($B15="New Construction",'Rate Assumptions'!$B$10,'Rate Assumptions'!$B$9))+IF($C15="Tier 1",'Rate Assumptions'!$B$12,IF($C15="Tier 2",'Rate Assumptions'!$B$13,'Rate Assumptions'!$B$14))+'Rate Assumptions'!$B$26)),"N/A") -> 0.093 | K15: =IF(K$4<=$H15,MAX('Rate Assumptions'!$B$5,MIN('Rate Assumptions'!$B$6,IF($B15="Bridge",'Rate Assumptions'!$B$11,IF($B15="New Construction",'Rate Assumptions'!$B$10,'Rate Assumptions'!$B$9))+IF($C15="Tier 1",'Rate Assumptions'!$B$12,IF($C15="Tier 2",'Rate Assumptions'!$B$13,'Rate Assumptions'!$B$14))+'Rate Assumptions'!$B$27)),"N/A") -> 0.094 | L15: =IF(L$4<=$H15,MAX('Rate Assumptions'!$B$5,MIN('Rate Assumptions'!$B$6,IF($B15="Bridge",'Rate Assumptions'!$B$11,IF($B15="New Construction",'Rate Assumptions'!$B$10,'Rate Assumptions'!$B$9))+IF($C15="Tier 1",'Rate Assumptions'!$B$12,IF($C15="Tier 2",'Rate Assumptions'!$B$13,'Rate Assumptions'!$B$14))+'Rate Assumptions'!$B$28)),"N/A") -> 0.095 | M15: =IF(M$4<=$H15,MAX('Rate Assumptions'!$B$5,MIN('Rate Assumptions'!$B$6,IF($B15="Bridge",'Rate Assumptions'!$B$11,IF($B15="New Construction",'Rate Assumptions'!$B$10,'Rate Assumptions'!$B$9))+IF($C15="Tier 1",'Rate Assumptions'!$B$12,IF($C15="Tier 2",'Rate Assumptions'!$B$13,'Rate Assumptions'!$B$14))+'Rate Assumptions'!$B$29)),"N/A") -> 0.096 | N15: =IF(N$4<=$H15,MAX('Rate Assumptions'!$B$5,MIN('Rate Assumptions'!$B$6,IF($B15="Bridge",'Rate Assumptions'!$B$11,IF($B15="New Construction",'Rate Assumptions'!$B$10,'Rate Assumptions'!$B$9))+IF($C15="Tier 1",'Rate Assumptions'!$B$12,IF($C15="Tier 2",'Rate Assumptions'!$B$13,'Rate Assumptions'!$B$14))+'Rate Assumptions'!$B$30)),"N/A") -> N/A | O15: =IF(O$4<=$H15,MAX('Rate Assumptions'!$B$5,MIN('Rate Assumptions'!$B$6,IF($B15="Bridge",'Rate Assumptions'!$B$11,IF($B15="New Construction",'Rate Assumptions'!$B$10,'Rate Assumptions'!$B$9))+IF($C15="Tier 1",'Rate Assumptions'!$B$12,IF($C15="Tier 2",'Rate Assumptions'!$B$13,'Rate Assumptions'!$B$14))+'Rate Assumptions'!$B$31)),"N/A") -> N/A | P15: =IF(P$4<=$H15,MAX('Rate Assumptions'!$B$5,MIN('Rate Assumptions'!$B$6,IF($B15="Bridge",'Rate Assumptions'!$B$11,IF($B15="New Construction",'Rate Assumptions'!$B$10,'Rate Assumptions'!$B$9))+IF($C15="Tier 1",'Rate Assumptions'!$B$12,IF($C15="Tier 2",'Rate Assumptions'!$B$13,'Rate Assumptions'!$B$14))+'Rate Assumptions'!$B$32)),"N/A") -> N/A
A16: Refinance | B16: Fix & Flip / Fix & Hold | C16: Tier 3 | D16: N/A | E16: N/A | F16: N/A | G16: N/A | H16: N/A | I16: Ineligible | J16: "Ineligible" | K16: "Ineligible" | L16: "Ineligible" | M16: "Ineligible" | N16: "Ineligible" | O16: "Ineligible" | P16: "Ineligible"
A17: Refinance | B17: New Construction | C17: Tier 1 | D17: 2500000 | E17: 680 | F17: 0.7 | G17: 0.7 | H17: 0.85 | I17: Max Acq. LTV subject to soft costs included in construction budget | J17: =IF(J$4<=$H17,MAX('Rate Assumptions'!$B$5,MIN('Rate Assumptions'!$B$6,IF($B17="Bridge",'Rate Assumptions'!$B$11,IF($B17="New Construction",'Rate Assumptions'!$B$10,'Rate Assumptions'!$B$9))+IF($C17="Tier 1",'Rate Assumptions'!$B$12,IF($C17="Tier 2",'Rate Assumptions'!$B$13,'Rate Assumptions'!$B$14))+'Rate Assumptions'!$B$26)),"N/A") -> 0.0945 | K17: =IF(K$4<=$H17,MAX('Rate Assumptions'!$B$5,MIN('Rate Assumptions'!$B$6,IF($B17="Bridge",'Rate Assumptions'!$B$11,IF($B17="New Construction",'Rate Assumptions'!$B$10,'Rate Assumptions'!$B$9))+IF($C17="Tier 1",'Rate Assumptions'!$B$12,IF($C17="Tier 2",'Rate Assumptions'!$B$13,'Rate Assumptions'!$B$14))+'Rate Assumptions'!$B$27)),"N/A") -> 0.0955 | L17: =IF(L$4<=$H17,MAX('Rate Assumptions'!$B$5,MIN('Rate Assumptions'!$B$6,IF($B17="Bridge",'Rate Assumptions'!$B$11,IF($B17="New Construction",'Rate Assumptions'!$B$10,'Rate Assumptions'!$B$9))+IF($C17="Tier 1",'Rate Assumptions'!$B$12,IF($C17="Tier 2",'Rate Assumptions'!$B$13,'Rate Assumptions'!$B$14))+'Rate Assumptions'!$B$28)),"N/A") -> 0.0965 | M17: =IF(M$4<=$H17,MAX('Rate Assumptions'!$B$5,MIN('Rate Assumptions'!$B$6,IF($B17="Bridge",'Rate Assumptions'!$B$11,IF($B17="New Construction",'Rate Assumptions'!$B$10,'Rate Assumptions'!$B$9))+IF($C17="Tier 1",'Rate Assumptions'!$B$12,IF($C17="Tier 2",'Rate Assumptions'!$B$13,'Rate Assumptions'!$B$14))+'Rate Assumptions'!$B$29)),"N/A") -> 0.0975 | N17: =IF(N$4<=$H17,MAX('Rate Assumptions'!$B$5,MIN('Rate Assumptions'!$B$6,IF($B17="Bridge",'Rate Assumptions'!$B$11,IF($B17="New Construction",'Rate Assumptions'!$B$10,'Rate Assumptions'!$B$9))+IF($C17="Tier 1",'Rate Assumptions'!$B$12,IF($C17="Tier 2",'Rate Assumptions'!$B$13,'Rate Assumptions'!$B$14))+'Rate Assumptions'!$B$30)),"N/A") -> 0.0985 | O17: =IF(O$4<=$H17,MAX('Rate Assumptions'!$B$5,MIN('Rate Assumptions'!$B$6,IF($B17="Bridge",'Rate Assumptions'!$B$11,IF($B17="New Construction",'Rate Assumptions'!$B$10,'Rate Assumptions'!$B$9))+IF($C17="Tier 1",'Rate Assumptions'!$B$12,IF($C17="Tier 2",'Rate Assumptions'!$B$13,'Rate Assumptions'!$B$14))+'Rate Assumptions'!$B$31)),"N/A") -> N/A | P17: =IF(P$4<=$H17,MAX('Rate Assumptions'!$B$5,MIN('Rate Assumptions'!$B$6,IF($B17="Bridge",'Rate Assumptions'!$B$11,IF($B17="New Construction",'Rate Assumptions'!$B$10,'Rate Assumptions'!$B$9))+IF($C17="Tier 1",'Rate Assumptions'!$B$12,IF($C17="Tier 2",'Rate Assumptions'!$B$13,'Rate Assumptions'!$B$14))+'Rate Assumptions'!$B$32)),"N/A") -> N/A
A18: Refinance | B18: New Construction | C18: Tier 2 | D18: 2500000 | E18: 700 | F18: 0.7 | G18: 0.65 | H18: 0.85 | I18: Max Acq. LTV subject to soft costs included in construction budget | J18: =IF(J$4<=$H18,MAX('Rate Assumptions'!$B$5,MIN('Rate Assumptions'!$B$6,IF($B18="Bridge",'Rate Assumptions'!$B$11,IF($B18="New Construction",'Rate Assumptions'!$B$10,'Rate Assumptions'!$B$9))+IF($C18="Tier 1",'Rate Assumptions'!$B$12,IF($C18="Tier 2",'Rate Assumptions'!$B$13,'Rate Assumptions'!$B$14))+'Rate Assumptions'!$B$26)),"N/A") -> 0.0955 | K18: =IF(K$4<=$H18,MAX('Rate Assumptions'!$B$5,MIN('Rate Assumptions'!$B$6,IF($B18="Bridge",'Rate Assumptions'!$B$11,IF($B18="New Construction",'Rate Assumptions'!$B$10,'Rate Assumptions'!$B$9))+IF($C18="Tier 1",'Rate Assumptions'!$B$12,IF($C18="Tier 2",'Rate Assumptions'!$B$13,'Rate Assumptions'!$B$14))+'Rate Assumptions'!$B$27)),"N/A") -> 0.0965 | L18: =IF(L$4<=$H18,MAX('Rate Assumptions'!$B$5,MIN('Rate Assumptions'!$B$6,IF($B18="Bridge",'Rate Assumptions'!$B$11,IF($B18="New Construction",'Rate Assumptions'!$B$10,'Rate Assumptions'!$B$9))+IF($C18="Tier 1",'Rate Assumptions'!$B$12,IF($C18="Tier 2",'Rate Assumptions'!$B$13,'Rate Assumptions'!$B$14))+'Rate Assumptions'!$B$28)),"N/A") -> 0.0975 | M18: =IF(M$4<=$H18,MAX('Rate Assumptions'!$B$5,MIN('Rate Assumptions'!$B$6,IF($B18="Bridge",'Rate Assumptions'!$B$11,IF($B18="New Construction",'Rate Assumptions'!$B$10,'Rate Assumptions'!$B$9))+IF($C18="Tier 1",'Rate Assumptions'!$B$12,IF($C18="Tier 2",'Rate Assumptions'!$B$13,'Rate Assumptions'!$B$14))+'Rate Assumptions'!$B$29)),"N/A") -> 0.0985 | N18: =IF(N$4<=$H18,MAX('Rate Assumptions'!$B$5,MIN('Rate Assumptions'!$B$6,IF($B18="Bridge",'Rate Assumptions'!$B$11,IF($B18="New Construction",'Rate Assumptions'!$B$10,'Rate Assumptions'!$B$9))+IF($C18="Tier 1",'Rate Assumptions'!$B$12,IF($C18="Tier 2",'Rate Assumptions'!$B$13,'Rate Assumptions'!$B$14))+'Rate Assumptions'!$B$30)),"N/A") -> 0.0995 | O18: =IF(O$4<=$H18,MAX('Rate Assumptions'!$B$5,MIN('Rate Assumptions'!$B$6,IF($B18="Bridge",'Rate Assumptions'!$B$11,IF($B18="New Construction",'Rate Assumptions'!$B$10,'Rate Assumptions'!$B$9))+IF($C18="Tier 1",'Rate Assumptions'!$B$12,IF($C18="Tier 2",'Rate Assumptions'!$B$13,'Rate Assumptions'!$B$14))+'Rate Assumptions'!$B$31)),"N/A") -> N/A | P18: =IF(P$4<=$H18,MAX('Rate Assumptions'!$B$5,MIN('Rate Assumptions'!$B$6,IF($B18="Bridge",'Rate Assumptions'!$B$11,IF($B18="New Construction",'Rate Assumptions'!$B$10,'Rate Assumptions'!$B$9))+IF($C18="Tier 1",'Rate Assumptions'!$B$12,IF($C18="Tier 2",'Rate Assumptions'!$B$13,'Rate Assumptions'!$B$14))+'Rate Assumptions'!$B$32)),"N/A") -> N/A
A19: Refinance | B19: New Construction | C19: Tier 3 | D19: 950000 | E19: 740 | F19: 0.6 | G19: 0.6 | H19: 0.8 | I19: Max Acq. LTV subject to soft costs included in construction budget | J19: =IF(J$4<=$H19,MAX('Rate Assumptions'!$B$5,MIN('Rate Assumptions'!$B$6,IF($B19="Bridge",'Rate Assumptions'!$B$11,IF($B19="New Construction",'Rate Assumptions'!$B$10,'Rate Assumptions'!$B$9))+IF($C19="Tier 1",'Rate Assumptions'!$B$12,IF($C19="Tier 2",'Rate Assumptions'!$B$13,'Rate Assumptions'!$B$14))+'Rate Assumptions'!$B$26)),"N/A") -> 0.0975 | K19: =IF(K$4<=$H19,MAX('Rate Assumptions'!$B$5,MIN('Rate Assumptions'!$B$6,IF($B19="Bridge",'Rate Assumptions'!$B$11,IF($B19="New Construction",'Rate Assumptions'!$B$10,'Rate Assumptions'!$B$9))+IF($C19="Tier 1",'Rate Assumptions'!$B$12,IF($C19="Tier 2",'Rate Assumptions'!$B$13,'Rate Assumptions'!$B$14))+'Rate Assumptions'!$B$27)),"N/A") -> 0.0985 | L19: =IF(L$4<=$H19,MAX('Rate Assumptions'!$B$5,MIN('Rate Assumptions'!$B$6,IF($B19="Bridge",'Rate Assumptions'!$B$11,IF($B19="New Construction",'Rate Assumptions'!$B$10,'Rate Assumptions'!$B$9))+IF($C19="Tier 1",'Rate Assumptions'!$B$12,IF($C19="Tier 2",'Rate Assumptions'!$B$13,'Rate Assumptions'!$B$14))+'Rate Assumptions'!$B$28)),"N/A") -> 0.0995 | M19: =IF(M$4<=$H19,MAX('Rate Assumptions'!$B$5,MIN('Rate Assumptions'!$B$6,IF($B19="Bridge",'Rate Assumptions'!$B$11,IF($B19="New Construction",'Rate Assumptions'!$B$10,'Rate Assumptions'!$B$9))+IF($C19="Tier 1",'Rate Assumptions'!$B$12,IF($C19="Tier 2",'Rate Assumptions'!$B$13,'Rate Assumptions'!$B$14))+'Rate Assumptions'!$B$29)),"N/A") -> 0.1005 | N19: =IF(N$4<=$H19,MAX('Rate Assumptions'!$B$5,MIN('Rate Assumptions'!$B$6,IF($B19="Bridge",'Rate Assumptions'!$B$11,IF($B19="New Construction",'Rate Assumptions'!$B$10,'Rate Assumptions'!$B$9))+IF($C19="Tier 1",'Rate Assumptions'!$B$12,IF($C19="Tier 2",'Rate Assumptions'!$B$13,'Rate Assumptions'!$B$14))+'Rate Assumptions'!$B$30)),"N/A") -> N/A | O19: =IF(O$4<=$H19,MAX('Rate Assumptions'!$B$5,MIN('Rate Assumptions'!$B$6,IF($B19="Bridge",'Rate Assumptions'!$B$11,IF($B19="New Construction",'Rate Assumptions'!$B$10,'Rate Assumptions'!$B$9))+IF($C19="Tier 1",'Rate Assumptions'!$B$12,IF($C19="Tier 2",'Rate Assumptions'!$B$13,'Rate Assumptions'!$B$14))+'Rate Assumptions'!$B$31)),"N/A") -> N/A | P19: =IF(P$4<=$H19,MAX('Rate Assumptions'!$B$5,MIN('Rate Assumptions'!$B$6,IF($B19="Bridge",'Rate Assumptions'!$B$11,IF($B19="New Construction",'Rate Assumptions'!$B$10,'Rate Assumptions'!$B$9))+IF($C19="Tier 1",'Rate Assumptions'!$B$12,IF($C19="Tier 2",'Rate Assumptions'!$B$13,'Rate Assumptions'!$B$14))+'Rate Assumptions'!$B$32)),"N/A") -> N/A
A20: Refinance | B20: Bridge | C20: Tier 1 | D20: 1500000 | E20: 680 | F20: 0.7 | G20: 0.7 | H20: 0.7 | J20: =IF(J$4<=$H20,MAX('Rate Assumptions'!$B$5,MIN('Rate Assumptions'!$B$6,IF($B20="Bridge",'Rate Assumptions'!$B$11,IF($B20="New Construction",'Rate Assumptions'!$B$10,'Rate Assumptions'!$B$9))+IF($C20="Tier 1",'Rate Assumptions'!$B$12,IF($C20="Tier 2",'Rate Assumptions'!$B$13,'Rate Assumptions'!$B$14))+'Rate Assumptions'!$B$26)),"N/A") -> 0.0925 | K20: =IF(K$4<=$H20,MAX('Rate Assumptions'!$B$5,MIN('Rate Assumptions'!$B$6,IF($B20="Bridge",'Rate Assumptions'!$B$11,IF($B20="New Construction",'Rate Assumptions'!$B$10,'Rate Assumptions'!$B$9))+IF($C20="Tier 1",'Rate Assumptions'!$B$12,IF($C20="Tier 2",'Rate Assumptions'!$B$13,'Rate Assumptions'!$B$14))+'Rate Assumptions'!$B$27)),"N/A") -> 0.093 | L20: =IF(L$4<=$H20,MAX('Rate Assumptions'!$B$5,MIN('Rate Assumptions'!$B$6,IF($B20="Bridge",'Rate Assumptions'!$B$11,IF($B20="New Construction",'Rate Assumptions'!$B$10,'Rate Assumptions'!$B$9))+IF($C20="Tier 1",'Rate Assumptions'!$B$12,IF($C20="Tier 2",'Rate Assumptions'!$B$13,'Rate Assumptions'!$B$14))+'Rate Assumptions'!$B$28)),"N/A") -> N/A | M20: =IF(M$4<=$H20,MAX('Rate Assumptions'!$B$5,MIN('Rate Assumptions'!$B$6,IF($B20="Bridge",'Rate Assumptions'!$B$11,IF($B20="New Construction",'Rate Assumptions'!$B$10,'Rate Assumptions'!$B$9))+IF($C20="Tier 1",'Rate Assumptions'!$B$12,IF($C20="Tier 2",'Rate Assumptions'!$B$13,'Rate Assumptions'!$B$14))+'Rate Assumptions'!$B$29)),"N/A") -> N/A | N20: =IF(N$4<=$H20,MAX('Rate Assumptions'!$B$5,MIN('Rate Assumptions'!$B$6,IF($B20="Bridge",'Rate Assumptions'!$B$11,IF($B20="New Construction",'Rate Assumptions'!$B$10,'Rate Assumptions'!$B$9))+IF($C20="Tier 1",'Rate Assumptions'!$B$12,IF($C20="Tier 2",'Rate Assumptions'!$B$13,'Rate Assumptions'!$B$14))+'Rate Assumptions'!$B$30)),"N/A") -> N/A | O20: =IF(O$4<=$H20,MAX('Rate Assumptions'!$B$5,MIN('Rate Assumptions'!$B$6,IF($B20="Bridge",'Rate Assumptions'!$B$11,IF($B20="New Construction",'Rate Assumptions'!$B$10,'Rate Assumptions'!$B$9))+IF($C20="Tier 1",'Rate Assumptions'!$B$12,IF($C20="Tier 2",'Rate Assumptions'!$B$13,'Rate Assumptions'!$B$14))+'Rate Assumptions'!$B$31)),"N/A") -> N/A | P20: =IF(P$4<=$H20,MAX('Rate Assumptions'!$B$5,MIN('Rate Assumptions'!$B$6,IF($B20="Bridge",'Rate Assumptions'!$B$11,IF($B20="New Construction",'Rate Assumptions'!$B$10,'Rate Assumptions'!$B$9))+IF($C20="Tier 1",'Rate Assumptions'!$B$12,IF($C20="Tier 2",'Rate Assumptions'!$B$13,'Rate Assumptions'!$B$14))+'Rate Assumptions'!$B$32)),"N/A") -> N/A
A21: Refinance | B21: Bridge | C21: Tier 2 | D21: 1500000 | E21: 700 | F21: 0.7 | G21: 0.7 | H21: 0.7 | J21: =IF(J$4<=$H21,MAX('Rate Assumptions'!$B$5,MIN('Rate Assumptions'!$B$6,IF($B21="Bridge",'Rate Assumptions'!$B$11,IF($B21="New Construction",'Rate Assumptions'!$B$10,'Rate Assumptions'!$B$9))+IF($C21="Tier 1",'Rate Assumptions'!$B$12,IF($C21="Tier 2",'Rate Assumptions'!$B$13,'Rate Assumptions'!$B$14))+'Rate Assumptions'!$B$26)),"N/A") -> 0.093 | K21: =IF(K$4<=$H21,MAX('Rate Assumptions'!$B$5,MIN('Rate Assumptions'!$B$6,IF($B21="Bridge",'Rate Assumptions'!$B$11,IF($B21="New Construction",'Rate Assumptions'!$B$10,'Rate Assumptions'!$B$9))+IF($C21="Tier 1",'Rate Assumptions'!$B$12,IF($C21="Tier 2",'Rate Assumptions'!$B$13,'Rate Assumptions'!$B$14))+'Rate Assumptions'!$B$27)),"N/A") -> 0.094 | L21: =IF(L$4<=$H21,MAX('Rate Assumptions'!$B$5,MIN('Rate Assumptions'!$B$6,IF($B21="Bridge",'Rate Assumptions'!$B$11,IF($B21="New Construction",'Rate Assumptions'!$B$10,'Rate Assumptions'!$B$9))+IF($C21="Tier 1",'Rate Assumptions'!$B$12,IF($C21="Tier 2",'Rate Assumptions'!$B$13,'Rate Assumptions'!$B$14))+'Rate Assumptions'!$B$28)),"N/A") -> N/A | M21: =IF(M$4<=$H21,MAX('Rate Assumptions'!$B$5,MIN('Rate Assumptions'!$B$6,IF($B21="Bridge",'Rate Assumptions'!$B$11,IF($B21="New Construction",'Rate Assumptions'!$B$10,'Rate Assumptions'!$B$9))+IF($C21="Tier 1",'Rate Assumptions'!$B$12,IF($C21="Tier 2",'Rate Assumptions'!$B$13,'Rate Assumptions'!$B$14))+'Rate Assumptions'!$B$29)),"N/A") -> N/A | N21: =IF(N$4<=$H21,MAX('Rate Assumptions'!$B$5,MIN('Rate Assumptions'!$B$6,IF($B21="Bridge",'Rate Assumptions'!$B$11,IF($B21="New Construction",'Rate Assumptions'!$B$10,'Rate Assumptions'!$B$9))+IF($C21="Tier 1",'Rate Assumptions'!$B$12,IF($C21="Tier 2",'Rate Assumptions'!$B$13,'Rate Assumptions'!$B$14))+'Rate Assumptions'!$B$30)),"N/A") -> N/A | O21: =IF(O$4<=$H21,MAX('Rate Assumptions'!$B$5,MIN('Rate Assumptions'!$B$6,IF($B21="Bridge",'Rate Assumptions'!$B$11,IF($B21="New Construction",'Rate Assumptions'!$B$10,'Rate Assumptions'!$B$9))+IF($C21="Tier 1",'Rate Assumptions'!$B$12,IF($C21="Tier 2",'Rate Assumptions'!$B$13,'Rate Assumptions'!$B$14))+'Rate Assumptions'!$B$31)),"N/A") -> N/A | P21: =IF(P$4<=$H21,MAX('Rate Assumptions'!$B$5,MIN('Rate Assumptions'!$B$6,IF($B21="Bridge",'Rate Assumptions'!$B$11,IF($B21="New Construction",'Rate Assumptions'!$B$10,'Rate Assumptions'!$B$9))+IF($C21="Tier 1",'Rate Assumptions'!$B$12,IF($C21="Tier 2",'Rate Assumptions'!$B$13,'Rate Assumptions'!$B$14))+'Rate Assumptions'!$B$32)),"N/A") -> N/A
A22: Refinance | B22: Bridge | C22: Tier 3 | D22: 950000 | E22: 740 | F22: 0.65 | G22: 0.65 | H22: 0.65 | J22: =IF(J$4<=$H22,MAX('Rate Assumptions'!$B$5,MIN('Rate Assumptions'!$B$6,IF($B22="Bridge",'Rate Assumptions'!$B$11,IF($B22="New Construction",'Rate Assumptions'!$B$10,'Rate Assumptions'!$B$9))+IF($C22="Tier 1",'Rate Assumptions'!$B$12,IF($C22="Tier 2",'Rate Assumptions'!$B$13,'Rate Assumptions'!$B$14))+'Rate Assumptions'!$B$26)),"N/A") -> 0.095 | K22: =IF(K$4<=$H22,MAX('Rate Assumptions'!$B$5,MIN('Rate Assumptions'!$B$6,IF($B22="Bridge",'Rate Assumptions'!$B$11,IF($B22="New Construction",'Rate Assumptions'!$B$10,'Rate Assumptions'!$B$9))+IF($C22="Tier 1",'Rate Assumptions'!$B$12,IF($C22="Tier 2",'Rate Assumptions'!$B$13,'Rate Assumptions'!$B$14))+'Rate Assumptions'!$B$27)),"N/A") -> N/A | L22: =IF(L$4<=$H22,MAX('Rate Assumptions'!$B$5,MIN('Rate Assumptions'!$B$6,IF($B22="Bridge",'Rate Assumptions'!$B$11,IF($B22="New Construction",'Rate Assumptions'!$B$10,'Rate Assumptions'!$B$9))+IF($C22="Tier 1",'Rate Assumptions'!$B$12,IF($C22="Tier 2",'Rate Assumptions'!$B$13,'Rate Assumptions'!$B$14))+'Rate Assumptions'!$B$28)),"N/A") -> N/A | M22: =IF(M$4<=$H22,MAX('Rate Assumptions'!$B$5,MIN('Rate Assumptions'!$B$6,IF($B22="Bridge",'Rate Assumptions'!$B$11,IF($B22="New Construction",'Rate Assumptions'!$B$10,'Rate Assumptions'!$B$9))+IF($C22="Tier 1",'Rate Assumptions'!$B$12,IF($C22="Tier 2",'Rate Assumptions'!$B$13,'Rate Assumptions'!$B$14))+'Rate Assumptions'!$B$29)),"N/A") -> N/A | N22: =IF(N$4<=$H22,MAX('Rate Assumptions'!$B$5,MIN('Rate Assumptions'!$B$6,IF($B22="Bridge",'Rate Assumptions'!$B$11,IF($B22="New Construction",'Rate Assumptions'!$B$10,'Rate Assumptions'!$B$9))+IF($C22="Tier 1",'Rate Assumptions'!$B$12,IF($C22="Tier 2",'Rate Assumptions'!$B$13,'Rate Assumptions'!$B$14))+'Rate Assumptions'!$B$30)),"N/A") -> N/A | O22: =IF(O$4<=$H22,MAX('Rate Assumptions'!$B$5,MIN('Rate Assumptions'!$B$6,IF($B22="Bridge",'Rate Assumptions'!$B$11,IF($B22="New Construction",'Rate Assumptions'!$B$10,'Rate Assumptions'!$B$9))+IF($C22="Tier 1",'Rate Assumptions'!$B$12,IF($C22="Tier 2",'Rate Assumptions'!$B$13,'Rate Assumptions'!$B$14))+'Rate Assumptions'!$B$31)),"N/A") -> N/A | P22: =IF(P$4<=$H22,MAX('Rate Assumptions'!$B$5,MIN('Rate Assumptions'!$B$6,IF($B22="Bridge",'Rate Assumptions'!$B$11,IF($B22="New Construction",'Rate Assumptions'!$B$10,'Rate Assumptions'!$B$9))+IF($C22="Tier 1",'Rate Assumptions'!$B$12,IF($C22="Tier 2",'Rate Assumptions'!$B$13,'Rate Assumptions'!$B$14))+'Rate Assumptions'!$B$32)),"N/A") -> N/A
A25: Control notes: Rate cells are suppressed as N/A when the LTC bucket exceeds the guideline Max LTC for that transaction type / strategy / tier. The borrower must also satisfy Max Acq LTV, Max ARLTV, Min FICO, and Max Loan Amount. Use the Loan Quote Evaluator for loan-level pass/fail and final buy rate.

Sheet Guideline Limits
A1: Fidelis Investors - April 2026 Guideline Limits
A2: Appendix A page 15 only; FL / CA / NY overlays excluded
A4: Key | B4: Loan Type | C4: Strategy | D4: Tier | E4: Max Total Loan Amount | F4: Min FICO | G4: Max Acq LTV | H4: Max ARLTV | I4: Max LTC | J4: Eligible Strategy | K4: Notes
A5: Purchase|Fix & Flip / Fix & Hold|Tier 1 | B5: Purchase | C5: Fix & Flip / Fix & Hold | D5: Tier 1 | E5: 2500000 | F5: 600 | G5: 0.9 | H5: 0.75 | I5: 0.925 | J5: F&F / F&H | K5: Projects with sq. ft additions capped at 87.5% LTC
A6: Purchase|Fix & Flip / Fix & Hold|Tier 2 | B6: Purchase | C6: Fix & Flip / Fix & Hold | D6: Tier 2 | E6: 2000000 | F6: 660 | G6: 0.9 | H6: 0.7 | I6: 0.925 | J6: F&F / F&H | K6: Projects with sq. ft additions capped at 87.5% LTC
A7: Purchase|Fix & Flip / Fix & Hold|Tier 3 | B7: Purchase | C7: Fix & Flip / Fix & Hold | D7: Tier 3 | E7: 950000 | F7: 680 | G7: 0.8 | H7: 0.65 | I7: 0.85 | J7: F&F / F&H
A8: Purchase|New Construction|Tier 1 | B8: Purchase | C8: New Construction | D8: Tier 1 | E8: 2500000 | F8: 680 | G8: 0.7 | H8: 0.7 | I8: 0.85 | J8: NC | K8: Max Acq. LTV subject to soft costs included in construction budget
A9: Purchase|New Construction|Tier 2 | B9: Purchase | C9: New Construction | D9: Tier 2 | E9: 2500000 | F9: 700 | G9: 0.7 | H9: 0.65 | I9: 0.85 | J9: NC | K9: Max Acq. LTV subject to soft costs included in construction budget
A10: Purchase|New Construction|Tier 3 | B10: Purchase | C10: New Construction | D10: Tier 3 | E10: 950000 | F10: 740 | G10: 0.6 | H10: 0.6 | I10: 0.8 | J10: NC | K10: Max Acq. LTV subject to soft costs included in construction budget
A11: Purchase|Bridge|Tier 1 | B11: Purchase | C11: Bridge | D11: Tier 1 | E11: 2500000 | F11: 600 | G11: 0.75 | H11: 0.75 | I11: 0.75 | J11: Bridge
A12: Purchase|Bridge|Tier 2 | B12: Purchase | C12: Bridge | D12: Tier 2 | E12: 2500000 | F12: 660 | G12: 0.7 | H12: 0.7 | I12: 0.7 | J12: Bridge
A13: Purchase|Bridge|Tier 3 | B13: Purchase | C13: Bridge | D13: Tier 3 | E13: 950000 | F13: 680 | G13: 0.7 | H13: 0.7 | I13: 0.7 | J13: Bridge
A14: Refinance|Fix & Flip / Fix & Hold|Tier 1 | B14: Refinance | C14: Fix & Flip / Fix & Hold | D14: Tier 1 | E14: 2500000 | F14: 640 | G14: 0.8 | H14: 0.7 | I14: 0.85 | J14: F&F / F&H | K14: Mid-construction refinances ineligible
A15: Refinance|Fix & Flip / Fix & Hold|Tier 2 | B15: Refinance | C15: Fix & Flip / Fix & Hold | D15: Tier 2 | E15: 2500000 | F15: 660 | G15: 0.75 | H15: 0.65 | I15: 0.8 | J15: F&F / F&H | K15: Mid-construction refinances ineligible
A16: Refinance|Fix & Flip / Fix & Hold|Tier 3 | B16: Refinance | C16: Fix & Flip / Fix & Hold | D16: Tier 3 | E16: N/A | F16: N/A | G16: N/A | H16: N/A | I16: N/A | J16: F&F / F&H | K16: Ineligible
A17: Refinance|New Construction|Tier 1 | B17: Refinance | C17: New Construction | D17: Tier 1 | E17: 2500000 | F17: 680 | G17: 0.7 | H17: 0.7 | I17: 0.85 | J17: NC | K17: Max Acq. LTV subject to soft costs included in construction budget
A18: Refinance|New Construction|Tier 2 | B18: Refinance | C18: New Construction | D18: Tier 2 | E18: 2500000 | F18: 700 | G18: 0.7 | H18: 0.65 | I18: 0.85 | J18: NC | K18: Max Acq. LTV subject to soft costs included in construction budget
A19: Refinance|New Construction|Tier 3 | B19: Refinance | C19: New Construction | D19: Tier 3 | E19: 950000 | F19: 740 | G19: 0.6 | H19: 0.6 | I19: 0.8 | J19: NC | K19: Max Acq. LTV subject to soft costs included in construction budget
A20: Refinance|Bridge|Tier 1 | B20: Refinance | C20: Bridge | D20: Tier 1 | E20: 1500000 | F20: 680 | G20: 0.7 | H20: 0.7 | I20: 0.7 | J20: Bridge
A21: Refinance|Bridge|Tier 2 | B21: Refinance | C21: Bridge | D21: Tier 2 | E21: 1500000 | F21: 700 | G21: 0.7 | H21: 0.7 | I21: 0.7 | J21: Bridge
A22: Refinance|Bridge|Tier 3 | B22: Refinance | C22: Bridge | D22: Tier 3 | E22: 950000 | F22: 740 | G22: 0.65 | H22: 0.65 | I22: 0.65 | J22: Bridge

Sheet Rate Assumptions
A1: Rate Assumptions
A2: Editable controls for buy rate floor/cap and pricing add-ons
A4: Assumption | B4: Value | C4: Note
A5: Rate Floor | B5: 0.0925 | C5: Hard minimum buy rate
A6: Rate Cap | B6: 0.105 | C6: Hard maximum buy rate
A7: Target Low | B7: 0.0975 | C7: Most submissions should price at or above this
A8: Target High | B8: 0.1 | C8: Most submissions should price at or below this
A9: Base - Fix & Flip / Fix & Hold | B9: 0.095 | C9: Before tier/FICO/leverage/other adjustments
A10: Base - New Construction | B10: 0.0975 | C10: Before tier/FICO/leverage/other adjustments
A11: Base - Bridge | B11: 0.095 | C11: Before tier/FICO/leverage/other adjustments
A12: Tier 1 Adjustment | B12: -0.001 | C12: 3+ completed projects in last 3 years
A13: Tier 2 Adjustment | B13: 0 | C13: 1-2 completed projects in last 3 years
A14: Tier 3 Adjustment | B14: 0.002 | C14: 0 completed projects in last 3 years
A15: FICO 740+ Adjustment | B15: -0.001
A16: FICO 700-739 Adjustment | B16: 0
A17: FICO <700 Adjustment | B17: 0.002 | C17: Still subject to guideline min FICO by tier/product
A18: 13+ Month Term Adjustment | B18: 0.002
A19: Cash-Out Refi Adjustment | B19: 0.005
A20: Judicial State Adjustment | B20: 0.001
A21: Non-Judicial State Adjustment | B21: -0.001
A22: Sq. Ft Addition LTC Cap | B22: 0.875 | C22: Applies to Purchase F&F/F&H with sq. ft additions
A25: Leverage Buckets | B25: Add-on
A26: 0.65 | B26: -0.002
A27: 0.7 | B27: -0.001
A28: 0.75 | B28: 0
A29: 0.8 | B29: 0.001
A30: 0.85 | B30: 0.002
A31: 0.9 | B31: 0.003
A32: 0.925 | B32: 0.004
A34: Heavy Rehab Adjustment (>25% Rehab Budget) | B34: 0.002 | C34: Add 20 bps if rehab scope exceeds 25%

Sheet Buy Rate
A1: Loan Quote Evaluator
A3: Inputs
A4: Loan Type | B4: ='Data Tape'!AC2 -> 0
A5: Strategy | B5: =IF('Data Tape'!AM2="Fix and Flip","Fix & Flip / Fix & Hold",'Data Tape'!AM2) -> 0
A6: Borrower Tier | B6: =IF('Data Tape'!P2>=3,"Tier 1",IF('Data Tape'!P2>=1,"Tier 2","Tier 3")) -> Tier 3
A7: FICO | B7: ='Data Tape'!Q2 -> 0
A8: Total Loan Amount | B8: ='Data Tape'!H2 -> 0
A9: Acq LTV | B9: =IF('Data Tape'!AC2="Refinance",('Data Tape'!H2-'Data Tape'!I2-'Data Tape'!L2)/'Data Tape'!T2,('Data Tape'!H2-'Data Tape'!I2-'Data Tape'!L2)/'Data Tape'!R2) -> #DIV/0!
A10: ARLTV | B10: ='Data Tape'!H2/'Data Tape'!U2 -> #DIV/0!
A11: LTC | B11: =IF('Data Tape'!AC2="Refinance",'Data Tape'!H2/('Data Tape'!O2+'Data Tape'!T2),'Data Tape'!H2/('Data Tape'!O2+'Data Tape'!R2)) -> #DIV/0!
A12: Term Months | B12: ='Data Tape'!AB2 -> 0
A13: Cash-Out Refi? | B13: No
A14: Foreclosure Type | B14: =IF(OR('Data Tape'!F2="CT",'Data Tape'!F2="DE",'Data Tape'!F2="FL",'Data Tape'!F2="IL",'Data Tape'!F2="IN",'Data Tape'!F2="IA",'Data Tape'!F2="KS",'Data Tape'!F2="KY",'Data Tape'!F2="LA",'Data Tape'!F2="ME",'Data Tape'!F2="MD",'Data Tape'!F2="MA",'Data Tape'!F2="NE",'Data Tape'!F2="NJ",'Data Tape'!F2="NM",'Data Tape'!F2="NY",'Data Tape'!F2="ND",'Data Tape'!F2="OH",'Data Tape'!F2="PA",'Data Tape'!F2="SC",'Data Tape'!F2="VT",'Data Tape'!F2="WI"),"Judicial","Non-Judicial") -> Non-Judicial
A15: Sq. Ft Addition? | B15: =IF('Data Tape'!AJ2-'Data Tape'!AI2>0,"Yes","No") -> No
A16: Heavy Rehab (>25%) | B16: =IF('Data Tape'!AM2="New Construction","No",IF('Data Tape'!O2/('Data Tape'!R2+'Data Tape'!O2)>25%,"Yes","No")) -> #DIV/0!
A19: Results
A20: Guideline Key | B20: =B4&"|"&B5&"|"&B6 -> 0|0|Tier 3
A21: Max Loan Amount | B21: =VLOOKUP(B20,'Guideline Limits'!$A$5:$K$22,5,FALSE) -> #N/A
A22: Min FICO | B22: =VLOOKUP(B20,'Guideline Limits'!$A$5:$K$22,6,FALSE) -> #N/A
A23: Max Acq LTV | B23: =VLOOKUP(B20,'Guideline Limits'!$A$5:$K$22,7,FALSE) -> #N/A
A24: Max ARLTV | B24: =VLOOKUP(B20,'Guideline Limits'!$A$5:$K$22,8,FALSE) -> #N/A
A25: Max LTC | B25: =IF(AND(B4="Purchase",B5="Fix & Flip / Fix & Hold",B15="Yes"),MIN(VLOOKUP(B20,'Guideline Limits'!$A$5:$K$22,9,FALSE),'Rate Assumptions'!$B$22),VLOOKUP(B20,'Guideline Limits'!$A$5:$K$22,9,FALSE)) -> #N/A
A26: Guideline Eligible? | B26: =IF(OR(B21="N/A",B22="N/A"),"Ineligible Product/Tier",IF(AND(B8<=B21,B7>=B22,B9<=B23,B10<=B24,B11<=B25),"Eligible","Not Eligible")) -> #N/A
A27: Pricing Leverage Bucket | B27: =IF(B11<=65%,65%,IF(B11<=70%,70%,IF(B11<=75%,75%,IF(B11<=80%,80%,IF(B11<=85%,85%,IF(B11<=90%,90%,IF(B11<=92.5%,92.5%,999%))))))) -> #DIV/0!
A28: Base Rate | B28: =IF(B5="Bridge",'Rate Assumptions'!$B$11,IF(B5="New Construction",'Rate Assumptions'!$B$10,'Rate Assumptions'!$B$9)) -> 0.095
A29: Tier Adjustment | B29: =IF(B6="Tier 1",'Rate Assumptions'!$B$12,IF(B6="Tier 2",'Rate Assumptions'!$B$13,'Rate Assumptions'!$B$14)) -> 0.002
A30: FICO Adjustment | B30: =IF(B7>=740,'Rate Assumptions'!$B$15,IF(B7>=700,'Rate Assumptions'!$B$16,'Rate Assumptions'!$B$17)) -> 0.002
A31: Leverage Adjustment | B31: =IF(B27=65%,'Rate Assumptions'!$B$26,IF(B27=70%,'Rate Assumptions'!$B$27,IF(B27=75%,'Rate Assumptions'!$B$28,IF(B27=80%,'Rate Assumptions'!$B$29,IF(B27=85%,'Rate Assumptions'!$B$30,IF(B27=90%,'Rate Assumptions'!$B$31,IF(B27=92.5%,'Rate Assumptions'!$B$32,999%))))))) -> #DIV/0!
A32: Term Adjustment | B32: =IF(B12>=13,'Rate Assumptions'!$B$18,0) -> 0
A33: Cash-Out Adjustment | B33: =IF(AND(B4="Refinance",B13="Yes"),'Rate Assumptions'!$B$19,0) -> 0
A34: Foreclosure Adjustment | B34: =IF(B14="Judicial",'Rate Assumptions'!$B$20,'Rate Assumptions'!$B$21) -> -0.001
A35: Heavy Rehab Adjustment | B35: =IF(B16="Yes",'Rate Assumptions'!$B$34,0) -> #DIV/0!
A36: Calculated Buy Rate | B36: =IF(B26="Eligible",MAX('Rate Assumptions'!$B$5,MIN('Rate Assumptions'!$B$6,SUM(B28:B35))),"N/A - Not Guideline Eligible") -> #N/A
A38: Guideline Check
A39: Loan Amount Test | B39: =IF(B8<=B21,"Pass","Fail: loan amount exceeds max loan amount") -> #N/A
A40: FICO Test | B40: =IF(B7>=B22,"Pass","Fail: FICO below minimum") -> #N/A
A41: Acq LTV Test | B41: =IF(B9<=B23,"Pass","Fail: Acq LTV exceeds max") -> #DIV/0!
A42: ARLTV Test | B42: =IF(B10<=B24,"Pass","Fail: ARLTV exceeds max") -> #DIV/0!
A43: LTC Test | B43: =IF(B11<=B25,"Pass","Fail: LTC exceeds max") -> #DIV/0!
A44: Summary | B44: =IF(B26="Eligible","Eligible. Buy rate shown above.","Not eligible. See failed test(s) above.") -> #N/A

Sheet Data Tape
A1: Loan Number | B1: Borrowing Entity | C1: Guarantor | D1: Address | E1: City | F1: State | G1: Zip | H1: Total Loan Amount | I1: Original Rehab Amount | J1: Current Rehab Amount | K1: Current Balance | L1: Original Interest Reserve | M1: Current Interest Reserve | N1: OOP Rehab | O1: Total Rehab Amount | P1: Borrower Total Projects Completed | Q1: FICO | R1: Purchase Price | S1: Assignment Fee, Wholesaler Fee, Seller Credit, Previous Purchase Price | T1: AIV | U1: ARV | V1: Appraisal Type | W1: Note Rate | X1: Origination Date | Y1: Next Due | Z1: First Due | AA1: Maturity Date | AB1: Term | AC1: Purchase/Refi | AD1: Accrual Type | AE1: Borrower Internal Projects Exited | AF1: # of Years Experience | AG1: Repeat Borrower (Y/N) | AH1: # of Bed/Baths | AI1: Pre- Rehab Sqft | AJ1: Post- Rehab Sqft | AK1: # of Units | AL1: Property Type | AM1: Loan Type | AN1: Exit Strategy | AO1: Guarantor Citizenship Status | AP1: Multi Property Flag | AQ1: Cross Collateralized Flag | AR1: Asset Purchased | AS1: Entitlement Status | AT1: Build Status | AU1: Lot Purchase Price | AV1: Lot Purchase Date

Sheet Definitions
B2: Field Name | C2: Data Type | D2: Definition
B3: Loan Number | C3: Text
B4: Borrowing Entity | C4: Text | D4: Borrower LLC Name
B5: Guarantor | C5: Text | D5: Guarantor First and Last Name
B6: Address | C6: Text | D6: Street Address
B7: City | C7: Text
B8: State | C8: Text
B9: Zip | C9: Text | D9: Ensure that it is a full zip code. (Zip codes with 0 at the beginning can be saved as texts)
B10: Total Loan Amount | C10: Numeric
B11: Original Rehab Amount | C11: Numeric | D11: Defined as the Lender Financed Rehab Amount
B12: Current Rehab Amount | C12: Numeric | D12: If Draws released, input remaining rehab
B13: Current Balance | C13: Numeric | D13: Outstanding UPB of the loan
B14: Original Interest Reserve | C14: Numeric | D14: Defined as Financed Interest Reserve
B15: Current Interest Reserve | C15: Numeric | D15: If IR released, input remaining IR
B16: OOP Rehab | C16: Numeric | D16: If borrower is coming out of pocket for rehab funds, then populate
B17: Total Rehab Amount | C17: Numeric | D17: Defined as the sum of the "Original Rehab Amount" (row 10) and "OOP Rehab" (row 15)
B18: FICO Score | C18: Numeric | D18: Determined by using the borrowers median FICO as indicated by a tri-merge credit report. If only two (2) scores are returned, the lower of the 2 will be used as the representative score. In the case of multiple qualifying borrowers/guarantors, Fidelis Investors will use the highest median score as the representative score.
B19: Borrower Total Projects Completed | C19: Numeric | D19: Defined as number of successful exits (sale or refinance into DSCR) in the past 36 months
B20: Purchase Price | C20: Numeric | D20: Gross dollar amount paid for property *Always populate, even for refinances
B21: As Is Value | C21: Numeric | D21: Value of the property as of the date of origination *Always populate, even for purchases
B22: ARV | C22: Numeric | D22: Value of the property after rehabitilitation of property is completed *Always populate, even for bridge loans
... B27: Maturity Date | C27: Date | D27: Date when payoff will be due
B28: Term | C28: Numeric
B29: Purchase/Refi | C29: Text | D29: Valid values: - Purchase - Refinance Rate/Term - Refinance Cash Out
B30: Accrual Type | C30: Text | D30: Valid values: - Note (aka Dutch) - Drawn (aka Non-Dutch)
B31: Borrower Internal Projects Exited | C31: Numeric | D31: Number of projects exited with the originating lender
B32: # of Years Experience | C32: Numeric
B33: Repeat Borrower | C33: Text | D33: Valid values: - Yes - No
B34: # of Bed/Baths | C34: Text | D34: i.e. 3/2
B35: Pre-Rehab Sqft | C35: Numeric
B36: Post-Rehab Sqft | C36: Numeric
B37: # of Units | C37: Numeric
B38: Property Type | C38: Text | D38: Valid values: - Single Family Residence - 2-4 Family - Condo - Townhouse - Multifamily (5+ Units) - Manufactured Home - Mixed Use
B39: Loan Type | C39: Text | D39: Valid values: - New Construction - Fix and Flip - Fix and Hold - Bridge
B40: Exit Strategy | C40: Text | D40: Valid values: - Sale - Refinance: Rental - Refinance: Bridge
B41: Guarantor Citizenship Status | C41: Text | D41: Valid values: - U.S. Citizen - Permanent Resident - Non-Permanent Resident - Foreign Nationals
B42: Multiproperty Flag | C42: Text | D42: Valid values: - Yes - No
B43: Cross Collateralized Flag | C43: Text | D43: Valid values: - Yes - No
B44: Asset Purchased | C44: Text | D44: Description of the purchased asset *New Construction only
B45: Entitlement Status | C45: Text | D45: Defined as the status of legal/permit approvals from the applicable jurisdiction *New Construction only
...

Sheet Rate Build-Up
A1: Fidelis Buy Rate Build-Up
A2: Simple broker/lender-facing explanation of how the buy rate is built and whether the loan clears guideline limits.
A4: Input | B4: Value | D4: Guideline Check | E4: Limit | F4: Result
